Workbook
Name _D11: [1]表二!#REF!
Name _D12: [1]表二!#REF!
Name _SHR1: #REF!
Name a: #REF!
Name B3BGH: #REF!
Name B3BH: #REF!
Name b3data: #REF!
Name BSC安装材料金额: '[2]dyb3'!#REF!
Name BSC任选设备金额: '[2]dyb3'!#REF!
Name button_area_1: #REF!
Name calc: '[3]DYB4'!#REF!
Name CC: #REF!
Name CDB: #REF!
Name celltips_area: #REF!
Name cif合计cly: '[4]表四(主材引)'!#REF!
Name cif合计sby: '[4]表四(引)'!#REF!
Name count: #REF!
Name CS: #REF!
Name CSC技工总工日: [6]CSC生成表3!$I$178
Name CSC总计clg: [6]国内主材表CSC!$H$42
Name CS技工总工日: '[6]CS表3(1)'!$L$160
Name CS普工总工日: '[6]CS表3(1)'!$M$160
Name CS总计clg: [6]国内主材表CS!$J$62
Name dflt1: #REF!
Name dflt2: #REF!
Name dflt3: #REF!
Name dflt4: #REF!
Name dflt5: #REF!
Name dflt6: #REF!
Name dflt7: #REF!
Name display_area_1: #REF!
Name exchange: '[3]DYB4'!$D$3
Name floor: #REF!
Name fob合计cly: '[4]表四(主材引)'!#REF!
Name fob合计sby: '[7]表四(引)'!#REF!
Name HLR服务费金额: [8]费用!$I$10
Name hy: #REF!
Name JKSBB4_ZHU: '[3]DYB4'!#REF!
Name JKSBB4Btj: [9]Macro1!#REF!
Name LOC: #REF!
Name LTR: #REF!
Name MSC服务费金额: '[2]B4-3'!#REF!
Name mz: #REF!
Name new监理费: [10]费率!$AN$4:$AZ$17
Name NS: #REF!
Name p: #REF!
Name pe: #REF!
Name pn: #REF!
Name PROGRAM_B3: #REF!
Name PROGRAM_JKSB: #REF!
Name PROGRAM_LXGC: #REF!
Name PROGRAM_SBB4: #REF!
Name PROGRAM_YQYB: #REF!
Name PROGRAM_ZCB4: #REF!
Name pt: #REF!
Name ptw: #REF!
Name q: #REF!
Name rjq: #REF!
Name sjf: [12]DATA!$X$1:[12]DATA!$Z$20
Name SS: #REF!

Sheet 表1-甲供物资平衡表
A1: 表1：B25302110AA0014项目结算送审甲供物资平衡表（第一分册） | N1: JMHSWX25052615025R | O1: JMHSWX25052615022R | P1: JMHSWX25052615021R | Q1: JMHSWX25051308476R | R1: JMPJWX25051308301R | S1: JMHSWX25041800897R | T1: JMJHWX25041800899R | U1: JMJHWX24122521503R | V1: JMJHWX24122845347R | W1: JMHSWX25071541474R | X1: JMPJWX25081257109R | Y1: JMPJWX25090573549R | Z1: JMPJWX25090573548R | AA1: JMHSWX25090473480R | AB1: JMHSWX25090473477R | AC1: JMJHWX25092982719R | AD1: JMHSWX25102086683R
A2: 单项工程名称：江门700MHz频段共建共享五期工程无线主设备项目——子项4：常规项目 | D2: 框架合同编号：CMGD-202500909 投资项目编号：B25302110AA0014 | N2: APO302127250700258 | O2: APO302127250700258 | P2: APO302127250700258 | Q2: APO302127250700258 | R2: APO302127250700258 | S2: APO302127250700258 | T2: APO302127250700258 | U2: APO302127250700258 | V2: APO302127250700258 | W2: APO302127250700258 | X2: APO302127251000020 | Y2: APO302127251000020 | Z2: APO302127251000020 | AA2: APO302127251000020 | AB2: APO302127251000020 | AC2: APO302127251000020 | AD2: APO302127251100301
A3: 订单编号：APO302127250700258、APO302127251000020、APO302127251100301 | N3: 1 | O3: 2 | P3: 3 | Q3: 4 | R3: 5 | S3: 6 | T3: 7 | U3: 8 | V3: 9 | W3: 10 | X3: 11 | Y3: 12 | Z3: 13 | AA3: 14 | AB3: 15 | AC3: 16 | AD3: 17 | AE3: 18 | AF3: 19 | AG3: 20 | AH3: 21
A4: 序号 | B4: 物料名称 | C4: 单位 | D4: 领用数量 | E4: 合同间调入数量 | F4: 利旧数量 | G4: 实际使用数量 | H4: 退库数量 | I4: 合同间调出数量 | J4: 最后一次领用材料单价（不含税价） | K4: 调入合同编号（包括框架合同及单项合同/订单编号） | L4: 调出合同编号（包括框架合同及单项合同/订单编号） | N4: CBN-江门鹤山市连城C-RAN1（江门鹤山三连工业区二）U-Z5H | O4: CBN-江门鹤山路管所（江门鹤山裕兴雨具）U-Z5H | P4: CBN-江门鹤山市鹤城二（江门鹤山创美）U-Z5H | Q4: CBN-江门鹤山福迳（江门鹤山甘牛集团）U-Z5H | R4: CBN-江门蓬江区滨江新区1二（江门新昌公园）U-Z5H | S4: CBN-江门鹤山浩龙（江门鹤山鹤城联东（设备替换））U-Z5H | T4: CBN-江门礼乐新丰（江门江海东海路（设备替换））U-Z5H | U4: CBN-江门轻轨礼乐站（江门捷宏一品）U-Z5H | V4: CBN-江门汇聪电子（江门白水带山脚）U-Z5H | W4: CBN-江门鹤山大朗（江门鹤山址山昆中石北）U-Z5H | X4: CBN-江门荷塘（江门蓬江技师荷塘校区）U-Z5H | Y4: CBN-江门益晖印刷（江门永达顺（新））U-Z5H | Z4: CBN-江门三堡（江门蓬江元岭村西）U-Z5H | AA4: CBN-江门鹤山大富（江门鹤山大墩村）U-Z5H | AB4: CBN-江门鹤山平岭（江门鹤山共和平岭山顶村）U-Z5H | AC4: CBN-江门柏年（江门江海连海二路）U-Z5H | AD4: CBN-江门鹤山新民（江门鹤山共和新联油漆）U-Z5H
D5: (1) | E5: (2) | F5: (3) | G5: (4) | H5: (5) | I5: (6) | J5: (7) | K5: 若调入物料涉及多个合同编号，需分行填列 | L5: 若调出物料涉及多个合同编号，需分行填列 | N5: 数量 | O5: 数量 | P5: 数量 | Q5: 数量 | R5: 数量 | S5: 数量 | T5: 数量 | U5: 数量 | V5: 数量 | W5: 数量 | X5: 数量 | Y5: 数量 | Z5: 数量 | AA5: 数量 | AB5: 数量 | AC5: 数量 | AD5: 数量
A6: 1 | B6: 10G-1.4KM单模光模块 | C6: 个 | D6: 16 | E6: 0 | F6: 0 | G6: =D6+E6+F6 -> 16 | H6: 0 | I6: 0 | J6: 10.4 | W6: 5 | Y6: 4 | Z6: 4 | AA6: 1 | AB6: 1 | AC6: 1
A7: 2 | B7: 25G-10KM单模光模块 | C7: 个 | D7: 34 | E7: 0 | F7: 0 | G7: =D7+E7+F7 -> 34 | H7: 0 | I7: 0 | J7: 201.7 | N7: 2 | O7: 2 | P7: 2 | Q7: 2 | R7: 2 | S7: 2 | T7: 2 | U7: 2 | V7: 2 | W7: 2 | X7: 2 | Y7: 2 | Z7: 2 | AA7: 2 | AB7: 2 | AC7: 2 | AD7: 2
A8: 3 | B8: 25G-2KM单模光模块 | C8: 个 | D8: 56 | E8: 0 | F8: 0 | G8: =D8+E8+F8 -> 56 | H8: 0 | I8: 0 | J8: 48.99 | N8: 4 | O8: 4 | P8: 4 | Q8: 4 | R8: 4 | S8: 4 | T8: 4 | U8: 4 | V8: 4 | X8: 4 | AA8: 4 | AB8: 4 | AC8: 4 | AD8: 4
A9: 4 | B9: 4448天线\700/900/1800/FA\4+4+4+8通道\电调（短款）dBi\四频13/14/16.5/15/14.5 | C9: 面 | D9: 15 | E9: 3 | F9: 0 | G9: =D9+E9+F9 -> 18 | H9: 0 | I9: 0 | J9: 3957.36 | R9: 3 | U9: 3 | V9: 3 | Y9: 3 | AA9: 0 | AB9: 3
A10: 5 | B10: 绿色700-900M宽频四通道电调天线 | C10: 面 | D10: 18 | E10: 0 | F10: 0 | G10: =D10+E10+F10 -> 18 | H10: 0 | I10: 0 | J10: 1558.96 | N10: 3 | O10: 3 | Q10: 3 | T10: 3 | AC10: 3 | AD10: 3
A11: 6 | B11: BBU 直流电源线 | C11: 根 | D11: 4 | E11: 0 | F11: 0 | G11: =D11+E11+F11 -> 4 | H11: 0 | I11: 0 | J11: 0 | W11: 1 | AA11: 1 | AB11: 1 | AC11: 1
A12: 7 | B12: 单模1 LCUPC-FC/UPC G.652D 15M黄色|LC/PC-FC/PC-15M-φ2-SM/IOFC-FC/UPC-LC/PC G652D 1F φ2 PVC 15M//LC/F | C12: 根 | D12: 34 | E12: 0 | F12: 0 | G12: =D12+E12+F12 -> 34 | H12: 0 | I12: 0 | J12: 0 | N12: 2 | O12: 2 | P12: 2 | Q12: 2 | R12: 2 | S12: 2 | T12: 2 | U12: 2 | V12: 2 | W12: 2 | X12: 2 | Y12: 2 | Z12: 2 | AA12: 2 | AB12: 2 | AC12: 2 | AD12: 2
A13: 8 | B13: H07V-K&RV黄绿色1×16mm2电线(VDE/CE/CCC)|绝缘层颜色:/黄/绿色;绝缘层材质:/聚氯乙烯;额定电压:Nom(V);导体材质:/铜;标称截面积:Nom(mm^2);屏蔽层:/否;CPR认证:/E等级;导体规格:/1*16mm2; | H07V-K 16mm2(R | C13: 米 | D13: 177 | E13: 0 | F13: 0 | G13: =D13+E13+F13 -> 177 | H13: 0 | I13: 0 | J13: 0 | N13: 9 | O13: 9 | P13: 9 | Q13: 9 | R13: 9 | S13: 9 | T13: 9 | U13: 9 | V13: 9 | W13: 13 | X13: 9 | Y13: 9 | Z13: 9 | AA13: 13 | AB13: 13 | AC13: 13 | AD13: 17
A14: 9 | B14: R9214H S7200(W)整机(直流,不含光模块) | C14: 套 | D14: 21 | E14: 0 | F14: 3 | G14: =D14+E14+F14 -> 24 | H14: 0 | I14: 0 | J14: 0 | R14: 3 | U14: 3 | V14: 3 | W14: 3 | Y14: 3 | AA14: 3 | AB14: 3
A15: 10 | B15: R9264M M7290整机(直流,不含光模块) | C15: 套 | D15: 24 | E15: 3 | F15: 0 | G15: =D15+E15+F15 -> 27 | H15: 0 | I15: 0 | J15: 0 | N15: 3 | O15: 3 | P15: 3 | Q15: 3 | S15: 3 | T15: 3 | X15: 3 | AC15: 3 | AD15: 3
A16: 11 | B16: RF-01024084-012|射频电缆组件|3米|长度:3m;线材:RF1/2S-;B端连接器:4.3-10M;A端连接器:DM;硫化风险等级不涉及 | 626979000517 V1.0 | C16: 根 | D16: 132 | E16: 0 | F16: 0 | G16: =D16+E16+F16 -> 132 | H16: 0 | I16: 0 | J16: 0 | N16: 12 | O16: 12 | P16: 12 | R16: 12 | S16: 12 | T16: 12 | U16: 12 | V16: 12 | W16: 12 | X16: 12 | Z16: 12
A17: 12 | B17: RF-01024084-205|射频电缆组件|5米|长度:5m;线材:RF1/2S-;B端连接器:4.3-10M;A端连接器:DM;硫化风险等级不涉及 | 626979000517 V1.0 | C17: 根 | D17: 60 | E17: 0 | F17: 0 | G17: =D17+E17+F17 -> 60 | H17: 0 | I17: 0 | J17: 0 | Q17: 12 | AA17: 12 | AB17: 12 | AC17: 12 | AD17: 12
A18: 13 | B18: RF-01024084-012|射频电缆组件|10米|长度:10m;线材:RF1/2S-;B端连接器:4.3-10M;A端连接器:DM;硫化风险等级不涉及 | 626979000517 V1.0 | C18: 根 | D18: 12 | E18: 0 | F18: 0 | G18: =D18+E18+F18 -> 12 | H18: 0 | I18: 0 | J18: 0 | Y18: 12
A19: 14 | B19: UL 2586黑色D型(芯线：蓝/红)2X10mm2(2x8AWG)编织屏蔽电缆(UL/CE) | UL2586 2X10mm2(2x8AWG) | C19: 米 | D19: 415 | E19: 0 | F19: 0 | G19: =D19+E19+F19 -> 415 | H19: 0 | I19: 0 | J19: 0 | Q19: 45 | V19: 190 | AD19: 180
A20: 15 | B20: UL 2586黑色D型(芯线：蓝/红)2X6mm2(2x10AWG)编织屏蔽电缆(UL/CE) | UL 2586 2×6mm2(2x10AWG) | C20: 米 | D20: 1070 | E20: 0 | F20: 0 | G20: =D20+E20+F20 -> 1070 | H20: 0 | I20: 0 | J20: 0 | N20: 75 | O20: 60 | P20: 65 | R20: 70 | U20: 135 | V20: 15 | W20: 165 | X20: 45 | Y20: 105 | Z20: 80 | AA20: 45 | AB20: 150 | AC20: 60
A21: 16 | B21: V9200安装件 | C21: 套 | D21: 4 | E21: 0 | F21: 0 | G21: =D21+E21+F21 -> 4 | H21: 0 | I21: 0 | J21: 0 | W21: 1 | AA21: 1 | AB21: 1 | AC21: 1
A22: 17 | B22: V9200风扇模块VFC | C22: 块 | D22: 4 | E22: 0 | F22: 0 | G22: =D22+E22+F22 -> 4 | H22: 0 | I22: 0 | J22: 0 | W22: 1 | AA22: 1 | AB22: 1 | AC22: 1
A23: 18 | B23: V9200工程安装辅料 | C23: 套 | D23: 4 | E23: 0 | F23: 0 | G23: =D23+E23+F23 -> 4 | H23: 0 | I23: 0 | J23: 0 | W23: 1 | AA23: 1 | AB23: 1 | AC23: 1
A24: 19 | B24: V9200机箱 | C24: 套 | D24: 4 | E24: 0 | F24: 0 | G24: =D24+E24+F24 -> 4 | H24: 0 | I24: 0 | J24: 143.36 | W24: 1 | AA24: 1 | AB24: 1 | AC24: 1
A25: 20 | B25: V9200基带处理模块VBPe0d | C25: 块 | D25: 7 | E25: 0 | F25: 1 | G25: =D25+E25+F25 -> 8 | H25: 0 | I25: 0 | J25: 0 | R25: 1 | U25: 1 | W25: 1 | Y25: 1 | Z25: 1 | AA25: 1 | AB25: 1
A26: 21 | B26: V9200基带处理模块VBPe0e | C26: 块 | D26: 9 | E26: 0 | F26: 0 | G26: =D26+E26+F26 -> 9 | H26: 0 | I26: 0 | J26: 20135.98 | N26: 1 | O26: 1 | P26: 1 | Q26: 1 | S26: 1 | T26: 1 | X26: 1 | AC26: 1 | AD26: 1
A27: 22 | B27: V9200交换管理模块VSWd0A | C27: 块 | D27: 4 | E27: 0 | F27: 0 | G27: =D27+E27+F27 -> 4 | H27: 0 | I27: 0 | J27: 819.55 | W27: 1 | AA27: 1 | AB27: 1 | AC27: 1
A28: 23 | B28: GPS&BDS双模天线 | C28: 套 | D28: 1 | E28: 0 | F28: 0 | G28: =D28+E28+F28 -> 1 | H28: 0 | I28: 0 | J28: 819.55 | AC28: 1
A29: 24 | B29: GPS&BDS避雷器及辅料 | C29: 套 | D29: 1 | E29: 0 | F29: 0 | G29: =D29+E29+F29 -> 1 | H29: 0 | I29: 0 | J29: 819.55 | AC29: 1
A30: 25 | B30: 北斗三&GPS避雷器 | C30: 套 | D30: 4 | E30: 0 | F30: 0 | G30: =D30+E30+F30 -> 4 | H30: 0 | I30: 0 | J30: 0 | W30: 1 | AA30: 1 | AB30: 1 | AC30: 1
A31: 26 | B31: 北斗三&GPS天线及辅料 | C31: 套 | D31: 4 | E31: 0 | F31: 0 | G31: =D31+E31+F31 -> 4 | H31: 0 | I31: 0 | J31: 14.83 | W31: 1 | AA31: 1 | AB31: 1 | AC31: 1
A32: 27 | B32: 多频段智能天线\700～900/1800/FAD\4+4+8通道\独立电调\四频14/16.5/13.5/15.5dBi | C32: 面 | D32: 3 | E32: 0 | F32: 0 | G32: =D32+E32+F32 -> 3 | H32: 0 | I32: 0 | J32: 3454.6 | S32: 3
A33: 28 | B33: 室内单芯单模光纤跳线 | C33: 根 | D33: 8 | E33: 0 | F33: 0 | G33: =D33+E33+F33 -> 8 | H33: 0 | I33: 0 | J33: 69.91 | W33: 2 | AA33: 2 | AB33: 2 | AC33: 2
A34: 29 | B34: 直流电源模块VPD | C34: 块 | D34: 4 | E34: 0 | F34: 0 | G34: =D34+E34+F34 -> 4 | H34: 0 | I34: 0 | J34: 0 | W34: 1 | AA34: 1 | AB34: 1 | AC34: 1
A35: 30 | B35: 多频段智能天线\700～900/1800/FAD\4+4+8通道\独立电调\四频14/16.5/13.5/15.5dBi | C35: 面 | D35: 6 | E35: 0 | F35: 0 | G35: =D35+E35+F35 -> 6 | H35: 0 | I35: 0 | J35: 1891.76 | P35: 3 | X35: 3
A36: 31 | B36: 直流电源分配单元DCPD10B | C36: 套 | D36: 4 | E36: 0 | F36: 0 | G36: =D36+E36+F36 -> 4 | H36: 0 | I36: 0 | J36: 0 | W36: 1 | AA36: 1 | AB36: 1 | AC36: 1
A37: 32 | B37: DCPD10B安装辅料 | C37: 套 | D37: 4 | E37: 0 | F37: 0 | G37: =D37+E37+F37 -> 4 | H37: 0 | I37: 0 | J37: 0 | W37: 1 | AA37: 1 | AB37: 1 | AC37: 1
A38: 33 | B38: FDD宏基站\基站硬件\V9200增强型机箱单元\1800+900\中兴\直流 | C38: 套 | D38: 1 | E38: 0 | F38: 0 | G38: =D38+E38+F38 -> 1 | H38: 0 | I38: 0 | J38: 0 | AB38: 1
A39: 34 | B39: FIBER-95542-002光纤光缆组件|10米长度：10m;线材： LSZH 7mm两芯单模光缆；B端连接器： LC/PC;A端连接器： LC/PC;传输模式：单模；芯线数量： Nom2pcs; | C39: 根 | D39: 19 | E39: 0 | F39: 0 | G39: =D39+E39+F39 -> 19 | H39: 0 | I39: 0 | J39: 0 | N39: 2 | O39: 2 | P39: 1 | T39: 2 | U39: 2 | W39: 2 | Y39: 2 | AA39: 2 | AB39: 2 | AD39: 2
A40: 35 | B40: FIBER-95542-002光纤光缆组件|15米长度：15m;线材： LSZH 7mm两芯单模光缆；B端连接器： LC/PC;A端连接器： LC/PC;传输模式：单模；芯线数量： Nom2pcs; | C40: 根 | D40: 2 | E40: 0 | F40: 0 | G40: =D40+E40+F40 -> 2 | H40: 0 | I40: 0 | J40: 0 | S40: 2
...

Sheet 表2-通信工程结算送审工程量、甲供材、费用明细表
B1: 表2：B25302110AA0014项目结算送审工程量明细表（第一分册）
B3: 一、结算送审工程量明细表 | F3: ='表1-甲供物资平衡表'!N3 -> 1 | G3: ='表1-甲供物资平衡表'!O3 -> 2 | H3: ='表1-甲供物资平衡表'!P3 -> 3 | I3: ='表1-甲供物资平衡表'!Q3 -> 4 | J3: ='表1-甲供物资平衡表'!R3 -> 5 | K3: ='表1-甲供物资平衡表'!S3 -> 6 | L3: ='表1-甲供物资平衡表'!T3 -> 7 | M3: ='表1-甲供物资平衡表'!U3 -> 8 | ... V3: ='表1-甲供物资平衡表'!AD3 -> 17
A4: 序号 | B4: 子项名称 | C4: 特征描述 | D4: 单位 | E4: 送审工程量 | F4: CBN-江门鹤山市连城C-RAN1（江门鹤山三连工业区二）U-Z5H | G4: CBN-江门鹤山路管所（江门鹤山裕兴雨具）U-Z5H | H4: CBN-江门鹤山市鹤城二（江门鹤山创美）U-Z5H | I4: CBN-江门鹤山福迳（江门鹤山甘牛集团）U-Z5H | J4: CBN-江门蓬江区滨江新区1二（江门新昌公园）U-Z5H | K4: CBN-江门鹤山浩龙（江门鹤山鹤城联东（设备替换））U-Z5H | L4: CBN-江门礼乐新丰（江门江海东海路（设备替换））U-Z5H | M4: CBN-江门轻轨礼乐站（江门捷宏一品）U-Z5H | N4: CBN-江门汇聪电子（江门白水带山脚）U-Z5H | O4: CBN-江门鹤山大朗（江门鹤山址山昆中石北）U-Z5H | P4: CBN-江门荷塘（江门蓬江技师荷塘校区）U-Z5H | Q4: CBN-江门益晖印刷（江门永达顺（新））U-Z5H | R4: CBN-江门三堡（江门蓬江元岭村西）U-Z5H | S4: CBN-江门鹤山大富（江门鹤山大墩村）U-Z5H | T4: CBN-江门鹤山平岭（江门鹤山共和平岭山顶村）U-Z5H | U4: CBN-江门柏年（江门江海连海二路）U-Z5H | V4: CBN-江门鹤山新民（江门鹤山共和新联油漆）U-Z5H
F5: 送审工程量 | G5: 送审工程量 | H5: 送审工程量 | I5: 送审工程量 | J5: 送审工程量 | K5: 送审工程量 | L5: 送审工程量 | M5: 送审工程量 | N5: 送审工程量 | O5: 送审工程量 | P5: 送审工程量 | Q5: 送审工程量 | R5: 送审工程量 | S5: 送审工程量 | T5: 送审工程量 | U5: 送审工程量 | V5: 送审工程量 | W5: 合计
A6: 1 | B6: 无线设备 | C6: 安装基带处理单元（机柜/箱嵌入式 BBU） | D6: 台 | E6: =SUM(F6:V6) -> 1 | S6: 1 | W6: =SUM(F6:V6) -> 1
A7: 2 | B7: 无线设备 | C7: 安装基带处理单元（壁挂式 BBU） | D7: 台 | E7: =SUM(F7:V7) -> 3 | O7: 1 | T7: 1 | U7: 1 | W7: =SUM(F7:V7) -> 3
A8: 3 | B8: 无线设备 | C8: 扩装设备板件 | D8: 块 | E8: =SUM(F8:V8) -> 13 | F8: 1 | G8: 1 | H8: 1 | I8: 1 | J8: 1 | K8: 1 | L8: 1 | M8: 1 | N8: 1 | P8: 1 | Q8: 1 | R8: 1 | V8: 1 | W8: =SUM(F8:V8) -> 13
A9: 4 | B9: 无线设备 | C9: 拆除设备板件 | D9: 块 | E9: =SUM(F9:V9) -> 1 | K9: 1 | W9: =SUM(F9:V9) -> 1
A10: 5 | B10: 无线设备 | C10: 放绑软光纤（设备机架间）（15m以下） | D10: 条 | E10: =SUM(F10:V10) -> 48 | F10: 2 | G10: 2 | H10: 2 | I10: 2 | J10: 2 | K10: 2 | L10: 2 | M10: 2 | N10: 2 | O10: 4 | P10: 2 | Q10: 2 | R10: 2 | S10: 6 | T10: 6 | U10: 6 | V10: 2 | W10: =SUM(F10:V10) -> 48
A11: 6 | B11: 无线设备 | C11: 安装定向天线（抱杆上） | D11: 副 | E11: =SUM(F11:V11) -> 3 | P11: 3 | W11: =SUM(F11:V11) -> 3
A12: 7 | B12: 无线设备 | C12: 安装定向天线（抱杆上宽体天线400mm 以上） | D12: 副 | E12: =SUM(F12:V12) -> 12 | H12: 3 | I12: 3 | N12: 3 | U12: 3 | W12: =SUM(F12:V12) -> 12
A13: 8 | B13: 无线设备 | C13: 安装定向天线（地面铁塔上、宽体天线400mm 以上）（安装高度40m以下） | D13: 副 | E13: =SUM(F13:V13) -> 9 | M13: 3 | T13: 3 | V13: 3 | W13: =SUM(F13:V13) -> 9
A14: 9 | B14: 无线设备 | C14: 拆除定向天线（地面铁塔上、宽体天线400mm 以上）（安装高度40m以下） | D14: 副 | E14: =SUM(F14:V14) -> 2 | M14: 2 | W14: =SUM(F14:V14) -> 2
A15: 10 | B15: 无线设备 | C15: 美化罩内安装定向天线-抱杆上 | D15: 副 | E15: =SUM(F15:V15) -> 9 | J15: 3 | K15: 3 | S15: 3 | W15: =SUM(F15:V15) -> 9
A16: 11 | B16: 无线设备 | C16: 美化罩内拆除定向天线-抱杆上 | D16: 副 | E16: =SUM(F16:V16) -> 9 | J16: 3 | K16: 3 | S16: 3 | W16: =SUM(F16:V16) -> 9
A17: 12 | B17: 无线设备 | C17: 无作业平台安装定向天线-地面铁塔上（安装高度40m以下） | D17: 副 | E17: =SUM(F17:V17) -> 6 | L17: 3 | Q17: 3 | W17: =SUM(F17:V17) -> 6
A18: 13 | B18: 无线设备 | C18: 无作业平台拆除定向天线-地面铁塔上（拆除高度40m以下） | D18: 副 | E18: =SUM(F18:V18) -> 3 | Q18: 3 | W18: =SUM(F18:V18) -> 3
A19: 14 | B19: 无线设备 | C19: 拆除定向天线（抱杆上、宽体天线400mm 以上） | D19: 副 | E19: =SUM(F19:V19) -> 3 | N19: 3 | W19: =SUM(F19:V19) -> 3
A20: 15 | B20: 无线设备 | C20: 安装射频拉远单元（抱杆上） | D20: 套 | E20: =SUM(F20:V20) -> 19 | H20: 3 | I20: 3 | N20: 3 | P20: 4 | R20: 3 | U20: 3 | W20: =SUM(F20:V20) -> 19
A21: 16 | B21: 无线设备 | C21: 拆除射频拉远单元（抱杆上） | D21: 套 | E21: =SUM(F21:V21) -> 1 | P21: 1 | W21: =SUM(F21:V21) -> 1
A22: 17 | B22: 无线设备 | C22: 美化罩内安装射频拉远单元-抱杆上 | D22: 套 | E22: =SUM(F22:V22) -> 6 | K22: 3 | S22: 3 | W22: =SUM(F22:V22) -> 6
A23: 18 | B23: 无线设备 | C23: 美化罩内拆除射频拉远单元-抱杆上 | D23: 套 | E23: =SUM(F23:V23) -> 6 | J23: 3 | K23: 3 | W23: =SUM(F23:V23) -> 6
A24: 19 | B24: 无线设备 | C24: 安装射频拉远单元（地面铁塔上）（安装高度40m以下） | D24: 套 | E24: =SUM(F24:V24) -> 9 | M24: 3 | T24: 3 | V24: 3 | W24: =SUM(F24:V24) -> 9
A25: 20 | B25: 无线设备 | C25: 无作业平台安装射频拉远单元-地面铁塔上（安装高度40m以下） | D25: 套 | E25: =SUM(F25:V25) -> 9 | L25: 3 | O25: 3 | Q25: 3 | W25: =SUM(F25:V25) -> 9
A26: 21 | B26: 无线设备 | C26: 无作业平台拆除射频拉远单元（地面铁塔上）（安装高度40m以下） | D26: 套 | E26: =SUM(F26:V26) -> 3 | L26: 3 | W26: =SUM(F26:V26) -> 3
A27: 22 | B27: 无线设备 | C27: 拆除定向天线-地面铁塔上（拆除高度40m以下） | D27: 套 | E27: =SUM(F27:V27) -> 3 | T27: 3 | W27: =SUM(F27:V27) -> 3
A28: 23 | B28: 无线设备 | C28: 安装射频拉远单元-楼顶铁塔上（安装高度20m以下） | D28: 套 | E28: =SUM(F28:V28) -> 6 | F28: 3 | G28: 3 | W28: =SUM(F28:V28) -> 6
A29: 24 | B29: 无线设备 | C29: 安装安装定向天线-楼顶铁塔上（安装高度20m以下）宽体天线400mm 以上 | D29: 套 | E29: =SUM(F29:V29) -> 6 | F29: 3 | G29: 3 | W29: =SUM(F29:V29) -> 6
A30: 25 | B30: 无线设备 | C30: 调测室外基站天、馈线系统（1/2英寸射频同轴电缆） | D30: 条 | E30: =SUM(F30:V30) -> 251 | F30: 12 | G30: 12 | H30: 12 | I30: 12 | K30: 12 | L30: 12 | M30: 20 | N30: 36 | O30: 13 | P30: 12 | Q30: 12 | R30: 12 | S30: 25 | T30: 25 | U30: 12 | V30: 12 | W30: =SUM(F30:V30) -> 251
A31: 26 | B31: 无线设备 | C31: 配合调测天、馈线系统 | D31: 扇区 | E31: =SUM(F31:V31) -> 51 | F31: 3 | G31: 3 | H31: 3 | I31: 3 | J31: 3 | K31: 3 | L31: 3 | M31: 3 | N31: 3 | O31: 3 | P31: 3 | Q31: 3 | R31: 3 | S31: 3 | T31: 3 | U31: 3 | V31: 3 | W31: =SUM(F31:V31) -> 51
A32: 27 | B32: 无线设备 | C32: 安装电源转换器/配电单元（室内） | D32: 台 | E32: =SUM(F32:V32) -> 3 | S32: 1 | T32: 1 | U32: 1 | W32: =SUM(F32:V32) -> 3
A33: 28 | B33: 无线设备 | C33: 安装室内墙挂综合箱（无源） | D33: 个 | E33: =SUM(F33:V33) -> 3 | O33: 1 | T33: 1 | U33: 1 | W33: =SUM(F33:V33) -> 3
A34: 29 | B34: 无线设备 | C34: 室外布放电力电缆（单芯相线截面积16平方毫米以下） | D34: 十米条 | E34: =SUM(F34:V34) -> 22.5 | F34: 0.9 | G34: 0.9 | H34: 0.9 | I34: 0.9 | J34: 0.9 | K34: 0.9 | L34: 0.9 | M34: 0.9 | O34: 0.9 | P34: 0.9 | Q34: 0.9 | R34: 0.9 | S34: 9 | T34: 0.9 | U34: 0.9 | V34: 0.9 | W34: =SUM(F34:V34) -> 22.5
A35: 30 | B35: 无线设备 | C35: 室外布放电力电缆（双芯相线截面积16平方毫米以下） | D35: 十米条 | E35: =SUM(F35:V35) -> 173 | F35: 7.5 | G35: 6 | H35: 6.5 | I35: 4.5 | J35: 7 | K35: 6.5 | L35: 18 | M35: 13.5 | N35: 20.5 | O35: 16.5 | P35: 4.5 | Q35: 10.5 | R35: 8 | S35: 4.5 | T35: 15 | U35: 6 | V35: 18 | W35: =SUM(F35:V35) -> 173
A36: 31 | B36: 无线设备 | C36: 室内布放电力电缆（单芯相线截面积16平方毫米以下） | D36: 十米条 | E36: =SUM(F36:V36) -> 17.3 | O36: 1.6 | S36: 6 | T36: 4.8 | U36: 4.9 | W36: =SUM(F36:V36) -> 17.3
A37: 32 | B37: 无线设备 | C37: 室内布放电力电缆（双芯相线截面积16平方毫米以下） | D37: 十米条 | E37: =SUM(F37:V37) -> 0.4 | O37: 0.1 | S37: 0.1 | T37: 0.1 | U37: 0.1 | W37: =SUM(F37:V37) -> 0.4
A38: 33 | B38: 无线设备 | C38: 拆除室外电力电缆（单芯相线截面积16平方毫米以下） | D38: 十米条 | E38: =SUM(F38:V38) -> 24.5 | K38: 6.5 | L38: 18 | W38: =SUM(F38:V38) -> 24.5
A39: 34 | B39: 无线设备 | C39: 布放射频同轴电缆1/2英寸以下（4m以下）-带端头已连接好 | D39: 条 | E39: =SUM(F39:V39) -> 272 | F39: 12 | G39: 12 | H39: 12 | I39: 12 | J39: 12 | K39: 12 | L39: 12 | M39: 20 | N39: 36 | O39: 12 | P39: 12 | Q39: 24 | R39: 12 | S39: 24 | T39: 24 | U39: 12 | V39: 12 | W39: =SUM(F39:V39) -> 272
A40: 35 | B40: 无线设备 | C40: 布放射频同轴电缆1/2英寸以下（4m以下） | D40: 条 | E40: =SUM(F40:V40) -> 4 | O40: 1 | S40: 1 | T40: 1 | U40: 1 | W40: =SUM(F40:V40) -> 4
A41: 36 | B41: 无线设备 | C41: 布放射频同轴电缆1/2英寸以下（4m以上每增加1m） | D41: 米条 | E41: =SUM(F41:V41) -> 84 | O41: 21 | S41: 21 | T41: 21 | U41: 21 | W41: =SUM(F41:V41) -> 84
...

Sheet Sheet10
F1: 1 | G1: 2 | H1: 3 | I1: 4 | J1: 5 | K1: 6 | L1: 7 | M1: 8 | N1: 9 | O1: 10 | P1: 11 | Q1: 12 | R1: 13 | S1: 14 | T1: 15 | U1: 16 | V1: 17 | W1: 18 | X1: 19 | Y1: 20 | Z1: 21 | AA1: 22 | AB1: 23 | AC1: 24 | AD1: 25 | AE1: 26 | AF1: 27 | AG1: 28 | AH1: 29 | AI1: 30 | AJ1: 31 | AK1: 32 | AL1: 33 | AM1: 34 | AN1: 35 | AO1: 36
F2: 恩平市中山医院+互联网专线+语音专线+新增 | G2: 开平市公安局新昌派出所+互联网专线+搬迁 | H2: 开平市公安局新昌派出思始点+互联网专线+搬迁 | I2: 开平市公安局月山派出所+互联网专线+搬迁 | J2: 开平市中心医院（水口医院） | K2: 广东东方思维科技有限公司 | L2: 开平市美力服装有限公司 | M2: 恩平市供水有限公司+集团专线+搬迁 | N2: 恩平富辉纺织企业有限公司 | O2: 恩平市溢丰纺织有限公司 | P2: 开平水口镇联竹村委会+IPVPN专线+新增 | Q2: 开平市丰优农业开发有限公司 | R2: 恩平三力胶粘制品有限公司+互联网专线+新增 | S2: 恩平市公安消防大队集团专线搬迁 | T2: 开平市翡翠网吧 | U2: 开平市莱尚网咖网吧 | V2: 广发证券股份有限公司江门恩平证券营业部 | W2: 开平市公安局潭江派出所（巡警大对） | X2: 开平市水口镇东桥电镀有限公司 | Y2: 开平市公安局长沙派出所 | Z2: 开平+开平市应急管理局+新增 | AA2: 恩平+恩平市君堂镇人民政府+变更 | AB2: 开平市南大电力工程有限公司 | AC2: 恩平+广东通驿高速公路服务区有限公司大槐服务区+变更 | AD2: 开平+开平市环境卫生管理处+G325义祠路交叉公园内+新增 | AE2: 恩平+恩平市沙湖六乡市场+新增 | AF2: 恩平+恩平市科达声通电子器材厂（分厂）+新增 | AG2: 恩平+恩平市万国商业城开发有限公司+新增 | AH2: 恩平+江苏金江建设有限公司+新增 | AI2: 恩平+恩平市君堂镇中心小学（主校区）+新增 | AJ2: 开平市国营镇海林场（2条互联网专线+电路租用） | AK2: 开平+开平市公安局+南环簕冲红绿灯+新增 | AL2: 开平+广东开平文旅发展集团有限公司+Z端+新增 | AM2: 开平+开平百事通计算机+新增 | AN2: 开平+开平市百合镇消防专职队+新增 | AO2: 江门恩平市御茶餐饮店XWXJ
F3: 光缆 | G3: 城区光缆 | H3: 城区光缆 | I3: 乡镇光缆 | J3: 乡镇光缆 | K3: 乡镇光缆 | L3: 乡镇光缆 | M3: 乡镇光缆 | N3: 乡镇光缆 | O3: 乡镇光缆 | P3: 乡镇光缆 | Q3: 乡镇光缆 | R3: 乡镇光缆 | S3: 城区光缆 | T3: 城区光缆 | U3: 城区光缆 | V3: 城区光缆 | W3: 城区光缆 | X3: 乡镇光缆 | Y3: 乡镇光缆 | Z3: 城区光缆 | AA3: 乡镇光缆 | AB3: 城区光缆 | AC3: 乡镇光缆 | AD3: 城区光缆 | AE3: 乡镇光缆 | AF3: 城区光缆 | AG3: 城区光缆 | AH3: 城区光缆 | AI3: 乡镇光缆 | AJ3: 乡镇光缆 | AK3: 城区光缆 | AL3: 城区光缆 | AM3: 城区光缆 | AN3: 乡镇光缆 | AO3: 城区光缆
A4: 名称 | B4: 规格型号 | C4: 单位 | D4: 单价 | E4: 汇总数量 | F4: 数量 | G4: 数量 | H4: 数量 | I4: 数量 | J4: 数量 | K4: 数量 | L4: 数量 | M4: 数量 | N4: 数量 | O4: 数量 | P4: 数量 | Q4: 数量 | R4: 数量 | S4: 数量 | T4: 数量 | U4: 数量 | V4: 数量 | W4: 数量 | X4: 数量 | Y4: 数量 | Z4: 数量 | AA4: 数量 | AB4: 数量 | AC4: 数量 | AD4: 数量 | AE4: 数量 | AF4: 数量 | AG4: 数量 | AH4: 数量 | AI4: 数量 | AJ4: 数量 | AK4: 数量 | AL4: 数量 | AM4: 数量 | AN4: 数量 | AO4: 数量
A5: PE子管φ25/21mm | B5: φ25/21mm | C5: 米 | D5: 1.13 | E5: 0
A6: PE子管φ32/28mm | B6: φ32/28mm | C6: 米 | D6: 1.47 | E6: 0
A7: PE子管Φ28/24mm | B7: Φ28/24mm | C7: 米 | D7: 1.26 | E7: 0
A8: 5孔防盗塞古 | C8: 个 | D8: 8.5 | E8: 0
A9: 6孔防盗塞古 | C9: 个 | D9: 9 | E9: 0
A10: 子管堵塞内径Φ24mm | B10: 内径Φ24mm | C10: 个 | D10: 0.29 | E10: 0
A11: 子管堵塞内径Φ25mm | B11: 内径Φ25mm | C11: 个 | D11: 0.4 | E11: 0
A12: 12芯熔接配线一体化模块 | C12: 块 | D12: 8.74 | E12: 25 | F12: 0 | G12: 0 | H12: 1 | I12: 0 | J12: 0 | K12: 1 | L12: 1 | M12: 1 | N12: 0 | O12: 1 | P12: 0 | Q12: 0 | R12: 4 | S12: 0 | T12: 0 | U12: 2 | V12: 2 | W12: 0 | X12: 0 | Y12: 0 | Z12: 1 | AA12: 0 | AB12: 1 | AC12: 0 | AD12: 0 | AE12: 1 | AF12: 0 | AG12: 2 | AH12: 0 | AI12: 1 | AJ12: 0 | AK12: 2 | AL12: 0 | AM12: 2 | AN12: 0 | AO12: 2
A13: 综合机柜2200mm*600mm*600mm;配24DDF系统,48芯熔接单元,含2米FC双头尾纤 | B13: 2200mm*600mm*600mm;配24DDF系统,48芯熔接单元,含2米FC双头尾纤 | C13: 架 | D13: 2426.4 | E13: 0
A14: 小型综合机柜600mm*600mm*450mm;配24DDF系统，24芯熔接单元，含2米FC双头尾纤 | B14: 600mm*600mm*450mm;配24DDF系统，24芯熔接单元，含2米FC双头尾纤 | C14: 架 | D14: 420 | E14: 0
A15: D型（户外小型）楼道内普通配纤箱 | B15: 分纤箱 | C15: 台 | D15: 320 | E15: 0
A16: 多媒体机箱 (24芯) | B16: 分纤箱 | C16: 台 | D16: 730.77 | E16: 0
A17: 光纤分配箱48芯 | B17: 分纤箱 | C17: 台 | D17: 197.6 | E17: 0
A18: 光缆分纤箱光缆分纤箱/340×265×120/非金属/壁挂式/24芯/FC | B18: 光缆分纤箱/340×265×120/非金属/壁挂式/24芯/FC | C18: 台 | D18: 130.55 | E18: 0
A19: 光纤分配箱48芯（非金属）光缆分纤箱/420×320×125/非金属/壁挂式/48芯/SC | B19: 光缆分纤箱/420×320×125/非金属/壁挂式/48芯/SC | C19: 台 | D19: 197.6 | E19: 18 | F19: 0 | G19: 0 | H19: 0 | I19: 2 | J19: 1 | K19: 1 | L19: 1 | M19: 0 | N19: 0 | O19: 1 | P19: 0 | Q19: 1 | R19: 1 | S19: 0 | T19: 1 | U19: 0 | V19: 0 | W19: 1 | X19: 0 | Y19: 0 | Z19: 1 | AA19: 0 | AB19: 1 | AC19: 0 | AD19: 1 | AE19: 1 | AF19: 0 | AG19: 0 | AH19: 1 | AI19: 1 | AJ19: 1 | AK19: 0 | AL19: 1 | AM19: 0 | AN19: 0 | AO19: 0 | AP19: 0 | AQ19: 0 | AR19: 0
A20: 入户FTTH多媒体箱 | B20: 12芯分纤箱 | C20: 台 | D20: 173.50427 | E20: 0
A21: 光缆终端盒12芯，挂墙式 | B21: 12芯，挂墙式 | C21: 个 | D21: 160 | E21: 0
A22: 光缆终端盒24芯，挂墙式 | B22: 24芯，挂墙式 | C22: 个 | D22: 190 | E22: 1 | P22: 1
A23: 光缆终端盒48芯，挂墙式 | B23: 48芯，挂墙式 | C23: 个 | D23: 250 | E23: 6 | R23: 1 | S23: 2 | AC23: 1 | AM23: 1 | AN23: 1
A24: 光缆交接箱288芯满配 | B24: 288芯满配 | C24: 套 | D24: 5091.15 | E24: 0
A25: 光缆交接箱576芯满配(单面) | B25: 576芯满配(单面) | C25: 套 | D25: 7723.82 | E25: 1 | AO25: 1
A26: 光缆交接箱576芯满配(双面) | B26: 576芯满配(双面) | C26: 套 | D26: 7534.72 | E26: 0
A27: 光缆交接箱144芯(挂墙） | B27: 144芯(挂墙） | C27: 套 | D27: 2679.42 | E27: 1 | R27: 1
A28: 光缆接头盒48芯（1+4型） | B28: 48芯（1+4型） | C28: 套 | D28: 73.72 | E28: 0
A29: 光缆接头盒96芯（1+4型） | B29: 96芯（1+4型） | C29: 套 | D29: 88.67 | E29: 4 | S29: 1 | AC29: 2 | AN29: 1
A30: 光缆接头盒144芯（1+4型） | B30: 144芯（1+4型） | C30: 套 | D30: 112.2 | E30: 1 | AG30: 1
A31: 管道架空光缆GYTS-12B1 | B31: GYTS-12B1 | C31: 公里 | D31: 1095.16 | E31: 6.528 | G31: 0.081 | H31: 0.204 | I31: 0.159 | J31: 0.125 | K31: 0.152 | L31: 0.33 | M31: 0.617 | N31: 0.545 | O31: 0.119 | R31: 0.411 | T31: 0.038 | V31: 0.1 | W31: 0.089 | Y31: 0.126 | Z31: 0.159 | AA31: 0.205 | AB31: 0.173 | AD31: 0.232 | AE31: 0.14 | AF31: 0.278 | AG31: 0.237 | AH31: 0.313 | AI31: 0.167 | AK31: 0.307 | AL31: 0.053 | AM31: 0.676 | AN31: 0.055 | AO31: 0.437
A32: 管道架空光缆GYTS-24B1 | B32: GYTS-24B1 | C32: 公里 | D32: 1552.2 | E32: 3.242 | P32: 0.032 | Q32: 1.048 | S32: 0.155 | U32: 0.231 | AC32: 0.753 | AG32: 0.104 | AJ32: 0.708 | AM32: 0.211
A33: 管道架空光缆GYTS-48B1 | B33: GYTS-48B1 | C33: 公里 | D33: 2509.31 | E33: 0.44 | R33: 0.44
A34: 管道架空光缆GYTA-96B1 | B34: GYTA-96B1 | C34: 公里 | D34: 4678.8 | E34: 0
A35: 带状光缆GYTA-144B1 | B35: GYTA-144B1 | C35: 公里 | D35: 13801.609 | E35: 0
A36: 带状光缆GYTA-288B1 | B36: GYTA-288B1 | C36: 公里 | D36: 21051.137 | E36: 0
A37: 蝶形光缆 单芯 | B37: 单芯 | C37: 公里 | D37: 156.9 | E37: 0
A38: 蝶形光缆 2芯 | B38: 2芯 | C38: 公里 | D38: 279.64 | E38: 0
A39: 1:8FC/UPC盒式光分路器 | B39: 分光器 | C39: 台 | D39: 36.263 | E39: 0
A40: 1:8SC/UPC盒式光分路器 | B40: 分光器 | C40: 台 | D40: 36.208 | E40: 0
...

Sheet Sheet15
A1: 名称 | B1: PE子管φ25/21mm | C1: PE子管φ32/28mm | D1: PE子管Φ28/24mm | E1: 5孔防盗塞古 | F1: 6孔防盗塞古 | G1: 子管堵塞内径Φ24mm | H1: 子管堵塞内径Φ25mm | I1: 12芯熔接配线一体化模块 | J1: 综合机柜2200mm*600mm*600mm;配24DDF系统,48芯熔接单元,含2米FC双头尾纤 | K1: 小型综合机柜600mm*600mm*450mm;配24DDF系统，24芯熔接单元，含2米FC双头尾纤 | L1: D型（户外小型）楼道内普通配纤箱 | M1: 多媒体机箱 (24芯) | N1: 光纤分配箱48芯 | O1: 光缆分纤箱光缆分纤箱/340×265×120/非金属/壁挂式/24芯/FC | P1: 光纤分配箱48芯（非金属）光缆分纤箱/420×320×125/非金属/壁挂式/48芯/SC | Q1: 入户FTTH多媒体箱 | R1: 光缆终端盒12芯，挂墙式 | S1: 光缆终端盒24芯，挂墙式 | T1: 光缆终端盒48芯，挂墙式 | U1: 光缆交接箱288芯满配 | V1: 光缆交接箱576芯满配(单面) | W1: 光缆交接箱576芯满配(双面) | X1: 光缆交接箱144芯(挂墙） | Y1: 光缆接头盒48芯（1+4型） | Z1: 光缆接头盒96芯（1+4型） | AA1: 光缆接头盒144芯（1+4型） | AB1: 管道架空光缆GYTS-12B1 | AC1: 管道架空光缆GYTS-24B1 | AD1: 管道架空光缆GYTS-48B1 | AE1: 管道架空光缆GYTA-96B1 | AF1: 带状光缆GYTA-144B1 | AG1: 带状光缆GYTA-288B1 | AH1: 蝶形光缆 单芯 | AI1: 蝶形光缆 2芯 | AJ1: 1:8FC/UPC盒式光分路器 | AK1: 1:8SC/UPC盒式光分路器 | AL1: 分光器托板式-成端型-FC/UPC-1:8 | AM1: 分光器托板式-成端型-FC/UPC-1:32 | AN1: 分光器托板式-尾纤型-FC/UPC-2:32 | AO1: 托板式光分路器（1:4） | AP1: 1:8SC/UPC插片式光分路器 | AQ1: 1:64FC/UPC托盘式光分路器 | AR1: 单芯跳纤(3.0mm)(G.652D)FC/PC,2米/条 | AS1: 单芯跳纤\2米\FC\FC\G.652D\3mm\单模 | AT1: 单芯跳纤\2米\FC\LC\G.652D\3mm\单模 | AU1: 铠装跳纤单模单芯,FC/PC-FC/PC,20米 | AV1: 铠装跳纤单模单芯,FC/PC-SC/PC,20米 | AW1: 铠装跳纤单芯单模,FC-FC,20米 | AX1: 铠装跳纤单芯单模,FC-FC,30米 | AY1: 尾纤FC-FC-3米单模单芯 | AZ1: 尾纤铠装跳纤单模单芯,FC-SC,3米 | BA1: 尾纤铠装跳纤单芯单模,FC-FC,20米 | BB1: 镀锌钢绞线7/2.6（热镀锌 | BC1: 镀锌钢绞线7/2.2（热镀锌） | BD1: 铜芯阻燃双层塑料电力线 | BE1: 电力电缆 | BF1: 网线 | BG1: 光纤走线槽
A2: 恩平市中山医院+互联网专线+语音专线+新增 | I2: 0 | P2: 0 | BC2: 0
A3: 开平市公安局新昌派出所+互联网专线+搬迁 | I3: 0 | P3: 0 | AB3: 0.081 | BC3: 0
A4: 开平市公安局新昌派出思始点+互联网专线+搬迁 | I4: 1 | P4: 0 | AB4: 0.204 | BC4: 0
A5: 开平市公安局月山派出所+互联网专线+搬迁 | I5: 0 | P5: 2 | AB5: 0.159 | BC5: 0
A6: 开平市中心医院（水口医院） | I6: 0 | P6: 1 | AB6: 0.125 | BC6: 0
A7: 广东东方思维科技有限公司 | I7: 1 | P7: 1 | AB7: 0.152 | BC7: 0
A8: 开平市美力服装有限公司 | I8: 1 | P8: 1 | AB8: 0.33 | AC8: 0 | BC8: 4.6
A9: 恩平市供水有限公司+集团专线+搬迁 | I9: 1 | P9: 0 | AB9: 0.617 | BC9: 0
A10: 恩平富辉纺织企业有限公司 | I10: 0 | P10: 0 | AB10: 0.545 | BC10: 8.05
A11: 恩平市溢丰纺织有限公司 | I11: 1 | P11: 1 | AB11: 0.119 | BC11: 0
A12: 开平水口镇联竹村委会+IPVPN专线+新增 | I12: 0 | P12: 0 | S12: 1 | AC12: 0.032 | BC12: 0
A13: 开平市丰优农业开发有限公司 | I13: 0 | P13: 1 | AC13: 1.048 | BC13: 0
A14: 恩平三力胶粘制品有限公司+互联网专线+新增 | I14: 4 | P14: 1 | T14: 1 | X14: 1 | AB14: 0.411 | AD14: 0.44 | BC14: 64.4
A15: 恩平市公安消防大队集团专线搬迁 | I15: 0 | P15: 0 | T15: 2 | Z15: 1 | AC15: 0.155 | BC15: 0
A16: 开平市翡翠网吧 | I16: 0 | P16: 1 | AB16: 0.038 | BC16: 0
A17: 开平市莱尚网咖网吧 | I17: 2 | P17: 0 | AC17: 0.231 | BC17: 0
A18: 广发证券股份有限公司江门恩平证券营业部 | I18: 2 | P18: 0 | AB18: 0.1 | BC18: 0
A19: 开平市公安局潭江派出所（巡警大对） | I19: 0 | P19: 1 | AB19: 0.089 | BC19: 0
A20: 开平市水口镇东桥电镀有限公司 | I20: 0 | P20: 0 | BC20: 0
A21: 开平市公安局长沙派出所 | I21: 0 | P21: 0 | AB21: 0.126 | BC21: 0
A22: 开平+开平市应急管理局+新增 | I22: 1 | P22: 1 | AB22: 0.159 | BC22: 0
A23: 恩平+恩平市君堂镇人民政府+变更 | I23: 0 | P23: 0 | AB23: 0.205 | BC23: 0
A24: 开平市南大电力工程有限公司 | I24: 1 | P24: 1 | AB24: 0.173 | BC24: 0
A25: 恩平+广东通驿高速公路服务区有限公司大槐服务区+变更 | I25: 0 | P25: 0 | T25: 1 | Z25: 2 | AC25: 0.753 | BC25: 0
A26: 开平+开平市环境卫生管理处+G325义祠路交叉公园内+新增 | I26: 0 | P26: 1 | AB26: 0.232 | BC26: 0
A27: 恩平+恩平市沙湖六乡市场+新增 | I27: 1 | P27: 1 | AB27: 0.14 | BC27: 0
A28: 恩平+恩平市科达声通电子器材厂（分厂）+新增 | I28: 0 | P28: 0 | AB28: 0.278 | BC28: 1.15
A29: 恩平+恩平市万国商业城开发有限公司+新增 | I29: 2 | P29: 0 | AA29: 1 | AB29: 0.237 | AC29: 0.104 | BC29: 0
A30: 恩平+江苏金江建设有限公司+新增 | I30: 0 | P30: 1 | AB30: 0.313 | BC30: 15.64
A31: 恩平+恩平市君堂镇中心小学（主校区）+新增 | I31: 1 | P31: 1 | AB31: 0.167 | BC31: 0
A32: 开平市国营镇海林场（2条互联网专线+电路租用） | I32: 0 | P32: 1 | AC32: 0.708 | BC32: 45.54
A33: 开平+开平市公安局+南环簕冲红绿灯+新增 | I33: 2 | P33: 0 | AB33: 0.307 | BC33: 0
A34: 开平+广东开平文旅发展集团有限公司+Z端+新增 | I34: 0 | P34: 1 | AB34: 0.053 | BC34: 0
A35: 开平+开平百事通计算机+新增 | I35: 2 | P35: 0 | T35: 1 | AB35: 0.676 | AC35: 0.211 | BC35: 55.43
A36: 开平+开平市百合镇消防专职队+新增 | I36: 0 | P36: 0 | T36: 1 | Z36: 1 | AB36: 0.055 | BC36: 12.65
A37: 江门恩平市御茶餐饮店XWXJ | I37: 2 | P37: 0 | V37: 1 | AB37: 0.437 | BC37: 0
A38: =SUM(B38:BG38) -> 274.67 | B38: =SUM(B2:B37) -> 0 | C38: =SUM(C2:C37) -> 0 | D38: =SUM(D2:D37) -> 0 | E38: =SUM(E2:E37) -> 0 | F38: =SUM(F2:F37) -> 0 | G38: =SUM(G2:G37) -> 0 | H38: =SUM(H2:H37) -> 0 | I38: =SUM(I2:I37) -> 25 | ... BG38: =SUM(BG2:BG37) -> 0
A39: =A38-Sheet10!A63 -> 0 | P39: 0 | BC39: 0
A40: =A38+Sheet16!A47 -> 2733.4812 | P40: 0 | BC40: 0

Sheet Sheet11
F1: 1 | G1: 2 | H1: 3 | I1: 4 | J1: 5 | K1: 6 | L1: 7 | M1: 8 | N1: 9 | O1: 10 | P1: 11 | Q1: 12 | R1: 13 | S1: 14 | T1: 15 | U1: 16 | V1: 17 | W1: 18 | X1: 19 | Y1: 20 | Z1: 21 | AA1: 22 | AB1: 23 | AC1: 24 | AD1: 25 | AE1: 26 | AF1: 27 | AG1: 28 | AH1: 29 | AI1: 30 | AJ1: 31 | AK1: 32 | AL1: 33 | AM1: 34 | AN1: 35 | AO1: 36 | AP1: 37 | AQ1: 38 | AR1: 39 | AS1: 40 | AT1: 41 | AU1: 42 | AV1: 43 | AW1: 44 | AX1: 45
F2: 恩平市金丰电子器材厂+语音专线+变更 | G2: 恩平市中山医院+互联网专线+语音专线+新增 | H2: 国家税务总局恩平市税务局前进街办事点+互联网专线+新增+融合 | I2: 国家税务总局恩平市税务局恩城税务分局+互联网专线+新增+融合 | J2: 国家税务总局恩平市税务局圣堂税务分局+互联网专线+新增+融合 | K2: 国家税务总局恩平市税务局大槐税务分局+互联网专线+新增+融合 | L2: 开平市公安局赤坎派出所+互联网专线+搬迁 | M2: 开平市公安局新昌派出所+互联网专线+搬迁 | N2: 开平市公安局新昌派出思始点+互联网专线+搬迁 | O2: 开平市公安局月山派出所+互联网专线+搬迁 | P2: 江门开平市长沙福来旅店预覆盖工程（小微新建） | Q2: 江门开平市味香皇食品厂预覆盖工程（小微新建） | R2: 开平市中心医院（水口医院） | S2: 广东东方思维科技有限公司 | T2: 开平市美力服装有限公司 | U2: 恩平市供水有限公司+集团专线+搬迁 | V2: 恩平富辉纺织企业有限公司 | W2: 恩平市溢丰纺织有限公司 | X2: 开平市翡翠网吧 | Y2: 开平市莱尚网咖网吧 | Z2: 广发证券股份有限公司江门恩平证券营业部 | AA2: 开平市公安局潭江派出所（巡警大对） | AB2: 江门市合山水利工程管理处（互联网专线+电路租用） | AC2: 开平市广侨汽车销售服务有限公司（恩平店）（统一Centrex+互联网专线） | AD2: 开平市公安局长沙派出所 | AE2: 开平+粤顺牧业有限公司+新增 | AF2: 开平+开平市应急管理局+新增 | AG2: 恩平+恩平市君堂镇人民政府+变更 | AH2: 开平+开平市环境卫生管理处+G325义祠路交叉公园内+新增 | AI2: 恩平+恩平市沙湖六乡市场+新增 | AJ2: 恩平+恩平锦兴纺织印染企业有限公司+变更 | AK2: 恩平+恩平市科达声通电子器材厂（分厂）+新增 | AL2: 恩平+恩平市万国商业城开发有限公司+新增 | AM2: 恩平+江苏金江建设有限公司+新增 | AN2: 恩平+恩平市君堂镇中心小学（主校区）+新增 | AO2: 开平+开平市公安局+南环簕冲红绿灯+新增 | AP2: 恩平+恩平市水利局+青南角+二期+新增 | AQ2: 恩平+恩平市水利局+江北灌区+二期+新增 | AR2: 恩平+恩平市水利局+凤子山+二期+新增 | AS2: 跨市+中华人民共和国珠海出入境边防检查总站+开平边检站+新增 | AT2: 开平+广东开平文旅发展集团有限公司+Z端+新增 | AU2: 开平+开平市世界遗产管理中心+新增 | AV2: 开平+开平百事通计算机+新增 | AW2: 开平+开平市百合镇消防专职队+新增 | AX2: 江门恩平市御茶餐饮店XWXJ
F3: 城区 | G3: 设备 | H3: 城区 | I3: 城区 | J3: 乡镇 | K3: 乡镇 | L3: 乡镇 | M3: 城区 | N3: 城区 | O3: 乡镇 | P3: 城区 | Q3: 乡镇 | R3: 乡镇 | S3: 乡镇 | T3: 乡镇 | U3: 乡镇 | V3: 乡镇 | W3: 乡镇 | X3: 城区 | Y3: 城区 | Z3: 城区 | AA3: 城区 | AB3: 乡镇 | AC3: 城区 | AD3: 乡镇 | AE3: 乡镇 | AF3: 城区 | AG3: 乡镇 | AH3: 城区 | AI3: 乡镇 | AJ3: 乡镇 | AK3: 城区 | AL3: 城区 | AM3: 城区 | AN3: 乡镇 | AO3: 城区 | AP3: 乡镇 | AQ3: 乡镇 | AR3: 乡镇 | AS3: 城区 | AT3: 城区 | AU3: 城区 | AV3: 城区 | AW3: 乡镇 | AX3: 城区
A4: 名称 | B4: 规格型号 | C4: 单位 | D4: 单价 | E4: 汇总数量 | F4: 数量 | G4: 数量 | H4: 数量 | I4: 数量 | J4: 数量 | K4: 数量 | L4: 数量 | M4: 数量 | N4: 数量 | O4: 数量 | P4: 数量 | Q4: 数量 | R4: 数量 | S4: 数量 | T4: 数量 | U4: 数量 | V4: 数量 | W4: 数量 | X4: 数量 | Y4: 数量 | Z4: 数量 | AA4: 数量 | AB4: 数量 | AC4: 数量 | AD4: 数量 | AE4: 数量 | AF4: 数量 | AG4: 数量 | AH4: 数量 | AI4: 数量 | AJ4: 数量 | AK4: 数量 | AL4: 数量 | AM4: 数量 | AN4: 数量 | AO4: 数量 | AP4: 数量 | AQ4: 数量 | AR4: 数量 | AS4: 数量 | AT4: 数量 | AU4: 数量 | AV4: 数量 | AW4: 数量 | AX4: 数量
A5: PE子管φ25/21mm | B5: φ25/21mm | C5: 米 | D5: 1.13 | E5: 57 | F5: 0 | G5: 0 | H5: 0 | I5: 0 | J5: 0 | K5: 0 | L5: 0 | M5: 0 | N5: 0 | O5: 0 | P5: 0 | Q5: 0 | R5: 0 | S5: 0 | T5: 0 | U5: 0 | V5: 0 | W5: 0 | X5: 0 | Y5: 0 | Z5: 0 | AA5: 0 | AB5: 0 | AC5: 0 | AD5: 0 | AE5: 0 | AF5: 0 | AG5: 0 | AH5: 0 | AI5: 0 | AJ5: 0 | AK5: 0 | AL5: 0 | AM5: 0 | AN5: 0 | AO5: 0 | AP5: 0 | AQ5: 0 | AR5: 0 | AS5: 0 | AT5: 0 | AU5: 0 | AV5: 0 | AW5: 0 | AX5: 57
A6: PE子管φ32/28mm | B6: φ32/28mm | C6: 米 | D6: 1.47 | E6: 29 | F6: 0 | G6: 0 | H6: 0 | I6: 0 | J6: 0 | K6: 0 | L6: 0 | M6: 0 | N6: 0 | O6: 0 | P6: 0 | Q6: 0 | R6: 0 | S6: 0 | T6: 0 | U6: 0 | V6: 0 | W6: 0 | X6: 0 | Y6: 0 | Z6: 0 | AA6: 0 | AB6: 0 | AC6: 0 | AD6: 0 | AE6: 0 | AF6: 0 | AG6: 0 | AH6: 0 | AI6: 0 | AJ6: 0 | AK6: 0 | AL6: 0 | AM6: 0 | AN6: 0 | AO6: 0 | AP6: 0 | AQ6: 0 | AR6: 0 | AS6: 0 | AT6: 0 | AU6: 0 | AV6: 0 | AW6: 0 | AX6: 29
A7: PE子管Φ28/24mm | B7: Φ28/24mm | C7: 米 | D7: 1.26 | E7: 0
A8: 5孔防盗塞古 | C8: 个 | D8: 8.5 | E8: 0
A9: 6孔防盗塞古 | C9: 个 | D9: 9 | E9: 2 | AX9: 2
A10: 子管堵塞内径Φ24mm | B10: 内径Φ24mm | C10: 个 | D10: 0.29 | E10: 8 | AX10: 8
A11: 子管堵塞内径Φ25mm | B11: 内径Φ25mm | C11: 个 | D11: 0.4 | E11: 4 | AX11: 4
A12: 12芯熔接配线一体化模块 | C12: 块 | D12: 8.74 | E12: 5 | F12: 0 | G12: 0 | H12: 0 | I12: 0 | J12: 0 | K12: 0 | L12: 0 | M12: 0 | N12: 0 | O12: 0 | P12: 0 | Q12: 4 | R12: 0 | S12: 0 | T12: 0 | U12: 0 | V12: 0 | W12: 0 | X12: 0 | Y12: 0 | Z12: 0 | AA12: 0 | AB12: 0 | AC12: 0 | AD12: 0 | AE12: 0 | AF12: 0 | AG12: 0 | AH12: 0 | AI12: 0 | AJ12: 0 | AK12: 0 | AL12: 0 | AM12: 0 | AN12: 0 | AO12: 0 | AP12: 0 | AQ12: 0 | AR12: 0 | AS12: 0 | AT12: 0 | AU12: 0 | AV12: 0 | AW12: 0 | AX12: 1
A13: 综合机柜2200mm*600mm*600mm;配24DDF系统,48芯熔接单元,含2米FC双头尾纤 | B13: 2200mm*600mm*600mm;配24DDF系统,48芯熔接单元,含2米FC双头尾纤 | C13: 架 | D13: 2426.4 | E13: 0
A14: 小型综合机柜600mm*600mm*450mm;配24DDF系统，24芯熔接单元，含2米FC双头尾纤 | B14: 600mm*600mm*450mm;配24DDF系统，24芯熔接单元，含2米FC双头尾纤 | C14: 架 | D14: 420 | E14: 7 | N14: 1 | U14: 1 | V14: 1 | AC14: 1 | AK14: 1 | AL14: 1 | AM14: 1
A15: D型（户外小型）楼道内普通配纤箱 | B15: 分纤箱 | C15: 台 | D15: 320 | E15: 0
A16: 多媒体机箱 (24芯) | B16: 分纤箱 | C16: 台 | D16: 730.77 | E16: 1 | AN16: 1
A17: 光纤分配箱48芯 | B17: 分纤箱 | C17: 台 | D17: 197.6 | E17: 0
A18: 光缆分纤箱光缆分纤箱/340×265×120/非金属/壁挂式/24芯/FC | B18: 光缆分纤箱/340×265×120/非金属/壁挂式/24芯/FC | C18: 台 | D18: 130.55 | E18: 0
A19: 光纤分配箱48芯（非金属）光缆分纤箱/420×320×125/非金属/壁挂式/48芯/SC | B19: 光缆分纤箱/420×320×125/非金属/壁挂式/48芯/SC | C19: 台 | D19: 197.6 | E19: 9 | F19: 0 | G19: 0 | H19: 0 | I19: 0 | J19: 0 | K19: 0 | L19: 0 | M19: 0 | N19: 0 | O19: 0 | P19: 1 | Q19: 7 | R19: 0 | S19: 0 | T19: 0 | U19: 0 | V19: 0 | W19: 0 | X19: 0 | Y19: 0 | AA19: 0 | AB19: 0 | AC19: 0 | AD19: 0 | AE19: 0 | AF19: 0 | AG19: 0 | AH19: 0 | AI19: 0 | AJ19: 0 | AK19: 0 | AL19: 0 | AM19: 0 | AN19: 0 | AO19: 0 | AP19: 0 | AQ19: 0 | AR19: 0 | AS19: 0 | AT19: 0 | AU19: 0 | AV19: 0 | AW19: 0 | AX19: 1
A20: 入户FTTH多媒体箱 | B20: 12芯分纤箱 | C20: 台 | D20: 173.50427 | E20: 0
A21: 光缆终端盒12芯，挂墙式 | B21: 12芯，挂墙式 | C21: 个 | D21: 160 | E21: 0
A22: 光缆终端盒24芯，挂墙式 | B22: 24芯，挂墙式 | C22: 个 | D22: 190 | E22: 0
A23: 光缆终端盒48芯，挂墙式 | B23: 48芯，挂墙式 | C23: 个 | D23: 250 | E23: 0
A24: 光缆交接箱288芯满配 | B24: 288芯满配 | C24: 套 | D24: 5091.15 | E24: 0
A25: 光缆交接箱576芯满配(单面) | B25: 576芯满配(单面) | C25: 套 | D25: 7723.82 | E25: 0
A26: 光缆交接箱576芯满配(双面) | B26: 576芯满配(双面) | C26: 套 | D26: 7534.72 | E26: 0
A27: 光缆交接箱144芯(挂墙） | B27: 144芯(挂墙） | C27: 套 | D27: 2679.42 | E27: 0
A28: 光缆接头盒48芯（1+4型） | B28: 48芯（1+4型） | C28: 套 | D28: 73.72 | E28: 1 | Q28: 1
A29: 光缆接头盒96芯（1+4型） | B29: 96芯（1+4型） | C29: 套 | D29: 88.67 | E29: 0
A30: 光缆接头盒144芯（1+4型） | B30: 144芯（1+4型） | C30: 套 | D30: 112.2 | E30: 0
A31: 管道架空光缆GYTS-12B1 | B31: GYTS-12B1 | C31: 公里 | D31: 1095.16 | E31: 1.106 | P31: 0.05 | Q31: 0.426 | AX31: 0.63
A32: 管道架空光缆GYTS-24B1 | B32: GYTS-24B1 | C32: 公里 | D32: 1552.2 | E32: 0 | L32: 0
A33: 管道架空光缆GYTS-48B1 | B33: GYTS-48B1 | C33: 公里 | D33: 2509.31 | E33: 0.622 | L33: 0 | Q33: 0.622
A34: 管道架空光缆GYTA-96B1 | B34: GYTA-96B1 | C34: 公里 | D34: 4678.8 | E34: 0
A35: 带状光缆GYTA-144B1 | B35: GYTA-144B1 | C35: 公里 | D35: 13801.609 | E35: 0
A36: 带状光缆GYTA-288B1 | B36: GYTA-288B1 | C36: 公里 | D36: 21051.137 | E36: 0
A37: 蝶形光缆 单芯 | B37: 单芯 | C37: 公里 | D37: 156.9 | E37: 7.083 | Q37: 7.083
A38: 蝶形光缆 2芯 | B38: 2芯 | C38: 公里 | D38: 279.64 | E38: 0.747 | P38: 0.747
A39: 1:8FC/UPC盒式光分路器 | B39: 分光器 | C39: 台 | D39: 36.263 | E39: 3 | AX39: 3
A40: 1:8SC/UPC盒式光分路器 | B40: 分光器 | C40: 台 | D40: 36.208 | E40: 25 | P40: 3 | Q40: 22
...

Sheet Sheet16
A1: 名称 | B1: PE子管φ25/21mm | C1: PE子管φ32/28mm | D1: PE子管Φ28/24mm | E1: 5孔防盗塞古 | F1: 6孔防盗塞古 | G1: 子管堵塞内径Φ24mm | H1: 子管堵塞内径Φ25mm | I1: 12芯熔接配线一体化模块 | J1: 综合机柜2200mm*600mm*600mm;配24DDF系统,48芯熔接单元,含2米FC双头尾纤 | K1: 小型综合机柜600mm*600mm*450mm;配24DDF系统，24芯熔接单元，含2米FC双头尾纤 | L1: D型（户外小型）楼道内普通配纤箱 | M1: 多媒体机箱 (24芯) | N1: 光纤分配箱48芯 | O1: 光缆分纤箱光缆分纤箱/340×265×120/非金属/壁挂式/24芯/FC | P1: 光纤分配箱48芯（非金属）光缆分纤箱/420×320×125/非金属/壁挂式/48芯/SC | Q1: 入户FTTH多媒体箱 | R1: 光缆终端盒12芯，挂墙式 | S1: 光缆终端盒24芯，挂墙式 | T1: 光缆终端盒48芯，挂墙式 | U1: 光缆交接箱288芯满配 | V1: 光缆交接箱576芯满配(单面) | W1: 光缆交接箱576芯满配(双面) | X1: 光缆交接箱144芯(挂墙） | Y1: 光缆接头盒48芯（1+4型） | Z1: 光缆接头盒96芯（1+4型） | AA1: 光缆接头盒144芯（1+4型） | AB1: 管道架空光缆GYTS-12B1 | AC1: 管道架空光缆GYTS-24B1 | AD1: 管道架空光缆GYTS-48B1 | AE1: 管道架空光缆GYTA-96B1 | AF1: 带状光缆GYTA-144B1 | AG1: 带状光缆GYTA-288B1 | AH1: 蝶形光缆 单芯 | AI1: 蝶形光缆 2芯 | AJ1: 1:8FC/UPC盒式光分路器 | AK1: 1:8SC/UPC盒式光分路器 | AL1: 分光器托板式-成端型-FC/UPC-1:8 | AM1: 分光器托板式-成端型-FC/UPC-1:32 | AN1: 分光器托板式-尾纤型-FC/UPC-2:32 | AO1: 托板式光分路器（1:4） | AP1: 1:8SC/UPC插片式光分路器 | AQ1: 1:64FC/UPC托盘式光分路器 | AR1: 单芯跳纤(3.0mm)(G.652D)FC/PC,2米/条 | AS1: 单芯跳纤\2米\FC\FC\G.652D\3mm\单模 | AT1: 单芯跳纤\2米\FC\LC\G.652D\3mm\单模 | AU1: 铠装跳纤单模单芯,FC/PC-FC/PC,20米 | AV1: 铠装跳纤单模单芯,FC/PC-SC/PC,20米 | AW1: 铠装跳纤单芯单模,FC-FC,20米 | AX1: 铠装跳纤单芯单模,FC-FC,30米 | AY1: 尾纤FC-FC-3米单模单芯 | AZ1: 尾纤铠装跳纤单模单芯,FC-SC,3米 | BA1: 尾纤铠装跳纤单芯单模,FC-FC,20米 | BB1: 镀锌钢绞线7/2.6（热镀锌 | BC1: 镀锌钢绞线7/2.2（热镀锌） | BD1: 铜芯阻燃双层塑料电力线 | BE1: 电力电缆 | BF1: 网线 | BG1: 光纤走线槽
A2: 恩平市金丰电子器材厂+语音专线+变更 | B2: 0 | C2: 0 | I2: 0 | P2: 0 | BC2: 0 | BF2: 20
A3: 恩平市中山医院+互联网专线+语音专线+新增 | B3: 0 | C3: 0 | I3: 0 | P3: 0 | BC3: 0
A4: 国家税务总局恩平市税务局前进街办事点+互联网专线+新增+融合 | B4: 0 | C4: 0 | I4: 0 | P4: 0 | AS4: 2 | AZ4: 2 | BA4: 4 | BC4: 0 | BF4: 20
A5: 国家税务总局恩平市税务局恩城税务分局+互联网专线+新增+融合 | B5: 0 | C5: 0 | I5: 0 | P5: 0 | AS5: 4 | AZ5: 2 | BA5: 2 | BC5: 0 | BF5: 20
A6: 国家税务总局恩平市税务局圣堂税务分局+互联网专线+新增+融合 | B6: 0 | C6: 0 | I6: 0 | P6: 0 | AS6: 4 | AZ6: 2 | BA6: 2 | BC6: 0 | BF6: 30
A7: 国家税务总局恩平市税务局大槐税务分局+互联网专线+新增+融合 | B7: 0 | C7: 0 | I7: 0 | P7: 0 | AS7: 2 | AZ7: 2 | BA7: 4 | BC7: 0 | BF7: 20
A8: 开平市公安局赤坎派出所+互联网专线+搬迁 | B8: 0 | C8: 0 | I8: 0 | P8: 0 | AC8: 0 | AD8: 0 | AR8: 2 | BC8: 0 | BF8: 10
A9: 开平市公安局新昌派出所+互联网专线+搬迁 | B9: 0 | C9: 0 | I9: 0 | P9: 0 | AR9: 3 | BC9: 0 | BF9: 10
A10: 开平市公安局新昌派出思始点+互联网专线+搬迁 | B10: 0 | C10: 0 | I10: 0 | K10: 1 | P10: 0 | AR10: 3 | BC10: 0 | BF10: 10
A11: 开平市公安局月山派出所+互联网专线+搬迁 | B11: 0 | C11: 0 | I11: 0 | P11: 0 | AR11: 2 | BC11: 0 | BF11: 10
A12: 江门开平市长沙福来旅店预覆盖工程（小微新建） | B12: 0 | C12: 0 | I12: 0 | P12: 1 | AB12: 0.05 | AI12: 0.747 | AK12: 3 | AL12: 1 | AR12: 8 | AV12: 1 | BC12: 0
A13: 江门开平市味香皇食品厂预覆盖工程（小微新建） | B13: 0 | C13: 0 | I13: 4 | P13: 7 | Y13: 1 | AB13: 0.426 | AD13: 0.622 | AH13: 7.083 | AK13: 22 | AL13: 3 | AR13: 50 | AV13: 3 | BC13: 132.0032
A14: 开平市中心医院（水口医院） | B14: 0 | C14: 0 | I14: 0 | P14: 0 | AR14: 2 | AT14: 4 | BC14: 0 | BF14: 5
A15: 广东东方思维科技有限公司 | B15: 0 | C15: 0 | I15: 0 | P15: 0 | AR15: 2 | AT15: 4 | BC15: 0 | BF15: 5
A16: 开平市美力服装有限公司 | B16: 0 | C16: 0 | I16: 0 | P16: 0 | AR16: 3 | BC16: 0 | BF16: 22
A17: 恩平市供水有限公司+集团专线+搬迁 | B17: 0 | C17: 0 | I17: 0 | K17: 1 | P17: 0 | AS17: 4 | BA17: 2 | BC17: 0 | BF17: 20
A18: 恩平富辉纺织企业有限公司 | B18: 0 | C18: 0 | I18: 0 | K18: 1 | P18: 0 | BC18: 0 | BF18: 20
A19: 恩平市溢丰纺织有限公司 | B19: 0 | C19: 0 | I19: 0 | P19: 0 | AS19: 6 | AZ19: 4 | BA19: 6 | BC19: 0 | BF19: 40
A20: 开平市翡翠网吧 | B20: 0 | C20: 0 | I20: 0 | P20: 0 | AR20: 20 | AT20: 4 | BA20: 4 | BC20: 0 | BF20: 10
A21: 开平市莱尚网咖网吧 | B21: 0 | C21: 0 | I21: 0 | P21: 0 | AR21: 20 | AT21: 4 | BA21: 4 | BC21: 0 | BF21: 10
A22: 广发证券股份有限公司江门恩平证券营业部 | B22: 0 | C22: 0 | I22: 0 | AS22: 3 | BC22: 0 | BF22: 30
A23: 开平市公安局潭江派出所（巡警大对） | B23: 0 | C23: 0 | I23: 0 | P23: 0 | AR23: 2 | BC23: 0 | BF23: 10
A24: 江门市合山水利工程管理处（互联网专线+电路租用） | B24: 0 | C24: 0 | I24: 0 | P24: 0 | AR24: 2 | AT24: 4 | AV24: 2 | BC24: 0 | BF24: 10
A25: 开平市广侨汽车销售服务有限公司（恩平店）（统一Centrex+互联网专线） | B25: 0 | C25: 0 | I25: 0 | K25: 1 | P25: 0 | AS25: 1 | AZ25: 1 | BC25: 0 | BF25: 20
A26: 开平市公安局长沙派出所 | B26: 0 | C26: 0 | I26: 0 | P26: 0 | AR26: 3 | BC26: 0 | BF26: 10
A27: 开平+粤顺牧业有限公司+新增 | B27: 0 | C27: 0 | I27: 0 | P27: 0 | AR27: 3 | AT27: 4 | BC27: 0 | BF27: 6
A28: 开平+开平市应急管理局+新增 | B28: 0 | C28: 0 | I28: 0 | P28: 0 | AR28: 4 | AT28: 4 | AV28: 2 | BC28: 0 | BF28: 10
A29: 恩平+恩平市君堂镇人民政府+变更 | B29: 0 | C29: 0 | I29: 0 | P29: 0 | BC29: 0 | BF29: 20
A30: 开平+开平市环境卫生管理处+G325义祠路交叉公园内+新增 | B30: 0 | C30: 0 | I30: 0 | P30: 0 | AR30: 2 | AT30: 4 | AV30: 2 | BC30: 0 | BF30: 10
A31: 恩平+恩平市沙湖六乡市场+新增 | B31: 0 | C31: 0 | I31: 0 | P31: 0 | AS31: 1 | AZ31: 1 | BC31: 0 | BF31: 20
A32: 恩平+恩平锦兴纺织印染企业有限公司+变更 | B32: 0 | C32: 0 | I32: 0 | P32: 0 | BC32: 0 | BF32: 20
A33: 恩平+恩平市科达声通电子器材厂（分厂）+新增 | B33: 0 | C33: 0 | I33: 0 | K33: 1 | P33: 0 | AS33: 1 | AZ33: 1 | BC33: 0 | BF33: 20
A34: 恩平+恩平市万国商业城开发有限公司+新增 | B34: 0 | C34: 0 | I34: 0 | K34: 1 | P34: 0 | AS34: 3 | AZ34: 1 | BC34: 0 | BF34: 20
A35: 恩平+江苏金江建设有限公司+新增 | B35: 0 | C35: 0 | I35: 0 | K35: 1 | P35: 0 | AS35: 3 | AZ35: 1 | BC35: 0 | BF35: 600
A36: 恩平+恩平市君堂镇中心小学（主校区）+新增 | B36: 0 | C36: 0 | I36: 0 | M36: 1 | P36: 0 | AS36: 2 | AZ36: 1 | BC36: 0 | BF36: 500
A37: 开平+开平市公安局+南环簕冲红绿灯+新增 | B37: 0 | C37: 0 | I37: 0 | P37: 0 | AR37: 6 | AT37: 4 | AV37: 16 | BC37: 0
A38: 恩平+恩平市水利局+青南角+二期+新增 | B38: 0 | C38: 0 | I38: 0 | P38: 0 | AZ38: 2 | BA38: 2 | BC38: 0 | BF38: 20
A39: 恩平+恩平市水利局+江北灌区+二期+新增 | B39: 0 | C39: 0 | I39: 0 | P39: 0 | AS39: 4 | AZ39: 2 | BA39: 4 | BC39: 0 | BF39: 20
A40: 恩平+恩平市水利局+凤子山+二期+新增 | B40: 0 | C40: 0 | I40: 0 | P40: 0 | AS40: 4 | AZ40: 2 | BA40: 2 | BC40: 0 | BF40: 20
...

Sheet Sheet12
F1: 1 | G1: 2 | H1: 3 | I1: 4 | J1: 5 | K1: 6 | L1: 7 | M1: 8 | N1: 9 | O1: 10 | P1: 11 | Q1: 12 | R1: 13 | S1: 14 | T1: 15 | U1: 16 | V1: 17 | W1: 18 | X1: 19 | Y1: 20 | Z1: 21 | AA1: 22 | AB1: 23 | AC1: 24 | AD1: 25 | AE1: 26 | AF1: 27 | AG1: 28 | AH1: 29 | AI1: 30 | AJ1: 31 | AK1: 32 | AL1: 33 | AM1: 34 | AN1: 35 | AO1: 36 | AP1: 37 | AQ1: 38 | AR1: 39 | AS1: 40 | AT1: 41 | AU1: 42 | AV1: 43 | AW1: 44 | AX1: 45
F2: 恩平市金丰电子器材厂+语音专线+变更 | G2: 恩平市中山医院+互联网专线+语音专线+新增 | H2: 国家税务总局恩平市税务局前进街办事点+互联网专线+新增+融合 | I2: 国家税务总局恩平市税务局恩城税务分局+互联网专线+新增+融合 | J2: 国家税务总局恩平市税务局圣堂税务分局+互联网专线+新增+融合 | K2: 国家税务总局恩平市税务局大槐税务分局+互联网专线+新增+融合 | L2: 开平市公安局赤坎派出所+互联网专线+搬迁 | M2: 开平市公安局新昌派出所+互联网专线+搬迁 | N2: 开平市公安局新昌派出思始点+互联网专线+搬迁 | O2: 开平市公安局月山派出所+互联网专线+搬迁 | P2: 江门开平市长沙福来旅店预覆盖工程（小微新建） | Q2: 江门开平市味香皇食品厂预覆盖工程（小微新建） | R2: 开平市中心医院（水口医院） | S2: 广东东方思维科技有限公司 | T2: 开平市美力服装有限公司 | U2: 恩平市供水有限公司+集团专线+搬迁 | V2: 恩平富辉纺织企业有限公司 | W2: 恩平市溢丰纺织有限公司 | X2: 开平水口镇联竹村委会+IPVPN专线+新增 | Y2: 开平市丰优农业开发有限公司 | Z2: 恩平三力胶粘制品有限公司+互联网专线+新增 | AA2: 恩平市公安消防大队集团专线搬迁 | AB2: 开平市翡翠网吧 | AC2: 开平市莱尚网咖网吧 | AD2: 广发证券股份有限公司江门恩平证券营业部 | AE2: 开平市公安局潭江派出所（巡警大对） | AF2: 开平市水口镇东桥电镀有限公司 | AG2: 江门市合山水利工程管理处（互联网专线+电路租用） | AH2: 开平市广侨汽车销售服务有限公司（恩平店）（统一Centrex+互联网专线） | AI2: 开平市公安局长沙派出所 | AJ2: 开平+粤顺牧业有限公司+新增 | AK2: 开平+开平市应急管理局+新增 | AL2: 恩平+恩平市君堂镇人民政府+变更 | AM2: 开平市南大电力工程有限公司 | AN2: 恩平+广东通驿高速公路服务区有限公司大槐服务区+变更 | AO2: 开平+开平市环境卫生管理处+G325义祠路交叉公园内+新增 | AP2: 恩平+恩平市沙湖六乡市场+新增 | AQ2: 恩平+恩平锦兴纺织印染企业有限公司+变更 | AR2: 恩平+恩平市科达声通电子器材厂（分厂）+新增 | AS2: 恩平+恩平市万国商业城开发有限公司+新增 | AT2: 恩平+江苏金江建设有限公司+新增 | AU2: 恩平+恩平市君堂镇中心小学（主校区）+新增 | AV2: 开平市国营镇海林场（2条互联网专线+电路租用） | AW2: 开平+开平市公安局+南环簕冲红绿灯+新增 | AX2: 恩平+恩平市水利局+青南角+二期+新增 | AY2: 恩平+恩平市水利局+江北灌区+二期+新增 | AZ2: 恩平+恩平市水利局+凤子山+二期+新增 | BA2: 跨市+中华人民共和国珠海出入境边防检查总站+开平边检站+新增 | BB2: 开平+广东开平文旅发展集团有限公司+Z端+新增 | BC2: 开平+开平市世界遗产管理中心+新增 | BD2: 开平+开平百事通计算机+新增 | BE2: 开平+开平市百合镇消防专职队+新增 | BF2: 江门恩平市御茶餐饮店XWXJ
F3: 城区 | G3: 设备 | H3: 城区 | I3: 城区 | J3: 乡镇 | K3: 乡镇 | L3: 乡镇 | M3: 城区 | N3: 城区 | O3: 乡镇 | P3: 城区 | Q3: 乡镇 | R3: 乡镇 | S3: 乡镇 | T3: 乡镇 | U3: 乡镇 | V3: 乡镇 | W3: 乡镇 | X3: 城区 | Y3: 城区 | Z3: 城区 | AA3: 城区 | AB3: 乡镇 | AC3: 城区 | AD3: 乡镇 | AE3: 乡镇 | AF3: 城区 | AG3: 乡镇 | AH3: 城区 | AI3: 乡镇 | AJ3: 乡镇 | AK3: 城区 | AL3: 城区 | AM3: 城区 | AN3: 乡镇 | AO3: 城区 | AP3: 乡镇 | AQ3: 乡镇 | AR3: 乡镇 | AS3: 城区 | AT3: 城区 | AU3: 城区 | AV3: 城区 | AW3: 乡镇 | AX3: 城区
A4: 名称 | B4: 规格型号 | C4: 单位 | D4: 单价 | E4: 汇总数量 | F4: 数量 | G4: 数量 | H4: 数量 | I4: 数量 | J4: 数量 | K4: 数量 | L4: 数量 | M4: 数量 | N4: 数量 | O4: 数量 | P4: 数量 | Q4: 数量 | R4: 数量 | S4: 数量 | T4: 数量 | U4: 数量 | V4: 数量 | W4: 数量 | X4: 数量 | Y4: 数量 | Z4: 数量 | AA4: 数量 | AB4: 数量 | AC4: 数量 | AD4: 数量 | AE4: 数量 | AF4: 数量 | AG4: 数量 | AH4: 数量 | AI4: 数量 | AJ4: 数量 | AK4: 数量 | AL4: 数量 | AM4: 数量 | AN4: 数量 | AO4: 数量 | AP4: 数量 | AQ4: 数量 | AR4: 数量 | AS4: 数量 | AT4: 数量 | AU4: 数量 | AV4: 数量 | AW4: 数量 | AX4: 数量
A5: PE子管 | B5: φ25/21mm | C5: 米 | D5: 1.13 | E5: 57
A6: PE子管 | B6: φ32/28mm | C6: 米 | D6: 1.47 | E6: 29
A7: PE子管 | B7: Φ28/24mm | C7: 米 | D7: 1.26 | E7: 0
A8: 5孔防盗塞古 | C8: 个 | D8: 8.5 | E8: 0
A9: 6孔防盗塞古 | C9: 个 | D9: 9 | E9: 2
A10: 子管堵塞 | B10: 内径Φ24mm | C10: 个 | D10: 0.29 | E10: 8
A11: 子管堵塞 | B11: 内径Φ25mm | C11: 个 | D11: 0.4 | E11: 4
A12: 12芯熔接配线一体化模块 | C12: 块 | D12: 8.74 | E12: 5
A13: 综合机柜 | B13: 2200mm*600mm*600mm;配24DDF系统,48芯熔接单元,含2米FC双头尾纤 | C13: 架 | D13: 2426.4 | E13: 0
A14: 小型综合机柜 | B14: 600mm*600mm*450mm;配24DDF系统，24芯熔接单元，含2米FC双头尾纤 | C14: 架 | D14: 420 | E14: 7
A15: D型（户外小型）楼道内普通配纤箱 | B15: 分纤箱 | C15: 台 | D15: 320 | E15: 0
A16: 多媒体机箱 (24芯) | B16: 分纤箱 | C16: 台 | D16: 730.77 | E16: 1
A17: 光纤分配箱48芯 | B17: 分纤箱 | C17: 台 | D17: 197.6 | E17: 0
A18: 光缆分纤箱 | B18: 光缆分纤箱/340×265×120/非金属/壁挂式/24芯/FC | C18: 台 | D18: 130.55 | E18: 0
A19: 光纤分配箱48芯（非金属） | B19: 光缆分纤箱/420×320×125/非金属/壁挂式/48芯/SC | C19: 台 | D19: 197.6 | E19: 9
A20: 入户FTTH多媒体箱 | B20: 12芯分纤箱 | C20: 台 | D20: 173.50427 | E20: 0
A21: 光缆终端盒 | B21: 12芯，挂墙式 | C21: 个 | D21: 160 | E21: 0
A22: 光缆终端盒 | B22: 24芯，挂墙式 | C22: 个 | D22: 190 | E22: 0
A23: 光缆终端盒 | B23: 48芯，挂墙式 | C23: 个 | D23: 250 | E23: 0
A24: 光缆交接箱 | B24: 288芯满配 | C24: 套 | D24: 5091.15 | E24: 0
... A62: 光纤走线槽 | B62: 光纤走线槽\铝合金\200x100mm\1米\承重部位2.0mm | C62: 公斤 | D62: 173.89 | E62: 0

Sheet Sheet1
H1: 1 | I1: 2 | J1: 3 | K1: 4 | L1: 5 | M1: 6 | N1: 7 | O1: 8 | P1: 9 | Q1: 10 | R1: 11 | S1: 12 | T1: 13 | U1: 14 | V1: 15 | W1: 16 | X1: 17 | Y1: 18 | Z1: 19 | AA1: 20 | AB1: 21 | AC1: 22 | AD1: 23 | AE1: 24 | AF1: 25 | AG1: 26 | AH1: 27 | AI1: 28 | AJ1: 29 | AK1: 30 | AL1: 31 | AM1: 32 | AN1: 33 | AO1: 34 | AP1: 35 | AQ1: 36
H2: 恩平市中山医院+互联网专线+语音专线+新增 | I2: 开平市公安局新昌派出所+互联网专线+搬迁 | J2: 开平市公安局新昌派出思始点+互联网专线+搬迁 | K2: 开平市公安局月山派出所+互联网专线+搬迁 | L2: 开平市中心医院（水口医院） | M2: 广东东方思维科技有限公司 | N2: 开平市美力服装有限公司 | O2: 恩平市供水有限公司+集团专线+搬迁 | P2: 恩平富辉纺织企业有限公司 | Q2: 恩平市溢丰纺织有限公司 | R2: 开平水口镇联竹村委会+IPVPN专线+新增 | S2: 开平市丰优农业开发有限公司 | T2: 恩平三力胶粘制品有限公司+互联网专线+新增 | U2: 恩平市公安消防大队集团专线搬迁 | V2: 开平市翡翠网吧 | W2: 开平市莱尚网咖网吧 | X2: 广发证券股份有限公司江门恩平证券营业部 | Y2: 开平市公安局潭江派出所（巡警大对） | Z2: 开平市水口镇东桥电镀有限公司 | AA2: 开平市公安局长沙派出所 | AB2: 开平+开平市应急管理局+新增 | AC2: 恩平+恩平市君堂镇人民政府+变更 | AD2: 开平市南大电力工程有限公司 | AE2: 恩平+广东通驿高速公路服务区有限公司大槐服务区+变更 | AF2: 开平+开平市环境卫生管理处+G325义祠路交叉公园内+新增 | AG2: 恩平+恩平市沙湖六乡市场+新增 | AH2: 恩平+恩平市科达声通电子器材厂（分厂）+新增 | AI2: 恩平+恩平市万国商业城开发有限公司+新增 | AJ2: 恩平+江苏金江建设有限公司+新增 | AK2: 恩平+恩平市君堂镇中心小学（主校区）+新增 | AL2: 开平市国营镇海林场（2条互联网专线+电路租用） | AM2: 开平+开平市公安局+南环簕冲红绿灯+新增 | AN2: 开平+广东开平文旅发展集团有限公司+Z端+新增 | AO2: 开平+开平百事通计算机+新增 | AP2: 开平+开平市百合镇消防专职队+新增 | AQ2: 江门恩平市御茶餐饮店XWXJ
H3: 光缆 | I3: 城区光缆 | J3: 城区光缆 | K3: 乡镇光缆 | L3: 乡镇光缆 | M3: 乡镇光缆 | N3: 乡镇光缆 | O3: 乡镇光缆 | P3: 乡镇光缆 | Q3: 乡镇光缆 | R3: 乡镇光缆 | S3: 乡镇光缆 | T3: 乡镇光缆 | U3: 城区光缆 | V3: 城区光缆 | W3: 城区光缆 | X3: 城区光缆 | Y3: 城区光缆 | Z3: 乡镇光缆 | AA3: 乡镇光缆 | AB3: 城区光缆 | AC3: 乡镇光缆 | AD3: 城区光缆 | AE3: 乡镇光缆 | AF3: 城区光缆 | AG3: 乡镇光缆 | AH3: 城区光缆 | AI3: 城区光缆 | AJ3: 城区光缆 | AK3: 乡镇光缆 | AL3: 乡镇光缆 | AM3: 城区光缆 | AN3: 城区光缆 | AO3: 城区光缆 | AP3: 乡镇光缆 | AQ3: 城区光缆
A4: 序号 | B4: 定额编号 | C4: 项目名称 | D4: 单位 | E4: 技工 | F4: 普工 | G4: 工程量合计 | H4: 数量 | I4: 数量 | J4: 数量 | K4: 数量 | L4: 数量 | M4: 数量 | N4: 数量 | O4: 数量 | P4: 数量 | Q4: 数量 | R4: 数量 | S4: 数量 | T4: 数量 | U4: 数量 | V4: 数量 | W4: 数量 | X4: 数量 | Y4: 数量 | Z4: 数量 | AA4: 数量 | AB4: 数量 | AC4: 数量 | AD4: 数量 | AE4: 数量 | AF4: 数量 | AG4: 数量 | AH4: 数量 | AI4: 数量 | AJ4: 数量 | AK4: 数量 | AL4: 数量 | AM4: 数量 | AN4: 数量 | AO4: 数量 | AP4: 数量 | AQ4: 数量
A5: 1 | B5: TXL1-001 | C5: 直埋光（电）缆工程施工测量 | D5: 百米 | E5: 0.56 | F5: 0.14 | G5: 2.57 | M5: 0.6 | S5: 0.08 | T5: 0.33 | AE5: 0.27 | AF5: 0.8 | AG5: 0.01 | AH5: 0.05 | AI5: 0.12 | AK5: 0.31
A6: 2 | B6: TXL1-002 | C6: 架空光(电)缆工程施工测量 | D6: 百米 | E6: 0.46 | F6: 0.12 | G6: 66.21 | I6: 0.81 | J6: 1.69 | K6: 1.44 | L6: 0.8 | M6: 0.06 | N6: 2.7 | O6: 5.87 | P6: 4.9 | Q6: 0.89 | R6: 0.12 | S6: 9.84 | T6: 3.48 | U6: 1.05 | V6: 0.23 | W6: 1.98 | X6: 0.7 | Y6: 0.59 | AA6: 0.18 | AB6: 1.41 | AC6: 1.75 | AD6: 1.55 | AE6: 1.03 | AF6: 0.66 | AG6: 0.92 | AH6: 2.32 | AI6: 0.45 | AJ6: 1.79 | AK6: 0.96 | AL6: 6.78 | AN6: 0.23 | AO6: 8.48 | AP6: 0.55
A7: 3 | B7: TXL1-003 | C7: 管道光(电)缆工程施工测量 | D7: 百米 | E7: 0.35 | F7: 0.09 | G7: 21.31 | M7: 0.56 | T7: 4.06 | AA7: 0.9 | AE7: 5.78 | AF7: 0.53 | AG7: 0.01 | AH7: 0.01 | AI7: 2.24 | AJ7: 0.62 | AM7: 2.77 | AO7: 0.06 | AQ7: 3.77
A8: 4 | B8: TXL1-005 | C8: GPS定位 | D8: 点 | E8: 0.05 | F8: 0 | G8: 86 | I8: 2 | J8: 2 | K8: 2 | L8: 2 | M8: 2 | N8: 3 | O8: 2 | P8: 2 | Q8: 2 | R8: 2 | S8: 12 | T8: 6 | U8: 2 | V8: 2 | W8: 2 | X8: 2 | Y8: 2 | AA8: 2 | AB8: 2 | AC8: 2 | AD8: 2 | AE8: 3 | AF8: 2 | AG8: 2 | AH8: 2 | AI8: 2 | AJ8: 2 | AK8: 3 | AL8: 2 | AM8: 2 | AN8: 1 | AO8: 4 | AP8: 2 | AQ8: 2
A9: 5 | B9: TXL1-006 | C9: 单盘检验（单窗口） | D9: 芯盘 | E9: 0.02 | F9: 0 | G9: 0
A10: 6 | B10: TXL1-006-1 | C10: 单盘检验（双窗口） | D10: 芯盘 | E10: 0.024 | F10: 0 | G10: 708 | I10: 12 | J10: 12 | K10: 12 | L10: 12 | M10: 12 | N10: 24 | O10: 12 | P10: 12 | Q10: 12 | R10: 24 | S10: 24 | T10: 60 | U10: 48 | V10: 12 | W10: 24 | X10: 12 | Y10: 12 | AA10: 12 | AB10: 12 | AC10: 12 | AD10: 12 | AE10: 48 | AF10: 12 | AG10: 12 | AH10: 12 | AI10: 36 | AJ10: 24 | AK10: 24 | AL10: 24 | AM10: 12 | AN10: 12 | AO10: 48 | AP10: 12 | AQ10: 48
A11: 7 | B11: TXL1-008 | C11: 人工开挖路面混凝土（100mm以内） | D11: 百平方米 | E11: 3.33 | F11: 24.25 | G11: 0.735 | M11: 0.18 | S11: 0.024 | T11: 0.099 | AE11: 0.081 | AF11: 0.24 | AG11: 0.003 | AH11: 0.015 | AK11: 0.093
A12: 8 | B12: TXL1-009 | C12: 人工开挖路面混凝土（每增加10mm） | D12: 百平方米 | E12: 0.33 | F12: 1.75 | G12: 0
A13: 9 | B13: TXL1-010 | C13: 人工开挖路面沥青柏油（100mm以内） | D13: 百平方米 | E13: 1.88 | F13: 13 | G13: 0
A14: 10 | B14: TXL1-011 | C14: 人工开挖路面沥青柏油（每增加10mm） | D14: 百平方米 | E14: 0.19 | F14: 1.25 | G14: 0
A15: 11 | B15: TXL1-012 | C15: 人工开挖路面砂石（100mm以内） | D15: 百平方米 | E15: 1.04 | F15: 6.29 | G15: 0
A16: 12 | B16: TXL1-013 | C16: 人工开挖路面砂石（每增加10mm） | D16: 百平方米 | E16: 0.09 | F16: 0.59 | G16: 0
A17: 13 | B17: TXL1-014 | C17: 人工开挖路面混凝土砌块 | D17: 百平方米 | E17: 0.31 | F17: 2.88 | G17: 0
A18: 14 | B18: TXL1-015 | C18: 人工开挖路面水泥花砖 | D18: 百平方米 | E18: 0.31 | F18: 2.88 | G18: 0.036 | AI18: 0.036
A19: 15 | B19: TXL1-016 | C19: 人工开挖路面条石 | D19: 百平方米 | E19: 5 | F19: 25.88 | G19: 0
A20: 16 | B20: TXL2-001 | C20: 挖、松填光（电）缆沟及接头坑普通土 | D20: 百立方米 | E20: 0 | F20: 39.38 | G20: 1.323 | M20: 0.324 | S20: 0.0432 | T20: 0.1782 | AE20: 0.1458 | AF20: 0.432 | AG20: 0.0054 | AH20: 0.027 | AK20: 0.1674
A21: 17 | B21: TXL2-002 | C21: 挖、松填光（电）缆沟及接头坑硬土 | D21: 百立方米 | E21: 0 | F21: 51.5 | G21: 0.0648 | AI21: 0.0648
A22: 18 | B22: TXL2-003 | C22: 挖、松填光（电）缆沟及接头坑砂砾土 | D22: 百立方米 | E22: 0 | F22: 62.13 | G22: 0
A23: 19 | B23: TXL2-007 | C23: 挖、夯填光（电）缆沟及接头坑普通土 | D23: 百立方米 | E23: 0 | F23: 40.88 | G23: 0
A24: 20 | B24: TXL2-008 | C24: 挖、夯填光（电）缆沟及接头坑硬土 | D24: 百立方米 | E24: 0 | F24: 55 | G24: 0
A25: 21 | B25: TXL2-009 | C25: 挖、夯填光（电）缆沟及接头坑砂砾土 | D25: 百立方米 | E25: 0 | F25: 71.13 | G25: 0
A26: 22 | B26: TXL2-014 | C26: 手推车倒运土方 | D26: 百立方米 | E26: 0 | F26: 12 | G26: 0
A27: 23 | B27: TXL2-021 | C27: 丘陵、水田、城区敷设埋式光缆36芯以下 | D27: 千米条 | E27: 7.44 | F27: 30.58 | G27: 0.241 | M27: 0.06 | S27: 0.008 | T27: 0.033 | AE27: 0.042 | AF27: 0.08 | AG27: 0.001 | AH27: 0.005 | AI27: 0.012
A28: 24 | B28: TXL2-022 | C28: 丘陵、水田、城区敷设埋式光缆72芯以下 | D28: 千米条 | E28: 10.05 | F28: 33.69 | G28: 0
A29: 25 | B29: TXL2-023 | C29: 丘陵、水田、城区敷设埋式光缆96芯以下 | D29: 千米条 | E29: 12.76 | F29: 36.52 | G29: 0
A30: 26 | B30: TXL2-024 | C30: 丘陵、水田、城区敷设埋式光缆144芯以下 | D30: 千米条 | E30: 15.5 | F30: 38.44 | G30: 0
A31: 27 | B31: TXL2-025 | C31: 丘陵、水田、城区敷设埋式光缆288芯以下 | D31: 千米条 | E31: 17.88 | F31: 41.25 | G31: 0
A32: 28 | B32: TXL2-026 | C32: 丘陵、水田、城区敷设埋式光缆288芯以上 | D32: 千米条 | E32: 22.1 | F32: 45 | G32: 0
A33: 29 | B33: TXL2-027 | C33: 山区敷设埋式光缆36芯以下 | D33: 千米条 | E33: 9.05 | F33: 40.22 | G33: 0
A34: 30 | B34: TXL2-028 | C34: 山区敷设埋式光缆72芯以下 | D34: 千米条 | E34: 12.55 | F34: 43.54 | G34: 0
A35: 31 | B35: TXL2-029 | C35: 山区敷设埋式光缆96芯以下 | D35: 千米条 | E35: 15.86 | F35: 47.1 | G35: 0
A36: 32 | B36: TXL2-030 | C36: 山区敷设埋式光缆144芯以下 | D36: 千米条 | E36: 19.2 | F36: 50.14 | G36: 0
A37: 33 | B37: TXL2-031 | C37: 山区敷设埋式光缆288芯以下 | D37: 千米条 | E37: 22.53 | F37: 53.13 | G37: 0
A38: 34 | B38: TXL2-032 | C38: 山区敷设埋式光缆288芯以上 | D38: 千米条 | E38: 27.5 | F38: 57.46 | G38: 0
A39: 35 | B39: TXL2-033 | C39: 敷设埋式电缆200对以下 | D39: 千米条 | E39: 8.35 | F39: 22.84 | G39: 0
... A42: 38 | B42: TXL2-122 | C42: 埋设标石山区 | D42: 个 | E42: 0.09 | F42: 0.18 | G42: 0
...

Sheet Sheet2
A1: 序号 | B1: 1 | C1: 2 | D1: 3 | E1: 4 | F1: 5 | G1: 6 | H1: 7 | I1: 8 | J1: 9 | K1: 10 | L1: 11 | M1: 12 | N1: 13 | O1: 14 | P1: 15 | Q1: 16 | R1: 17 | S1: 18 | T1: 19 | U1: 20 | V1: 21 | W1: 22 | X1: 23 | Y1: 24 | Z1: 25 | AA1: 26 | AB1: 27 | AC1: 28 | AD1: 29 | AE1: 30 | AF1: 31 | AG1: 32 | AH1: 33 | AI1: 34 | AJ1: 35 | AK1: 36 | AL1: 37 | AM1: 38 | AN1: 39 | AO1: 40 | AP1: 41 | AQ1: 42 | AR1: 43 | AS1: 44 | AT1: 45 | AU1: 46 | AV1: 47 | AW1: 48 | AX1: 49 | AY1: 50 | AZ1: 51 | BA1: 52 | BB1: 53 | BC1: 54 | BD1: 55 | BE1: 56 | BF1: 57 | BG1: 58 | BH1: 59 | BI1: 60 | BJ1: 61 | BK1: 62 | BL1: 63 | BM1: 64 | BN1: 65 | BO1: 66 | BP1: 67 | BQ1: 68 | BR1: 69 | BS1: 70 | BT1: 71 | BU1: 72 | BV1: 73 | BW1: 74 | BX1: 75 | BY1: 76 | BZ1: 77 | CA1: 78 | CB1: 79 | CC1: 80 | CD1: 81 | CE1: 82 | CF1: 83 | CG1: 84 | CH1: 85 | CI1: 86 | CJ1: 87 | CK1: 88 | CL1: 89 | CM1: 90 | CN1: 91 | CO1: 92 | CP1: 93 | CQ1: 94 | CR1: 95 | CS1: 96 | CT1: 97 | CU1: 98 | CV1: 99 | CW1: 100 | CX1: 101 | CY1: 102 | CZ1: 103 | DA1: 104 | DB1: 105 | DC1: 106 | DD1: 107 | DE1: 108 | DF1: 109 | DG1: 110 | DH1: 111 | DI1: 112 | DJ1: 113 | DK1: 114 | DL1: 115 | DM1: 116 | DN1: 117 | DO1: 118 | DP1: 119 | DQ1: 120 | DR1: 121 | DS1: 122 | DT1: 123 | DU1: 124 | DV1: 125 | DW1: 126 | DX1: 127 | DY1: 128 | DZ1: 129 | EA1: 130 | EB1: 131 | EC1: 132 | ED1: 133 | EE1: 134 | EF1: 135 | EG1: 136 | EH1: 137 | EI1: 138 | EJ1: 139 | EK1: 140 | EL1: 141 | EM1: 142 | EN1: 143 | EO1: 144 | EP1: 145 | EQ1: 146 | ER1: 147 | ES1: 148 | ET1: 149 | EU1: 150 | EV1: 151 | EW1: 152 | EX1: 153 | EY1: 154 | EZ1: 155 | FA1: 156 | FB1: 157 | FC1: 158 | FD1: 159 | FE1: 160 | FF1: 161 | FG1: 162 | FH1: 163 | FI1: 164 | FJ1: 165 | FK1: 166 | FL1: 167 | FM1: 168 | FN1: 169 | FO1: 170 | FP1: 171 | FQ1: 172 | FR1: 173 | FS1: 174 | FT1: 175 | FU1: 176 | FV1: 177 | FW1: 178 | FX1: 179 | FY1: 180 | FZ1: 181 | GA1: 182 | GB1: 183 | GC1: 184 | GD1: 185 | GE1: 186 | GF1: 187 | GG1: 188 | GH1: 189 | GI1: 190 | GJ1: 191 | GK1: 192 | GL1: 193 | GM1: 194 | GN1: 195 | GO1: 196 | GP1: 197 | GQ1: 198 | GR1: 199 | GS1: 200 | GT1: 201 | GU1: 202 | GV1: 203 | GW1: 204 | GX1: 205 | GY1: 206 | GZ1: 207 | HA1: 208 | HB1: 209 | HC1: 210 | HD1: 211 | HE1: 212 | HF1: 213 | HG1: 214 | HH1: 215 | HI1: 216 | HJ1: 217 | HK1: 218 | HL1: 219 | HM1: 220 | HN1: 221 | HO1: 222 | HP1: 223 | HQ1: 224 | HR1: 225 | HS1: 226 | HT1: 227 | HU1: 228 | HV1: 229 | HW1: 230 | HX1: 231 | HY1: 232 | HZ1: 233 | IA1: 234 | IB1: 235 | IC1: 236 | ID1: 237 | IE1: 238 | IF1: 239 | IG1: 240 | IH1: 241 | II1: 242 | IJ1: 243 | IK1: 244 | IL1: 245 | IM1: 246 | IN1: 247 | IO1: 248 | IP1: 249 | IQ1: 250 | IR1: 251 | IS1: 252 | IT1: 253 | IU1: 254 | IV1: 255 | IW1: 256 | IX1: 257 | IY1: 258 | IZ1: 259 | JA1: 260 | JB1: 261 | JC1: 262 | JD1: 263 | JE1: 264 | JF1: 265 | JG1: 266 | JH1: 267 | JI1: 268 | JJ1: 269 | JK1: 270 | JL1: 271 | JM1: 272 | JN1: 273 | JO1: 274 | JP1: 275 | JQ1: 276 | JR1: 277 | JS1: 278 | JT1: 279 | JU1: 280 | JV1: 281 | JW1: 282 | JX1: 283 | JY1: 284 | JZ1: 285 | KA1: 286 | KB1: 287 | KC1: 288 | KD1: 289 | KE1: 290 | KF1: 291 | KG1: 292 | KH1: 293 | KI1: 294 | KJ1: 295 | KK1: 296 | KL1: 297 | KM1: 298 | KN1: 299 | KO1: 300 | KP1: 301 | KQ1: 302 | KR1: 303 | KS1: 304 | KT1: 305 | KU1: 306 | KV1: 307 | KW1: 308 | KX1: 309 | KY1: 310 | KZ1: 311 | LA1: 312 | LB1: 313 | LC1: 314 | LD1: 315 | LE1: 316 | LF1: 317 | LG1: 318 | LH1: 319 | LI1: 320 | LJ1: 321 | LK1: 322 | LL1: 323 | LM1: 323 | LN1: 323 | LO1: 324 | LP1: 325 | LQ1: 326
A2: 定额编号 | B2: TXL1-001 | C2: TXL1-002 | D2: TXL1-003 | E2: TXL1-005 | F2: TXL1-006 | G2: TXL1-006-1 | H2: TXL1-008 | I2: TXL1-009 | J2: TXL1-010 | K2: TXL1-011 | L2: TXL1-012 | M2: TXL1-013 | N2: TXL1-014 | O2: TXL1-015 | P2: TXL1-016 | Q2: TXL2-001 | R2: TXL2-002 | S2: TXL2-003 | T2: TXL2-007 | U2: TXL2-008 | V2: TXL2-009 | W2: TXL2-014 | X2: TXL2-021 | Y2: TXL2-022 | Z2: TXL2-023 | AA2: TXL2-024 | AB2: TXL2-025 | AC2: TXL2-026 | AD2: TXL2-027 | AE2: TXL2-028 | AF2: TXL2-029 | AG2: TXL2-030 | AH2: TXL2-031 | AI2: TXL2-032 | AJ2: TXL2-033 | AK2: TXL2-109 | AL2: TXL2-121 | AM2: TXL2-122 | AN2: TXL2-123 | AO2: TXL2-127 | AP2: TXL3-001 | AQ2: TXL3-004 | AR2: TXL3-007 | AS2: TXL3-010 | AT2: TXL3-048 | AU2: TXL3-051 | AV2: TXL3-054 | AW2: TXL3-057 | AX2: TXL3-142 | AY2: TXL3-143 | AZ2: TXL3-144 | BA2: TXL3-145 | BB2: TXL3-146 | BC2: TXL3-147 | BD2: TXL3-149 | BE2: TXL3-150 | BF2: TXL3-169 | BG2: TXL3-170 | BH2: TXL3-171 | BI2: TXL3-180 | BJ2: TXL3-192 | BK2: TXL3-193 | BL2: TXL3-194 | BM2: TXL3-195 | BN2: TXL3-196 | BO2: TXL3-197 | BP2: TXL3-198 | BQ2: TXL3-199 | BR2: TXL3-200 | BS2: TXL3-201 | BT2: TXL3-218 | BU2: TXL4-001 | BV2: TXL4-002 | BW2: TXL4-003 | BX2: TXL4-004 | BY2: TXL4-005 | BZ2: TXL4-005-1 | CA2: TXL4-005-2 | CB2: TXL4-006 | CC2: TXL4-007 | CD2: TXL4-008 | CE2: TXL4-009 | CF2: TXL4-010 | CG2: TXL4-011 | CH2: TXL4-012 | CI2: TXL4-013 | CJ2: TXL4-014 | CK2: TXL4-015 | CL2: TXL4-016 | CM2: TXL4-019 | CN2: TXL4-024 | CO2: TXL4-033 | CP2: TXL4-034 | CQ2: TXL4-035 | CR2: TXL4-036 | CS2: TXL4-037 | CT2: TXL4-038 | CU2: TXL4-039 | CV2: TXL4-040 | CW2: TXL4-041 | CX2: TXL4-042 | CY2: TXL4-043 | CZ2: TXL4-044 | DA2: TXL4-045 | DB2: TXL4-046 | DC2: TXL4-047 | DD2: TXL4-048 | DE2: TXL4-049 | DF2: TXL4-050 | DG2: TXL4-051 | DH2: TXL4-052 | DI2: TXL4-053 | DJ2: TXL4-053-1 | DK2: TXL4-053-2 | DL2: TXL4-054 | DM2: TXL4-056 | DN2: TXL4-057 | DO2: TXL4-058 | DP2: TXL4-057-1 | DQ2: TXL4-059 | DR2: TXL4-060 | DS2: TXL4-061 | DT2: TXL4-062 | DU2: TXL5-042 | DV2: TXL5-043 | DW2: TXL5-044 | DX2: TXL5-045 | DY2: TXL5-046 | DZ2: TXL5-049 | EA2: TXL5-050 | EB2: TXL5-051 | EC2: TXL5-052 | ED2: TXL5-054 | EE2: TXL5-055 | EF2: TXL5-056 | EG2: TXL5-057 | EH2: TXL5-058 | EI2: TXL5-068 | EJ2: TXL5-069 | EK2: TXL5-070 | EL2: TXL5-071 | EM2: TXL5-074 | EN2: TXL5-076 | EO2: TXL5-077 | EP2: TXL6-001 | EQ2: TXL6-002 | ER2: TXL6-003 | ES2: TXL6-004 | ET2: TXL6-005 | EU2: TXL6-006 | EV2: TXL6-007 | EW2: TXL6-008 | EX2: TXL6-009 | EY2: TXL6-011 | EZ2: TXL6-013 | FA2: TXL6-015 | FB2: TXL6-018 | FC2: TXL6-027 | FD2: TXL6-029 | FE2: TXL6-073 | FF2: TXL6-073-1 | FG2: TXL6-075 | FH2: TXL6-075-1 | FI2: TXL6-079 | FJ2: TXL6-079-1 | FK2: TXL6-082 | FL2: TXL6-082-1 | FM2: TXL6-072 | FN2: TXL6-072-1 | FO2: TXL6-102 | FP2: TXL6-103 | FQ2: TXL6-104 | FR2: TXL6-106 | FS2: TXL6-108 | FT2: TXL6-110 | FU2: TXL6-112 | FV2: TXL6-113 | FW2: TXL6-114 | FX2: TXL6-115 | FY2: TXL6-116 | FZ2: TXL6-117 | GA2: TXL6-118 | GB2: TXL6-119 | GC2: TXL6-133 | GD2: TXL6-134 | GE2: TXL6-135 | GF2: TXL6-136 | GG2: TXL6-137 | GH2: TXL6-139 | GI2: TXL6-152 | GJ2: TXL6-153 | GK2: TXL6-165 | GL2: TXL6-166 | GM2: TXL6-167 | GN2: TXL6-168 | GO2: TXL6-169 | GP2: TXL6-170 | GQ2: TXL6-199 | GR2: TXL7-004 | GS2: TXL7-005 | GT2: TXL7-006 | GU2: TXL7-007 | GV2: TXL7-008 | GW2: TXL7-009 | GX2: TXL7-010 | GY2: TXL7-014 | GZ2: TXL7-016 | HA2: TXL7-023 | HB2: TXL7-024 | HC2: TXL7-025 | HD2: TXL7-026 | HE2: TXL7-027 | HF2: TXL7-028 | HG2: TXL7-029 | HH2: TXL7-030 | HI2: TXL7-031 | HJ2: TXL7-032 | HK2: TXL7-033 | HL2: TXL7-034 | HM2: TXL7-035 | HN2: TXL7-036 | HO2: TXL7-042 | HP2: TXL7-043 | HQ2: TXL7-044 | HR2: TXL7-045 | HS2: TXL7-046 | HT2: TXL7-056 | HU2: TXL7-064 | HV2: TXL7-065 | HW2: TXL7-066 | HX2: TXL7-067 | HY2: TXL7-077 | HZ2: TXL7-082 | IA2: TSY1-005 | IB2: TSY1-006 | IC2: TSY1-007 | ID2: TSY1-008 | IE2: TSY1-009 | IF2: TSY1-010 | IG2: TSY1-011 | IH2: TSY1-029 | II2: TSY1-030 | IJ2: TSY1-051 | IK2: TSY1-054 | IL2: TSY1-055 | IM2: TSY1-056 | IN2: TSY1-067 | IO2: TSY1-068 | IP2: TSY1-069 | IQ2: TSY1-079 | IR2: TSY1-080 | IS2: TSY1-081 | IT2: TSY1-082 | IU2: TSY1-089 | IV2: TSY1-089 | IW2: TSY1-090 | IX2: TSY1-100 | IY2: TSY2-002 | IZ2: TSY2-003 | JA2: TSY2-005 | JB2: TSY2-006 | JC2: TSY2-007 | JD2: TSY2-008 | JE2: TSY2-009 | JF2: TSY2-010 | JG2: TSY2-011 | JH2: TSY2-012 | JI2: TSY2-013 | JJ2: TSY2-014 | JK2: TSY2-015 | JL2: TSY2-016 | JM2: TSY2-019 | JN2: TSY2-059 | JO2: TSY2-064 | JP2: TSY2-067 | JQ2: TSY2-068 | JR2: TSY2-092 | JS2: TSY2-095 | JT2: TSY2-099 | JU2: TSY2-101 | JV2: TSY3-018 | JW2: TSY3-019 | JX2: TSY3-027 | JY2: TSY3-031 | JZ2: TSY3-032 | KA2: TSY3-033 | KB2: TSY3-034 | KC2: TSY3-035 | KD2: TSY3-036 | KE2: TSY3-047 | KF2: TSY3-063 | KG2: TSY3-064 | KH2: TSY3-066 | KI2: TSY3-067 | KJ2: TSY4-002 | KK2: TSY4-003 | KL2: TSY4-007 | KM2: TSY4-011 | KN2: TSY4-013 | KO2: TSY4-014 | KP2: TSY4-017 | KQ2: TSW2-105 | KR2: TSW2-106 | KS2: TSW2-107 | KT2: TSW2-108 | KU2: TSW2-109 | KV2: TSW2-110 | KW2: TSW2-111 | KX2: TSW2-112 | KY2: TSD3-006 | KZ2: TSD3-050 | LA2: 客响补充 | LB2: 客响补充 | LC2: 客响补充 | LD2: 客响补充 | LE2: 客响补充 | LF2: 客响补充 | LG2: 客响补充 | LH2: 客响补充 | LI2: 客响补充 | LJ2: 客响补充 | LK2: 客响补充 | LL2: 客响补充 | LO2: TXL4-011 | LP2: TSY1-007 | LQ2: TXL4-054
