Workbook
Name _0_101: '[1]GSM-04-03'!#REF!

Sheet 封面
A1: 工 程 结 算 书
B2: 工程名称： | C2: 江门700MHz频段共建共享五期工程无线主设备项目——子项4：常规项目
B3: 建设单位： | C3: 中国移动通信集团广东有限公司江门分公司
B4: 项目编号： | C4: B25302110AA0014
B5: 施工单位： | C5: 武汉虹信技术服务有限责任公司
B6: 编制单位： | C6: 武汉虹信技术服务有限责任公司
B7: 编 制 人： | C7: 陈志仁
B8: 工程造价（不含税）： | C8: =表1!I13 -> 99351.903
B10: 编制日期： | C10: 45818

Sheet 工作量总表
A1: 工作量总表
A2: =表1!A3 -> 项目名称：江门700MHz频段共建共享五期工程无线主设备项目——子项4：常规项目
A3: =表1!F4 -> 建设单位：中国移动通信集团广东有限公司江门分公司
A4: =表1!A4 -> 0 | Y4: 表格编号：WXSB-01
A5: 序号 | B5: 区域 | C5: 基站名称 | D5: 无线工日 | E5: 室外项目安装 | F5: 主要材料费 | G5: 人工费 | H5: 仪表使用费 | I5: 直接工程费 | J5: 措施费 | K5: 直接费 | L5: 间接费 | M5: 利润 | N5: 企业管理费 | O5: 规费 | P5: 其他费（系统录入费、标签制作费、二次运输费等） | Q5: 安全生产费 | R5: 调遣费 | S5: 建筑安装工程费(不含税） | T5: 建筑安装工程费（安全生产费）(不含税） | U5: 施工费（不含税）（降点后） | V5: 小计降点前（不含税） | W5: 小计降点前（含税） | X5: 结算价（降点后不含税金额） | Y5: 税金 | Z5: 结算价（降点后含税金额）
A6: 1 | B6: 鹤山 | C6: CBN-江门鹤山市连城C-RAN1（江门鹤山三连工业区二）U-Z5H | D6: =SUMIFS(表3!$65:$65,表3!$2:$2,工作量总表!C6) -> 49.403 | F6: =SUMIFS(表四乙供主材!$11:$11,表四乙供主材!$2:$2,C:C) -> 200 | G6: =D6*114 -> 5631.942 | H6: =SUMIFS(表3丙!$7:$7,表3丙!$2:$2,工作量总表!C6) -> 536.4 | I6: =F6+G6+H6 -> 6368.342 | J6: =G6*$D$115+R6 -> 2739.1383 | K6: =I6+J6 -> 9107.4803 | L6: =N6+O6 -> 3440.5534 | M6: =G6*20% -> 1126.3884 | N6: =G6*$H$105 -> 1543.1521 | O6: =G6*33.69% -> 1897.4013 | P6: =INDEX(表6其他费!$G$11:$GK$11,ROW()-5) -> 300 | Q6: =T6*2% -> 262.86955 | R6: =SUMIFS(计列施工队伍调遣费站点!H:H,计列施工队伍调遣费站点!C:C,工作量总表!C6) -> 1410 | S6: =K6+L6+M6 -> 13674.422 | T6: =I6+G6*$F$115+'表二（安全生产费）'!$I$14/17+M6+L6 -> 13143.478 | U6: =(S6-O6-F6)*0.17 -> 1968.0935 | V6: =U6/0.17+F6+O6+Q6+P6 -> 14237.292 | W6: =V6*1.09 -> 15518.648 | X6: =ROUND(U6+F6+O6+Q6+P6,2) -> 4628.36 | Y6: =X6*9% -> 416.5524 | Z6: =X6+Y6 -> 5044.9124 | AA6: JMHSWX25052615025R
A7: 2 | B7: 鹤山 | C7: CBN-江门鹤山路管所（江门鹤山裕兴雨具）U-Z5H | D7: =SUMIFS(表3!$65:$65,表3!$2:$2,工作量总表!C7) -> 48.906 | F7: =SUMIFS(表四乙供主材!$11:$11,表四乙供主材!$2:$2,C:C) -> 200 | G7: =D7*114 -> 5575.284 | H7: =SUMIFS(表3丙!$7:$7,表3丙!$2:$2,工作量总表!C7) -> 536.4 | I7: =F7+G7+H7 -> 6311.684 | J7: =G7*$D$115+R7 -> 1315.767 | K7: =I7+J7 -> 7627.451 | L7: =N7+O7 -> 3405.941 | M7: =G7*20% -> 1115.0568 | N7: =G7*$H$105 -> 1527.6278 | O7: =G7*33.69% -> 1878.3132 | P7: =INDEX(表6其他费!$G$11:$GK$11,ROW()-5) -> 300 | Q7: =T7*2% -> 260.54102 | R7: =SUMIFS(计列施工队伍调遣费站点!H:H,计列施工队伍调遣费站点!C:C,工作量总表!C7) -> 0 | S7: =K7+L7+M7 -> 12148.449 | T7: =I7+G7*$F$115+'表二（安全生产费）'!$I$14/17+M7+L7 -> 13027.051 | U7: =(S7-O7-F7)*0.17 -> 1711.9231 | V7: =U7/0.17+F7+O7+Q7+P7 -> 12708.99 | W7: =V7*1.09 -> 13852.799 | X7: =ROUND(U7+F7+O7+Q7+P7,2) -> 4350.78 | Y7: =X7*9% -> 391.5702 | Z7: =X7+Y7 -> 4742.3502 | AA7: JMHSWX25052615022R
A8: 3 | B8: 鹤山 | C8: CBN-江门鹤山市鹤城二（江门鹤山创美）U-Z5H | D8: =SUMIFS(表3!$65:$65,表3!$2:$2,工作量总表!C8) -> 47.517 | F8: =SUMIFS(表四乙供主材!$11:$11,表四乙供主材!$2:$2,C:C) -> 200 | G8: =D8*114 -> 5416.938 | H8: =SUMIFS(表3丙!$7:$7,表3丙!$2:$2,工作量总表!C8) -> 536.4 | I8: =F8+G8+H8 -> 6153.338 | J8: =G8*$D$115+R8 -> 1278.3974 | K8: =I8+J8 -> 7431.7354 | L8: =N8+O8 -> 3309.2074 | M8: =G8*20% -> 1083.3876 | N8: =G8*$H$105 -> 1484.241 | O8: =G8*33.69% -> 1824.9664 | P8: =INDEX(表6其他费!$G$11:$GK$11,ROW()-5) -> 300 | Q8: =T8*2% -> 254.03332 | R8: =SUMIFS(计列施工队伍调遣费站点!H:H,计列施工队伍调遣费站点!C:C,工作量总表!C8) -> 0 | S8: =K8+L8+M8 -> 11824.33 | T8: =I8+G8*$F$115+'表二（安全生产费）'!$I$14/17+M8+L8 -> 12701.666 | U8: =(S8-O8-F8)*0.17 -> 1665.8919 | V8: =U8/0.17+F8+O8+Q8+P8 -> 12378.364 | W8: =V8*1.09 -> 13492.416 | X8: =ROUND(U8+F8+O8+Q8+P8,2) -> 4244.89 | Y8: =X8*9% -> 382.0401 | Z8: =X8+Y8 -> 4626.9301 | AA8: JMHSWX25052615021R
A9: 4 | B9: 鹤山 | C9: CBN-江门鹤山福迳（江门鹤山甘牛集团）U-Z5H | D9: =SUMIFS(表3!$65:$65,表3!$2:$2,工作量总表!C9) -> 47.361 | F9: =SUMIFS(表四乙供主材!$11:$11,表四乙供主材!$2:$2,C:C) -> 200 | G9: =D9*114 -> 5399.154 | H9: =SUMIFS(表3丙!$7:$7,表3丙!$2:$2,工作量总表!C9) -> 536.4 | I9: =F9+G9+H9 -> 6135.554 | J9: =G9*$D$115+R9 -> 1274.2003 | K9: =I9+J9 -> 7409.7543 | L9: =N9+O9 -> 3298.3432 | M9: =G9*20% -> 1079.8308 | N9: =G9*$H$105 -> 1479.3682 | O9: =G9*33.69% -> 1818.975 | P9: =INDEX(表6其他费!$G$11:$GK$11,ROW()-5) -> 300 | Q9: =T9*2% -> 253.30243 | R9: =SUMIFS(计列施工队伍调遣费站点!H:H,计列施工队伍调遣费站点!C:C,工作量总表!C9) -> 0 | S9: =K9+L9+M9 -> 11787.928 | T9: =I9+G9*$F$115+'表二（安全生产费）'!$I$14/17+M9+L9 -> 12665.122 | U9: =(S9-O9-F9)*0.17 -> 1660.7221 | V9: =U9/0.17+F9+O9+Q9+P9 -> 12341.231 | W9: =V9*1.09 -> 13451.942 | X9: =ROUND(U9+F9+O9+Q9+P9,2) -> 4233 | Y9: =X9*9% -> 380.97 | Z9: =X9+Y9 -> 4613.97 | AA9: JMHSWX25051308476R
A10: 5 | B10: 鹤山 | C10: CBN-江门蓬江区滨江新区1二（江门新昌公园）U-Z5H | D10: =SUMIFS(表3!$65:$65,表3!$2:$2,工作量总表!C10) -> 59.937 | F10: =SUMIFS(表四乙供主材!$11:$11,表四乙供主材!$2:$2,C:C) -> 200 | G10: =D10*114 -> 6832.818 | H10: =SUMIFS(表3丙!$7:$7,表3丙!$2:$2,工作量总表!C10) -> 536.4 | I10: =F10+G10+H10 -> 7569.218 | J10: =G10*$D$115+R10 -> 1612.545 | K10: =I10+J10 -> 9181.763 | L10: =N10+O10 -> 4174.1685 | M10: =G10*20% -> 1366.5636 | N10: =G10*$H$105 -> 1872.1921 | O10: =G10*33.69% -> 2301.9764 | P10: =INDEX(表6其他费!$G$11:$GK$11,ROW()-5) -> 1100 | Q10: =T10*2% -> 312.22315 | R10: =SUMIFS(计列施工队伍调遣费站点!H:H,计列施工队伍调遣费站点!C:C,工作量总表!C10) -> 0 | S10: =K10+L10+M10 -> 14722.495 | T10: =I10+G10*$F$115+'表二（安全生产费）'!$I$14/17+M10+L10 -> 15611.158 | U10: =(S10-O10-F10)*0.17 -> 2077.4882 | V10: =U10/0.17+F10+O10+Q10+P10 -> 16134.718 | W10: =V10*1.09 -> 17586.843 | X10: =ROUND(U10+F10+O10+Q10+P10,2) -> 5991.69 | Y10: =X10*9% -> 539.2521 | Z10: =X10+Y10 -> 6530.9421 | AA10: JMPJWX25051308301R
A11: 6 | B11: 鹤山 | C11: CBN-江门鹤山浩龙（江门鹤山鹤城联东（设备替换））U-Z5H | D11: =SUMIFS(表3!$65:$65,表3!$2:$2,工作量总表!C11) -> 75.173 | F11: =SUMIFS(表四乙供主材!$11:$11,表四乙供主材!$2:$2,C:C) -> 200 | G11: =D11*114 -> 8569.722 | H11: =SUMIFS(表3丙!$7:$7,表3丙!$2:$2,工作量总表!C11) -> 536.4 | I11: =F11+G11+H11 -> 9306.122 | J11: =G11*$D$115+R11 -> 2022.4544 | K11: =I11+J11 -> 11328.576 | L11: =N11+O11 -> 5235.2432 | M11: =G11*20% -> 1713.9444 | N11: =G11*$H$105 -> 2348.1038 | O11: =G11*33.69% -> 2887.1393 | P11: =INDEX(表6其他费!$G$11:$GK$11,ROW()-5) -> 1100 | Q11: =T11*2% -> 383.60643 | R11: =SUMIFS(计列施工队伍调遣费站点!H:H,计列施工队伍调遣费站点!C:C,工作量总表!C11) -> 0 | S11: =K11+L11+M11 -> 18277.764 | T11: =I11+G11*$F$115+'表二（安全生产费）'!$I$14/17+M11+L11 -> 19180.322 | U11: =(S11-O11-F11)*0.17 -> 2582.4062 | V11: =U11/0.17+F11+O11+Q11+P11 -> 19761.37 | W11: =V11*1.09 -> 21539.894 | X11: =ROUND(U11+F11+O11+Q11+P11,2) -> 7153.15 | Y11: =X11*9% -> 643.7835 | Z11: =X11+Y11 -> 7796.9335 | AA11: JMHSWX25041800897R
A12: 7 | B12: 鹤山 | C12: CBN-江门礼乐新丰（江门江海东海路（设备替换））U-Z5H | D12: =SUMIFS(表3!$65:$65,表3!$2:$2,工作量总表!C12) -> 75.057 | F12: =SUMIFS(表四乙供主材!$11:$11,表四乙供主材!$2:$2,C:C) -> 200 | G12: =D12*114 -> 8556.498 | H12: =SUMIFS(表3丙!$7:$7,表3丙!$2:$2,工作量总表!C12) -> 536.4 | I12: =F12+G12+H12 -> 9292.898 | J12: =G12*$D$115+R12 -> 2019.3335 | K12: =I12+J12 -> 11312.232 | L12: =N12+O12 -> 5227.1646 | M12: =G12*20% -> 1711.2996 | N12: =G12*$H$105 -> 2344.4805 | O12: =G12*33.69% -> 2882.6842 | P12: =INDEX(表6其他费!$G$11:$GK$11,ROW()-5) -> 1100 | Q12: =T12*2% -> 383.06295 | R12: =SUMIFS(计列施工队伍调遣费站点!H:H,计列施工队伍调遣费站点!C:C,工作量总表!C12) -> 0 | S12: =K12+L12+M12 -> 18250.696 | T12: =I12+G12*$F$115+'表二（安全生产费）'!$I$14/17+M12+L12 -> 19153.148 | U12: =(S12-O12-F12)*0.17 -> 2578.562 | V12: =U12/0.17+F12+O12+Q12+P12 -> 19733.759 | W12: =V12*1.09 -> 21509.797 | X12: =ROUND(U12+F12+O12+Q12+P12,2) -> 7144.31 | Y12: =X12*9% -> 642.9879 | Z12: =X12+Y12 -> 7787.2979 | AA12: JMJHWX25041800899R
A13: 8 | B13: 鹤山 | C13: CBN-江门轻轨礼乐站（江门捷宏一品）U-Z5H | D13: =SUMIFS(表3!$65:$65,表3!$2:$2,工作量总表!C13) -> 74.133 | F13: =SUMIFS(表四乙供主材!$11:$11,表四乙供主材!$2:$2,C:C) -> 224.48 | G13: =D13*114 -> 8451.162 | H13: =SUMIFS(表3丙!$7:$7,表3丙!$2:$2,工作量总表!C13) -> 536.4 | I13: =F13+G13+H13 -> 9212.042 | J13: =G13*$D$115+R13 -> 1994.4742 | K13: =I13+J13 -> 11206.516 | L13: =N13+O13 -> 5162.8149 | M13: =G13*20% -> 1690.2324 | N13: =G13*$H$105 -> 2315.6184 | O13: =G13*33.69% -> 2847.1965 | P13: =INDEX(表6其他费!$G$11:$GK$11,ROW()-5) -> 1100 | Q13: =T13*2% -> 379.22346 | R13: =SUMIFS(计列施工队伍调遣费站点!H:H,计列施工队伍调遣费站点!C:C,工作量总表!C13) -> 0 | S13: =K13+L13+M13 -> 18059.563 | T13: =I13+G13*$F$115+'表二（安全生产费）'!$I$14/17+M13+L13 -> 18961.173 | U13: =(S13-O13-F13)*0.17 -> 2547.9408 | V13: =U13/0.17+F13+O13+Q13+P13 -> 19538.787 | W13: =V13*1.09 -> 21297.278 | X13: =ROUND(U13+F13+O13+Q13+P13,2) -> 7098.84 | Y13: =X13*9% -> 638.8956 | Z13: =X13+Y13 -> 7737.7356 | AA13: JMJHWX24122521503R
A14: 9 | B14: 鹤山 | C14: CBN-江门汇聪电子（江门白水带山脚）U-Z5H | D14: =SUMIFS(表3!$65:$65,表3!$2:$2,工作量总表!C14) -> 80.999 | F14: =SUMIFS(表四乙供主材!$11:$11,表四乙供主材!$2:$2,C:C) -> 200 | G14: =D14*114 -> 9233.886 | H14: =SUMIFS(表3丙!$7:$7,表3丙!$2:$2,工作量总表!C14) -> 536.4 | I14: =F14+G14+H14 -> 9970.286 | J14: =G14*$D$115+R14 -> 2179.1971 | K14: =I14+J14 -> 12149.483 | L14: =N14+O14 -> 5640.981 | M14: =G14*20% -> 1846.7772 | N14: =G14*$H$105 -> 2530.0848 | O14: =G14*33.69% -> 3110.8962 | P14: =INDEX(表6其他费!$G$11:$GK$11,ROW()-5) -> 1100 | Q14: =T14*2% -> 410.90225 | R14: =SUMIFS(计列施工队伍调遣费站点!H:H,计列施工队伍调遣费站点!C:C,工作量总表!C14) -> 0 | S14: =K14+L14+M14 -> 19637.241 | T14: =I14+G14*$F$115+'表二（安全生产费）'!$I$14/17+M14+L14 -> 20545.112 | U14: =(S14-O14-F14)*0.17 -> 2775.4787 | V14: =U14/0.17+F14+O14+Q14+P14 -> 21148.144 | W14: =V14*1.09 -> 23051.476 | X14: =ROUND(U14+F14+O14+Q14+P14,2) -> 7597.28 | Y14: =X14*9% -> 683.7552 | Z14: =X14+Y14 -> 8281.0352 | AA14: JMJHWX24122845347R
A15: 10 | B15: 鹤山 | C15: CBN-江门鹤山大朗（江门鹤山址山昆中石北）U-Z5H | D15: =SUMIFS(表3!$65:$65,表3!$2:$2,工作量总表!C15) -> 42.4455 | F15: =SUMIFS(表四乙供主材!$11:$11,表四乙供主材!$2:$2,C:C) -> 224.48 | G15: =D15*114 -> 4838.787 | H15: =SUMIFS(表3丙!$7:$7,表3丙!$2:$2,工作量总表!C15) -> 536.4 | I15: =F15+G15+H15 -> 5599.667 | J15: =G15*$D$115+R15 -> 1141.9537 | K15: =I15+J15 -> 6741.6207 | L15: =N15+O15 -> 2956.015 | M15: =G15*20% -> 967.7574 | N15: =G15*$H$105 -> 1325.8276 | O15: =G15*33.69% -> 1630.1873 | P15: =INDEX(表6其他费!$G$11:$GK$11,ROW()-5) -> 300 | Q15: =T15*2% -> 230.76207 | R15: =SUMIFS(计列施工队伍调遣费站点!H:H,计列施工队伍调遣费站点!C:C,工作量总表!C15) -> 0 | S15: =K15+L15+M15 -> 10665.393 | T15: =I15+G15*$F$115+'表二（安全生产费）'!$I$14/17+M15+L15 -> 11538.103 | U15: =(S15-O15-F15)*0.17 -> 1497.8234 | V15: =U15/0.17+F15+O15+Q15+P15 -> 11196.155 | W15: =V15*1.09 -> 12203.809 | X15: =ROUND(U15+F15+O15+Q15+P15,2) -> 3883.25 | Y15: =X15*9% -> 349.4925 | Z15: =X15+Y15 -> 4232.7425 | AA15: JMHSWX25071541474R
A16: 11 | B16: 鹤山 | C16: CBN-江门荷塘（江门蓬江技师荷塘校区）U-Z5H | D16: =SUMIFS(表3!$65:$65,表3!$2:$2,工作量总表!C16) -> 51.601 | F16: =SUMIFS(表四乙供主材!$11:$11,表四乙供主材!$2:$2,C:C) -> 448.48 | G16: =D16*114 -> 5882.514 | H16: =SUMIFS(表3丙!$7:$7,表3丙!$2:$2,工作量总表!C16) -> 536.4 | I16: =F16+G16+H16 -> 6867.394 | J16: =G16*$D$115+R16 -> 1388.2733 | K16: =I16+J16 -> 8255.6673 | L16: =N16+O16 -> 3593.6278 | M16: =G16*20% -> 1176.5028 | N16: =G16*$H$105 -> 1611.8088 | O16: =G16*33.69% -> 1981.819 | P16: =INDEX(表6其他费!$G$11:$GK$11,ROW()-5) -> 1100 | Q16: =T16*2% -> 278.13716 | R16: =SUMIFS(计列施工队伍调遣费站点!H:H,计列施工队伍调遣费站点!C:C,工作量总表!C16) -> 0 | S16: =K16+L16+M16 -> 13025.798 | T16: =I16+G16*$F$115+'表二（安全生产费）'!$I$14/17+M16+L16 -> 13906.858 | U16: =(S16-O16-F16)*0.17 -> 1801.2348 | V16: =U16/0.17+F16+O16+Q16+P16 -> 14403.935 | W16: =V16*1.09 -> 15700.289 | X16: =ROUND(U16+F16+O16+Q16+P16,2) -> 5609.67 | Y16: =X16*9% -> 504.8703 | Z16: =X16+Y16 -> 6114.5403 | AA16: JMPJWX25081257109R | AC16: 配套工作量小，放主设备结算
A17: 12 | B17: 鹤山 | C17: CBN-江门益晖印刷（江门永达顺（新））U-Z5H | D17: =SUMIFS(表3!$65:$65,表3!$2:$2,工作量总表!C17) -> 88.689 | F17: =SUMIFS(表四乙供主材!$11:$11,表四乙供主材!$2:$2,C:C) -> 200 | G17: =D17*114 -> 10110.546 | H17: =SUMIFS(表3丙!$7:$7,表3丙!$2:$2,工作量总表!C17) -> 536.4 | I17: =F17+G17+H17 -> 10846.946 | J17: =G17*$D$115+R17 -> 2386.0889 | K17: =I17+J17 -> 13233.035 | L17: =N17+O17 -> 6176.5326 | M17: =G17*20% -> 2022.1092 | N17: =G17*$H$105 -> 2770.2896 | O17: =G17*33.69% -> 3406.2429 | P17: =INDEX(表6其他费!$G$11:$GK$11,ROW()-5) -> 1100 | Q17: =T17*2% -> 446.93122 | R17: =SUMIFS(计列施工队伍调遣费站点!H:H,计列施工队伍调遣费站点!C:C,工作量总表!C17) -> 0 | S17: =K17+L17+M17 -> 21431.677 | T17: =I17+G17*$F$115+'表二（安全生产费）'!$I$14/17+M17+L17 -> 22346.561 | U17: =(S17-O17-F17)*0.17 -> 3030.3237 | V17: =U17/0.17+F17+O17+Q17+P17 -> 22978.608 | W17: =V17*1.09 -> 25046.683 | X17: =ROUND(U17+F17+O17+Q17+P17,2) -> 8183.5 | Y17: =X17*9% -> 736.515 | Z17: =X17+Y17 -> 8920.015 | AA17: JMPJWX25090573549R
A18: 13 | B18: 鹤山 | C18: CBN-江门三堡（江门蓬江元岭村西）U-Z5H | D18: =SUMIFS(表3!$65:$65,表3!$2:$2,工作量总表!C18) -> 28.702 | F18: =SUMIFS(表四乙供主材!$11:$11,表四乙供主材!$2:$2,C:C) -> 200 | G18: =D18*114 -> 3272.028 | H18: =SUMIFS(表3丙!$7:$7,表3丙!$2:$2,工作量总表!C18) -> 536.4 | I18: =F18+G18+H18 -> 4008.428 | J18: =G18*$D$115+R18 -> 772.19861 | K18: =I18+J18 -> 4780.6266 | L18: =N18+O18 -> 1998.8819 | M18: =G18*20% -> 654.4056 | N18: =G18*$H$105 -> 896.53567 | O18: =G18*33.69% -> 1102.3462 | P18: =INDEX(表6其他费!$G$11:$GK$11,ROW()-5) -> 300 | Q18: =T18*2% -> 165.88181 | R18: =SUMIFS(计列施工队伍调遣费站点!H:H,计列施工队伍调遣费站点!C:C,工作量总表!C18) -> 0 | S18: =K18+L18+M18 -> 7433.9141 | T18: =I18+G18*$F$115+'表二（安全生产费）'!$I$14/17+M18+L18 -> 8294.0903 | U18: =(S18-O18-F18)*0.17 -> 1042.3665 | V18: =U18/0.17+F18+O18+Q18+P18 -> 7899.7959 | W18: =V18*1.09 -> 8610.7776 | X18: =ROUND(U18+F18+O18+Q18+P18,2) -> 2810.59 | Y18: =X18*9% -> 252.9531 | Z18: =X18+Y18 -> 3063.5431 | AA18: JMPJWX25090573548R
A19: 14 | B19: 鹤山 | C19: CBN-江门鹤山大富（江门鹤山大墩村）U-Z5H | D19: =SUMIFS(表3!$65:$65,表3!$2:$2,工作量总表!C19) -> 78.6265 | F19: =SUMIFS(表四乙供主材!$11:$11,表四乙供主材!$2:$2,C:C) -> 200 | G19: =D19*114 -> 8963.421 | H19: =SUMIFS(表3丙!$7:$7,表3丙!$2:$2,工作量总表!C19) -> 536.4 | I19: =F19+G19+H19 -> 9699.821 | J19: =G19*$D$115+R19 -> 2115.3674 | K19: =I19+J19 -> 11815.188 | L19: =N19+O19 -> 5475.7539 | M19: =G19*20% -> 1792.6842 | N19: =G19*$H$105 -> 2455.9774 | O19: =G19*33.69% -> 3019.7765 | P19: =INDEX(表6其他费!$G$11:$GK$11,ROW()-5) -> 1100 | Q19: =T19*2% -> 399.78668 | R19: =SUMIFS(计列施工队伍调遣费站点!H:H,计列施工队伍调遣费站点!C:C,工作量总表!C19) -> 0 | S19: =K19+L19+M19 -> 19083.626 | T19: =I19+G19*$F$115+'表二（安全生产费）'!$I$14/17+M19+L19 -> 19989.334 | U19: =(S19-O19-F19)*0.17 -> 2696.8545 | V19: =U19/0.17+F19+O19+Q19+P19 -> 20583.413 | W19: =V19*1.09 -> 22435.92 | X19: =ROUND(U19+F19+O19+Q19+P19,2) -> 7416.42 | Y19: =X19*9% -> 667.4778 | Z19: =X19+Y19 -> 8083.8978 | AA19: JMHSWX25090473480R
A20: 15 | B20: 鹤山 | C20: CBN-江门鹤山平岭（江门鹤山共和平岭山顶村）U-Z5H | D20: =SUMIFS(表3!$65:$65,表3!$2:$2,工作量总表!C20) -> 91.0465 | F20: =SUMIFS(表四乙供主材!$11:$11,表四乙供主材!$2:$2,C:C) -> 224.48 | G20: =D20*114 -> 10379.301 | H20: =SUMIFS(表3丙!$7:$7,表3丙!$2:$2,工作量总表!C20) -> 536.4 | I20: =F20+G20+H20 -> 11140.181 | J20: =G20*$D$115+R20 -> 2449.515 | K20: =I20+J20 -> 13589.696 | L20: =N20+O20 -> 6340.715 | M20: =G20*20% -> 2075.8602 | N20: =G20*$H$105 -> 2843.9285 | O20: =G20*33.69% -> 3496.7865 | P20: =INDEX(表6其他费!$G$11:$GK$11,ROW()-5) -> 1525 | Q20: =T20*2% -> 458.46611 | R20: =SUMIFS(计列施工队伍调遣费站点!H:H,计列施工队伍调遣费站点!C:C,工作量总表!C20) -> 0 | S20: =K20+L20+M20 -> 22006.271 | T20: =I20+G20*$F$115+'表二（安全生产费）'!$I$14/17+M20+L20 -> 22923.306 | U20: =(S20-O20-F20)*0.17 -> 3108.4508 | V20: =U20/0.17+F20+O20+Q20+P20 -> 23989.737 | W20: =V20*1.09 -> 26148.814 | X20: =ROUND(U20+F20+O20+Q20+P20,2) -> 8813.18 | Y20: =X20*9% -> 793.1862 | Z20: =X20+Y20 -> 9606.3662 | AA20: JMHSWX25090473477R
A21: 16 | B21: 鹤山 | C21: CBN-江门柏年（江门江海连海二路）U-Z5H | D21: =SUMIFS(表3!$65:$65,表3!$2:$2,工作量总表!C21) -> 54.5695 | F21: =SUMIFS(表四乙供主材!$11:$11,表四乙供主材!$2:$2,C:C) -> 200 | G21: =D21*114 -> 6220.923 | H21: =SUMIFS(表3丙!$7:$7,表3丙!$2:$2,工作量总表!C21) -> 536.4 | I21: =F21+G21+H21 -> 6957.323 | J21: =G21*$D$115+R21 -> 1468.1378 | K21: =I21+J21 -> 8425.4608 | L21: =N21+O21 -> 3800.3619 | M21: =G21*20% -> 1244.1846 | N21: =G21*$H$105 -> 1704.5329 | O21: =G21*33.69% -> 2095.829 | P21: =INDEX(表6其他费!$G$11:$GK$11,ROW()-5) -> 300 | Q21: =T21*2% -> 287.07549 | R21: =SUMIFS(计列施工队伍调遣费站点!H:H,计列施工队伍调遣费站点!C:C,工作量总表!C21) -> 0 | S21: =K21+L21+M21 -> 13470.007 | T21: =I21+G21*$F$115+'表二（安全生产费）'!$I$14/17+M21+L21 -> 14353.775 | U21: =(S21-O21-F21)*0.17 -> 1899.6103 | V21: =U21/0.17+F21+O21+Q21+P21 -> 14057.083 | W21: =V21*1.09 -> 15322.22 | X21: =ROUND(U21+F21+O21+Q21+P21,2) -> 4782.51 | Y21: =X21*9% -> 430.4259 | Z21: =X21+Y21 -> 5212.9359 | AA21: JMJHWX25092982719R
A22: 17 | B22: 鹤山 | C22: CBN-江门鹤山新民（江门鹤山共和新联油漆）U-Z5H | D22: =SUMIFS(表3!$65:$65,表3!$2:$2,工作量总表!C22) -> 57.232 | F22: =SUMIFS(表四乙供主材!$11:$11,表四乙供主材!$2:$2,C:C) -> 200 | G22: =D22*114 -> 6524.448 | H22: =SUMIFS(表3丙!$7:$7,表3丙!$2:$2,工作量总表!C22) -> 536.4 | I22: =F22+G22+H22 -> 7260.848 | J22: =G22*$D$115+R22 -> 1539.7697 | K22: =I22+J22 -> 8800.6177 | L22: =N22+O22 -> 3985.7853 | M22: =G22*20% -> 1304.8896 | N22: =G22*$H$105 -> 1787.6988 | O22: =G22*33.69% -> 2198.0865 | P22: =INDEX(表6其他费!$G$11:$GK$11,ROW()-5) -> 725 | Q22: =T22*2% -> 299.54976 | R22: =SUMIFS(计列施工队伍调遣费站点!H:H,计列施工队伍调遣费站点!C:C,工作量总表!C22) -> 0 | S22: =K22+L22+M22 -> 14091.293 | T22: =I22+G22*$F$115+'表二（安全生产费）'!$I$14/17+M22+L22 -> 14977.488 | U22: =(S22-O22-F22)*0.17 -> 1987.845 | V22: =U22/0.17+F22+O22+Q22+P22 -> 15115.842 | W22: =V22*1.09 -> 16476.268 | X22: =ROUND(U22+F22+O22+Q22+P22,2) -> 5410.48 | Y22: =X22*9% -> 486.9432 | Z22: =X22+Y22 -> 5897.4232 | AA22: JMHSWX25102086683R
A23: 18 | D23: =SUMIFS(表3!$65:$65,表3!$2:$2,工作量总表!C23) -> 0 | F23: =SUMIFS(表四乙供主材!$11:$11,表四乙供主材!$2:$2,C:C) -> 0 | G23: =D23*114 -> 0 | H23: =SUMIFS(表3丙!$7:$7,表3丙!$2:$2,工作量总表!C23) -> 0 | I23: =F23+G23+H23 -> 0 | J23: =G23*$D$115+R23 -> 0 | K23: =I23+J23 -> 0 | L23: =N23+O23 -> 0 | M23: =G23*20% -> 0 | N23: =G23*$H$105 -> 0 | O23: =G23*33.69% -> 0 | P23: =INDEX(表6其他费!$G$11:$GK$11,ROW()-5) -> 0 | Q23: =S23*2% -> 0 | R23: =SUMIFS(计列施工队伍调遣费站点!H:H,计列施工队伍调遣费站点!C:C,工作量总表!C23) -> 0 | S23: =K23+L23+M23 -> 0 | T23: =I23+G23*$F$115+'表二（安全生产费）'!I31/17+M23+L23 -> 0 | U23: =(S23-O23-F23)*0.17 -> 0 | V23: =U23/0.17+F23+O23+Q23+P23 -> 0 | W23: =V23*1.09 -> 0 | X23: =ROUND(U23+F23+O23+Q23+P23,2) -> 0 | Y23: =X23*9% -> 0 | Z23: =X23+Y23 -> 0 | AA23: JMJMWX24070131809R
A24: 19 | D24: =SUMIFS(表3!$65:$65,表3!$2:$2,工作量总表!C24) -> 0 | F24: =SUMIFS(表四乙供主材!$11:$11,表四乙供主材!$2:$2,C:C) -> 0 | G24: =D24*114 -> 0 | H24: =SUMIFS(表3丙!$7:$7,表3丙!$2:$2,工作量总表!C24) -> 0 | I24: =F24+G24+H24 -> 0 | J24: =G24*$D$115+R24 -> 0 | K24: =I24+J24 -> 0 | L24: =N24+O24 -> 0 | M24: =G24*20% -> 0 | N24: =G24*$H$105 -> 0 | O24: =G24*33.69% -> 0 | P24: =INDEX(表6其他费!$G$11:$GK$11,ROW()-5) -> 0 | Q24: =S24*2% -> 0 | R24: =SUMIFS(计列施工队伍调遣费站点!H:H,计列施工队伍调遣费站点!C:C,工作量总表!C24) -> 0 | S24: =K24+L24+M24 -> 0 | T24: =I24+G24*$F$115+'表二（安全生产费）'!I32/17+M24+L24 -> 0 | U24: =(S24-O24-F24)*0.17 -> 0 | V24: =U24/0.17+F24+O24+Q24+P24 -> 0 | W24: =V24*1.09 -> 0 | X24: =ROUND(U24+F24+O24+Q24+P24,2) -> 0 | Y24: =X24*9% -> 0 | Z24: =X24+Y24 -> 0 | AA24: JMJMWX24070131810R
A25: 20 | D25: =SUMIFS(表3!$65:$65,表3!$2:$2,工作量总表!C25) -> 0 | F25: =SUMIFS(表四乙供主材!$11:$11,表四乙供主材!$2:$2,C:C) -> 0 | G25: =D25*114 -> 0 | H25: =SUMIFS(表3丙!$7:$7,表3丙!$2:$2,工作量总表!C25) -> 0 | I25: =F25+G25+H25 -> 0 | J25: =G25*27.4%+R25 -> 0 | K25: =I25+J25 -> 0 | L25: =G25*61.09% -> 0 | M25: =G25*20% -> 0 | O25: =G25*33.69% -> 0 | P25: =INDEX(表6其他费!$G$11:$GK$11,ROW()-5) -> 0 | Q25: =S25*2% -> 0 | R25: =SUMIFS(计列施工队伍调遣费站点!H:H,计列施工队伍调遣费站点!C:C,工作量总表!C25) -> 0 | S25: =K25+L25+M25 -> 0 | T25: =I25+G25*$F$115+'表二（安全生产费）'!I33/17+M25+L25 -> 0 | U25: =(S25-O25-F25)*0.17 -> 0 | V25: =U25/0.17+F25+O25+Q25+P25 -> 0 | W25: =V25*1.09 -> 0 | X25: =ROUND(U25+F25+O25+Q25+P25,2) -> 0 | Y25: =X25*9% -> 0 | Z25: =X25+Y25 -> 0 | AA25: JMJMWX24070131771R
A26: 21 | D26: =SUMIFS(表3!$65:$65,表3!$2:$2,工作量总表!C26) -> 0 | F26: =SUMIFS(表四乙供主材!$11:$11,表四乙供主材!$2:$2,C:C) -> 0 | G26: =D26*114 -> 0 | H26: =SUMIFS(表3丙!$7:$7,表3丙!$2:$2,工作量总表!C26) -> 0 | I26: =F26+G26+H26 -> 0 | J26: =G26*27.4%+R26 -> 0 | K26: =I26+J26 -> 0 | L26: =G26*61.09% -> 0 | M26: =G26*20% -> 0 | O26: =G26*33.69% -> 0 | P26: =INDEX(表6其他费!$G$11:$GK$11,ROW()-5) -> 0 | Q26: =S26*2% -> 0 | R26: =SUMIFS(计列施工队伍调遣费站点!H:H,计列施工队伍调遣费站点!C:C,工作量总表!C26) -> 0 | S26: =K26+L26+M26 -> 0 | T26: =I26+G26*$F$115+'表二（安全生产费）'!I34/17+M26+L26 -> 0 | U26: =(S26-O26-F26)*0.17 -> 0 | V26: =U26/0.17+F26+O26+Q26+P26 -> 0 | W26: =V26*1.09 -> 0 | X26: =ROUND(U26+F26+O26+Q26+P26,2) -> 0 | Y26: =X26*9% -> 0 | Z26: =X26+Y26 -> 0 | AA26: JMJMWX24070131832R
A27: 22 | D27: =SUMIFS(表3!$65:$65,表3!$2:$2,工作量总表!C27) -> 0 | F27: =SUMIFS(表四乙供主材!$11:$11,表四乙供主材!$2:$2,C:C) -> 0 | G27: =D27*114 -> 0 | H27: =SUMIFS(表3丙!$7:$7,表3丙!$2:$2,工作量总表!C27) -> 0 | I27: =F27+G27+H27 -> 0 | J27: =G27*27.4%+R27 -> 0 | K27: =I27+J27 -> 0 | L27: =G27*61.09% -> 0 | M27: =G27*20% -> 0 | O27: =G27*33.69% -> 0 | P27: =INDEX(表6其他费!$G$11:$GK$11,ROW()-5) -> 0 | Q27: =S27*2% -> 0 | R27: =SUMIFS(计列施工队伍调遣费站点!H:H,计列施工队伍调遣费站点!C:C,工作量总表!C27) -> 0 | S27: =K27+L27+M27 -> 0 | T27: =I27+G27*$F$115+'表二（安全生产费）'!I35/17+M27+L27 -> 0 | U27: =(S27-O27-F27)*0.17 -> 0 | V27: =U27/0.17+F27+O27+Q27+P27 -> 0 | W27: =V27*1.09 -> 0 | X27: =ROUND(U27+F27+O27+Q27+P27,2) -> 0 | Y27: =X27*9% -> 0 | Z27: =X27+Y27 -> 0 | AA27: JMJMWX24070131835R
A28: 23 | D28: =SUMIFS(表3!$65:$65,表3!$2:$2,工作量总表!C28) -> 0 | F28: =SUMIFS(表四乙供主材!$11:$11,表四乙供主材!$2:$2,C:C) -> 0 | G28: =D28*114 -> 0 | H28: =SUMIFS(表3丙!$7:$7,表3丙!$2:$2,工作量总表!C28) -> 0 | I28: =F28+G28+H28 -> 0 | J28: =G28*27.4%+R28 -> 0 | K28: =I28+J28 -> 0 | L28: =G28*61.09% -> 0 | M28: =G28*20% -> 0 | O28: =G28*33.69% -> 0 | P28: =INDEX(表6其他费!$G$11:$GK$11,ROW()-5) -> 0 | Q28: =S28*2% -> 0 | R28: =SUMIFS(计列施工队伍调遣费站点!H:H,计列施工队伍调遣费站点!C:C,工作量总表!C28) -> 0 | S28: =K28+L28+M28 -> 0 | T28: =I28+G28*$F$115+'表二（安全生产费）'!I36/17+M28+L28 -> 0 | U28: =(S28-O28-F28)*0.17 -> 0 | V28: =U28/0.17+F28+O28+Q28+P28 -> 0 | W28: =V28*1.09 -> 0 | X28: =ROUND(U28+F28+O28+Q28+P28,2) -> 0 | Y28: =X28*9% -> 0 | Z28: =X28+Y28 -> 0 | AA28: JMJMWX24070131836R
A29: 24 | D29: =SUMIFS(表3!$65:$65,表3!$2:$2,工作量总表!C29) -> 0 | F29: =SUMIFS(表四乙供主材!$11:$11,表四乙供主材!$2:$2,C:C) -> 0 | G29: =D29*114 -> 0 | H29: =SUMIFS(表3丙!$7:$7,表3丙!$2:$2,工作量总表!C29) -> 0 | I29: =F29+G29+H29 -> 0 | J29: =G29*27.4%+R29 -> 0 | K29: =I29+J29 -> 0 | L29: =G29*61.09% -> 0 | M29: =G29*20% -> 0 | O29: =G29*33.69% -> 0 | P29: =INDEX(表6其他费!$G$11:$GK$11,ROW()-5) -> 0 | Q29: =S29*2% -> 0 | R29: =SUMIFS(计列施工队伍调遣费站点!H:H,计列施工队伍调遣费站点!C:C,工作量总表!C29) -> 0 | S29: =K29+L29+M29 -> 0 | T29: =I29+G29*$F$115+'表二（安全生产费）'!I37/17+M29+L29 -> 0 | U29: =(S29-O29-F29)*0.17 -> 0 | V29: =U29/0.17+F29+O29+Q29+P29 -> 0 | W29: =V29*1.09 -> 0 | X29: =ROUND(U29+F29+O29+Q29+P29,2) -> 0 | Y29: =X29*9% -> 0 | Z29: =X29+Y29 -> 0 | AA29: JMJMWX24070131838R
A30: 25 | D30: =SUMIFS(表3!$65:$65,表3!$2:$2,工作量总表!C30) -> 0 | F30: =SUMIFS(表四乙供主材!$11:$11,表四乙供主材!$2:$2,C:C) -> 0 | G30: =D30*114 -> 0 | H30: =SUMIFS(表3丙!$7:$7,表3丙!$2:$2,工作量总表!C30) -> 0 | I30: =F30+G30+H30 -> 0 | J30: =G30*27.4%+R30 -> 0 | K30: =I30+J30 -> 0 | L30: =G30*61.09% -> 0 | M30: =G30*20% -> 0 | O30: =G30*33.69% -> 0 | P30: =INDEX(表6其他费!$G$11:$GK$11,ROW()-5) -> 0 | Q30: =S30*2% -> 0 | R30: =SUMIFS(计列施工队伍调遣费站点!H:H,计列施工队伍调遣费站点!C:C,工作量总表!C30) -> 0 | S30: =K30+L30+M30 -> 0 | T30: =I30+G30*$F$115+'表二（安全生产费）'!I38/17+M30+L30 -> 0 | U30: =(S30-O30-F30)*0.17 -> 0 | V30: =U30/0.17+F30+O30+Q30+P30 -> 0 | W30: =V30*1.09 -> 0 | X30: =ROUND(U30+F30+O30+Q30+P30,2) -> 0 | Y30: =X30*9% -> 0 | Z30: =X30+Y30 -> 0 | AA30: JMJMWX24070131840R
A31: 26 | D31: =SUMIFS(表3!$65:$65,表3!$2:$2,工作量总表!C31) -> 0 | F31: =SUMIFS(表四乙供主材!$11:$11,表四乙供主材!$2:$2,C:C) -> 0 | G31: =D31*114 -> 0 | H31: =SUMIFS(表3丙!$7:$7,表3丙!$2:$2,工作量总表!C31) -> 0 | I31: =F31+G31+H31 -> 0 | J31: =G31*27.4%+R31 -> 0 | K31: =I31+J31 -> 0 | L31: =G31*61.09% -> 0 | M31: =G31*20% -> 0 | O31: =G31*33.69% -> 0 | P31: =INDEX(表6其他费!$G$11:$GK$11,ROW()-5) -> 0 | Q31: =S31*2% -> 0 | R31: =SUMIFS(计列施工队伍调遣费站点!H:H,计列施工队伍调遣费站点!C:C,工作量总表!C31) -> 0 | S31: =K31+L31+M31 -> 0 | T31: =I31+G31*$F$115+'表二（安全生产费）'!I39/17+M31+L31 -> 0 | U31: =(S31-O31-F31)*0.17 -> 0 | V31: =U31/0.17+F31+O31+Q31+P31 -> 0 | W31: =V31*1.09 -> 0 | X31: =ROUND(U31+F31+O31+Q31+P31,2) -> 0 | Y31: =X31*9% -> 0 | Z31: =X31+Y31 -> 0 | AA31: JMJMWX24070131861R
A32: 27 | D32: =SUMIFS(表3!$65:$65,表3!$2:$2,工作量总表!C32) -> 0 | F32: =SUMIFS(表四乙供主材!$11:$11,表四乙供主材!$2:$2,C:C) -> 0 | G32: =D32*114 -> 0 | H32: =SUMIFS(表3丙!$7:$7,表3丙!$2:$2,工作量总表!C32) -> 0 | I32: =F32+G32+H32 -> 0 | J32: =G32*27.4%+R32 -> 0 | K32: =I32+J32 -> 0 | L32: =G32*61.09% -> 0 | M32: =G32*20% -> 0 | O32: =G32*33.69% -> 0 | P32: =INDEX(表6其他费!$G$11:$GK$11,ROW()-5) -> 0 | Q32: =S32*2% -> 0 | R32: =SUMIFS(计列施工队伍调遣费站点!H:H,计列施工队伍调遣费站点!C:C,工作量总表!C32) -> 0 | S32: =K32+L32+M32 -> 0 | T32: =I32+G32*$F$115+'表二（安全生产费）'!I40/17+M32+L32 -> 0 | U32: =(S32-O32-F32)*0.17 -> 0 | V32: =U32/0.17+F32+O32+Q32+P32 -> 0 | W32: =V32*1.09 -> 0 | X32: =ROUND(U32+F32+O32+Q32+P32,2) -> 0 | Y32: =X32*9% -> 0 | Z32: =X32+Y32 -> 0 | AA32: JMJMWX24070131862R
A33: 28 | D33: =SUMIFS(表3!$65:$65,表3!$2:$2,工作量总表!C33) -> 0 | F33: =SUMIFS(表四乙供主材!$11:$11,表四乙供主材!$2:$2,C:C) -> 0 | G33: =D33*114 -> 0 | H33: =SUMIFS(表3丙!$7:$7,表3丙!$2:$2,工作量总表!C33) -> 0 | I33: =F33+G33+H33 -> 0 | J33: =G33*27.4%+R33 -> 0 | K33: =I33+J33 -> 0 | L33: =G33*61.09% -> 0 | M33: =G33*20% -> 0 | O33: =G33*33.69% -> 0 | P33: =INDEX(表6其他费!$G$11:$GK$11,ROW()-5) -> 0 | Q33: =S33*2% -> 0 | R33: =SUMIFS(计列施工队伍调遣费站点!H:H,计列施工队伍调遣费站点!C:C,工作量总表!C33) -> 0 | S33: =K33+L33+M33 -> 0 | T33: =I33+G33*$F$115+'表二（安全生产费）'!I41/17+M33+L33 -> 0 | U33: =(S33-O33-F33)*0.17 -> 0 | V33: =U33/0.17+F33+O33+Q33+P33 -> 0 | W33: =V33*1.09 -> 0 | X33: =ROUND(U33+F33+O33+Q33+P33,2) -> 0 | Y33: =X33*9% -> 0 | Z33: =X33+Y33 -> 0 | AA33: JMJMWX24070131863R
A34: 29 | D34: =SUMIFS(表3!$65:$65,表3!$2:$2,工作量总表!C34) -> 0 | F34: =SUMIFS(表四乙供主材!$11:$11,表四乙供主材!$2:$2,C:C) -> 0 | G34: =D34*114 -> 0 | H34: =SUMIFS(表3丙!$7:$7,表3丙!$2:$2,工作量总表!C34) -> 0 | I34: =F34+G34+H34 -> 0 | J34: =G34*27.4%+R34 -> 0 | K34: =I34+J34 -> 0 | L34: =G34*61.09% -> 0 | M34: =G34*20% -> 0 | O34: =G34*33.69% -> 0 | P34: =INDEX(表6其他费!$G$11:$GK$11,ROW()-5) -> 0 | Q34: =S34*2% -> 0 | R34: =SUMIFS(计列施工队伍调遣费站点!H:H,计列施工队伍调遣费站点!C:C,工作量总表!C34) -> 0 | S34: =K34+L34+M34 -> 0 | T34: =I34+G34*$F$115+'表二（安全生产费）'!I42/17+M34+L34 -> 0 | U34: =(S34-O34-F34)*0.17 -> 0 | V34: =U34/0.17+F34+O34+Q34+P34 -> 0 | W34: =V34*1.09 -> 0 | X34: =ROUND(U34+F34+O34+Q34+P34,2) -> 0 | Y34: =X34*9% -> 0 | Z34: =X34+Y34 -> 0 | AA34: JMJMWX24070131870R
A35: 30 | D35: =SUMIFS(表3!$65:$65,表3!$2:$2,工作量总表!C35) -> 0 | F35: =SUMIFS(表四乙供主材!$11:$11,表四乙供主材!$2:$2,C:C) -> 0 | G35: =D35*114 -> 0 | H35: =SUMIFS(表3丙!$7:$7,表3丙!$2:$2,工作量总表!C35) -> 0 | I35: =F35+G35+H35 -> 0 | J35: =G35*27.4%+R35 -> 0 | K35: =I35+J35 -> 0 | L35: =G35*61.09% -> 0 | M35: =G35*20% -> 0 | O35: =G35*33.69% -> 0 | P35: =INDEX(表6其他费!$G$11:$GK$11,ROW()-5) -> 0 | Q35: =S35*2% -> 0 | R35: =SUMIFS(计列施工队伍调遣费站点!H:H,计列施工队伍调遣费站点!C:C,工作量总表!C35) -> 0 | S35: =K35+L35+M35 -> 0 | T35: =I35+G35*$F$115+'表二（安全生产费）'!I43/17+M35+L35 -> 0 | U35: =(S35-O35-F35)*0.17 -> 0 | V35: =U35/0.17+F35+O35+Q35+P35 -> 0 | W35: =V35*1.09 -> 0 | X35: =ROUND(U35+F35+O35+Q35+P35,2) -> 0 | Y35: =X35*9% -> 0 | Z35: =X35+Y35 -> 0 | AA35: JMJMWX24070131875R
A36: 31 | D36: =SUMIFS(表3!$65:$65,表3!$2:$2,工作量总表!C36) -> 0 | F36: =SUMIFS(表四乙供主材!$11:$11,表四乙供主材!$2:$2,C:C) -> 0 | G36: =D36*114 -> 0 | H36: =SUMIFS(表3丙!$7:$7,表3丙!$2:$2,工作量总表!C36) -> 0 | I36: =F36+G36+H36 -> 0 | J36: =G36*27.4%+R36 -> 0 | K36: =I36+J36 -> 0 | L36: =G36*61.09% -> 0 | M36: =G36*20% -> 0 | O36: =G36*33.69% -> 0 | P36: =INDEX(表6其他费!$G$11:$GK$11,ROW()-5) -> 0 | Q36: =S36*2% -> 0 | R36: =SUMIFS(计列施工队伍调遣费站点!H:H,计列施工队伍调遣费站点!C:C,工作量总表!C36) -> 0 | S36: =K36+L36+M36 -> 0 | T36: =I36+G36*$F$115+'表二（安全生产费）'!I44/17+M36+L36 -> 0 | U36: =(S36-O36-F36)*0.17 -> 0 | V36: =U36/0.17+F36+O36+Q36+P36 -> 0 | W36: =V36*1.09 -> 0 | X36: =ROUND(U36+F36+O36+Q36+P36,2) -> 0 | Y36: =X36*9% -> 0 | Z36: =X36+Y36 -> 0 | AA36: JMJMWX24070131874R
... A93: 88 | D93: =SUMIFS(表3!$65:$65,表3!$2:$2,工作量总表!C93) -> 0 | F93: =SUMIFS(表四乙供主材!$11:$11,表四乙供主材!$2:$2,C:C) -> 0 | G93: =D93*114 -> 0 | H93: =SUMIFS(表3丙!$7:$7,表3丙!$2:$2,工作量总表!C93) -> 0 | I93: =F93+G93+H93 -> 0 | J93: =G93*27.4%+R93 -> 0 | K93: =I93+J93 -> 0 | L93: =G93*61.09% -> 0 | M93: =G93*20% -> 0 | O93: =G93*33.69% -> 0 | P93: =INDEX(表6其他费!$G$11:$GK$11,ROW()-5) -> 0 | Q93: =S93*2% -> 0 | R93: =SUMIFS(计列施工队伍调遣费站点!H:H,计列施工队伍调遣费站点!C:C,工作量总表!C93) -> 0 | S93: =K93+L93+M93 -> 0 | T93: =I93+G93*$F$115+'表二（安全生产费）'!I101/17+M93+L93 -> 0 | U93: =(S93-O93-F93)*0.17 -> 0 | V93: =U93/0.17+F93+O93+Q93+P93 -> 0 | W93: =V93*1.09 -> 0 | X93: =ROUND(U93+F93+O93+Q93+P93,2) -> 0 | Y93: =X93*9% -> 0 | Z93: =X93+Y93 -> 0 | AA93: JMJMWX24122963551R
D94: =SUM(D6:D93) -> 1051.398 | E94: =SUM(E6:E93) -> 0 | F94: =SUM(F6:F93) -> 3721.92 | G94: =SUM(G6:G93) -> 119859.37 | H94: =SUM(H6:H93) -> 9118.8 | I94: =SUM(I6:I93) -> 132700.09 | J94: =SUM(J6:J93) -> 29696.812 | K94: =SUM(K6:K93) -> 162396.9 | ... W94: =SUM(W6:W93) -> 303245.87 | X94: =SUM(X6:X22) -> 99351.9 | Y94: =SUM(Y6:Y93) -> 8941.671 | Z94: =SUM(Z6:Z93) -> 108293.57 | AA94: 99351.91
Z95: =Z94 -> 108293.57
A99: 施工单位： | G99: 监理单位： | Q99: 建设单位：
...

Sheet 表1
A1: 工程结算总表（表一）
A3: 项目名称：江门700MHz频段共建共享五期工程无线主设备项目——子项4：常规项目
F4: 建设单位：中国移动通信集团广东有限公司江门分公司 | I4: 表格编号：TSW1 | J4: 第1页
A5: 序号 | B5: 表格编号 | C5: 单项工程名称 | D5: 工程费（降点部分） | E5: 规费(不降点) | F5: 零小工程包干费(不降点) | G5: 安全生产费(不降点) | H5: 其他费用(不降点) | I5: 总 价 值（不含税）
I6: 人民币（元） | J6: 其中外币（）
A7: Ⅰ | B7: Ⅱ | C7: Ⅲ | D7: Ⅳ | E7: Ⅴ | F7: Ⅶ | G7: Ⅷ | H7: Ⅸ | I7: Ⅹ | J7: Ⅺ
A8: 1 | C8: 建筑安装工程费 | D8: =表2!D7-表2!D14-表2!I17-表2!I24 -> 215488.33 | E8: =表2!I17 -> 40380.622 | F8: =表2!D14 -> 3721.92 | G8: =表5!D11 -> 5466.3549 | H8: =表5!D12 -> 13150 | I8: =SUM(D8:H8) -> 278207.22
C13: 中标折扣系数17% | D13: =D8*0.17 -> 36633.015 | E13: =E8 -> 40380.622 | F13: =F8 -> 3721.92 | G13: =G8 -> 5466.3549 | H13: =H8 -> 13150 | I13: =SUM(D13:H13)-0.01 -> 99351.903
A14: 施工单位： 负责人： 日期： | D14: 监理单位： 负责人： 日期： | G14: 建设单位： 负责人： 日期：
J32: =I13-工作量总表!X94 -> 0.002737656

Sheet 表2
A1: 建 筑 安 装 工 程 费 用 结 算（表 二）
A2: =表1!A3 -> 项目名称：江门700MHz频段共建共享五期工程无线主设备项目——子项4：常规项目
A3: =表1!A4 -> 0
A4: =表1!F4 -> 建设单位：中国移动通信集团广东有限公司江门分公司 | I4: 表格编号：TSW2
A5: 序号 | B5: 费用名称 | C5: 依据和计算方法 | D5: 金额（元） | F5: 序号 | G5: 费用名称 | H5: 依据和计算方法 | I5: 金额（元）
A6: Ⅰ | B6: Ⅱ | C6: Ⅲ | D6: Ⅳ | F6: Ⅰ | G6: Ⅱ | H6: Ⅲ | I6: Ⅳ
B7: 建筑安装工程费 | C7: 一+二+三+四 | D7: =D9+I16+I23+I24 -> 259590.87 | F7: 8 | G7: 夜间施工增加费 | H7: 人工费×2.1% | I7: =D11*2.1% -> 2517.0468
B8: 建筑安装工程费（不含税） | C8: 一+二+三 | D8: =D9+I16+I23 -> 259590.87 | F8: 9 | G8: 冬雨季施工增加费 | H8: 人工费（室外）×2.5% | I8: =D11*2.5% -> 2996.4843
A9: 一 | B9: 直接费 | C9: 直接工程费+措施费 | D9: =D10+D19 -> 162396.9 | F9: 10 | G9: 生产工用具使用费 | H9: 人工费×0.8% | I9: =D11*0.8% -> 958.87498
A10: (1) | B10: 直接工程费 | C10: 1至4之和 | D10: =D11+D14+D17+D18 -> 132700.09 | F10: 11 | G10: 施工用水电蒸汽费 | H10: 不计取
A11: 1 | B11: 人工费 | C11: 技工费+普工费 | D11: =D12+D13 -> 119859.37 | F11: 12 | G11: 特殊地区施工增加费 | H11: 不计取
A12: (1) | B12: 技工费 | C12: 技工总工日×114元/工日 | D12: =表3!CQ65*114 -> 119859.37 | F12: 13 | G12: 已完工程及设备保护费 | H12: 人工费×1.5% | I12: =D11*1.5% -> 1797.8906
A13: (2) | B13: 普工费 | C13: 普工总工日×61元/工日 | F13: 14 | G13: 运土费 | H13: 不计取
A14: 2 | B14: 材料费 | C14: (1)+(2) | D14: =D15+D16 -> 3721.92 | F14: 15 | G14: 施工队伍调遗费 | H14: 2×[单程调遗费定额×调遗人数]按451定额计取 | I14: =计列施工队伍调遣费站点!H20 -> 1410
A15: (1) | B15: 主要材料费 | C15: 国内主材费 | D15: =表四乙供主材!CQ11 -> 3721.92 | F15: 16 | G15: 大型施工机械调遗费 | H15: 不计取
A16: (2) | B16: 辅助材料费 | C16: 不计取 | F16: 二 | G16: 间接费 | H16: 规费+企业管理费 | I16: =I17+I22 -> 73222.09
A17: 3 | B17: 机械使用费 | C17: 按实际计列 | F17: （一） | G17: 规费 | H17: 1至4之和 | I17: =SUM(I18:I21) -> 40380.622
A18: 4 | B18: 仪表使用费 | C18: 表三丙-总计 | D18: =表3丙!CR7 -> 9118.8 | F18: 1 | G18: 工程排污费 | H18: 按实际计列
A19: (二） | B19: 措施费 | C19: 1至16之和 | D19: =SUM(D20:D26,I7:I15) -> 29696.812 | F19: 2 | G19: 社会保障费 | H19: 人工费×28.5% | I19: =D11*28.5% -> 34159.921
A20: 1 | B20: 环境保护费 | C20: 不计取 | F20: 3 | G20: 住房公积金 | H20: 人工费×4.19% | I20: =D11*4.19% -> 5022.1077
A21: 2 | B21: 文明施工费 | C21: 人工费×1.1% | D21: =D11*1.1% -> 1318.4531 | F21: 4 | G21: 危险作业意外伤害保险费 | H21: 人工费×1% | I21: =D11*1% -> 1198.5937
A22: 3 | B22: 工地器材搬运费 | C22: 人工费×1.1% | D22: =D11*1.1% -> 1318.4531 | F22: （二） | G22: 企业管理费 | H22: 人工费×27.4% | I22: =D11*27.4% -> 32841.468
A23: 4 | B23: 工程干扰费 | C23: 人工费×4%×80% | D23: =D11*4%*80% -> 3835.4999 | F23: 三 | G23: 利润 | H23: 人工费×20.00% | I23: =D11*20% -> 23971.874
A24: 5 | B24: 工程点交、场地清理费 | C24: 人工费×2.5% | D24: =D11*2.5% -> 2996.4843 | F24: 四 | G24: 税金 | H24: (直接费+间接费+利润-主材费)×10%＋主材费×16%
A25: 6 | B25: 临时设施费 | C25: 人工费×3.8%(按451定额计取) | D25: =表3!CQ65*114*3.8% -> 4554.6561
A26: 7 | B26: 工程车辆使用费 | C26: 人工费×5.0% | D26: =D11*5% -> 5992.9686

Sheet 表二（安全生产费）
A1: 建 筑 安 装 工 程 费 用 结 算（表 二）
A2: =表1!A3 -> 项目名称：江门700MHz频段共建共享五期工程无线主设备项目——子项4：常规项目
A3: =表1!A4 -> 0
A4: =表1!F4 -> 建设单位：中国移动通信集团广东有限公司江门分公司 | I4: 表格编号：TSW2
A5: 序号 | B5: 费用名称 | C5: 依据和计算方法 | D5: 金额（元） | F5: 序号 | G5: 费用名称 | H5: 依据和计算方法 | I5: 金额（元）
A6: Ⅰ | B6: Ⅱ | C6: Ⅲ | D6: Ⅳ | F6: Ⅰ | G6: Ⅱ | H6: Ⅲ | I6: Ⅳ
B7: 建筑安装工程费 | C7: 一+二+三+四 | D7: =D9+I16+I23+I24 -> 273317.74 | F7: 8 | G7: 夜间施工增加费 | H7: 人工费×2.1% | I7: =D11*2.1% -> 2517.0468
B8: 建筑安装工程费（不含税） | C8: 一+二+三 | D8: =D9+I16+I23 -> 273317.74 | F8: 9 | G8: 冬雨季施工增加费 | H8: 人工费（室外）×2.5% | I8: =D11*2.5% -> 2996.4843
A9: 一 | B9: 直接费 | C9: 直接工程费+措施费 | D9: =D10+D19 -> 176123.78 | F9: 10 | G9: 生产工用具使用费 | H9: 人工费×0.8% | I9: =D11*0.8% -> 958.87498 | K9: 施工调遣费
A10: (1) | B10: 直接工程费 | C10: 1至4之和 | D10: =D11+D14+D17+D18 -> 132700.09 | F10: 11 | G10: 施工用水电蒸汽费 | H10: 不计取 | K10: 当前施工单位 | L10: 武汉虹信技术服务有限责任公司 | M10: 调遣里程 | N10: =INDEX(P13:P19,MATCH(L10,O13:O19,0)) -> 1082 | O10: 总工日 | P10: =表3!CQ65 -> 1051.398
A11: 1 | B11: 人工费 | C11: 技工费+普工费 | D11: =D12+D13 -> 119859.37 | F11: 12 | G11: 特殊地区施工增加费 | H11: 不计取
A12: (1) | B12: 技工费 | C12: 技工总工日×114元/工日 | D12: =表3!CQ65*114 -> 119859.37 | F12: 13 | G12: 已完工程及设备保护费 | H12: 人工费×1.5% | I12: =D11*1.5% -> 1797.8906 | K12: 调遣里程(L) | L12: 单程调遣费 | M12: 预算总工日 | N12: 调遣人数 | O12: 施工单位 | P12: 施工现场与企业的距离（公里） | Q12: 对应单程调遣费
A13: (2) | B13: 普工费 | C13: 普工总工日×61元/工日 | F13: 14 | G13: 运土费 | H13: 不计取 | K13: <35 | L13: 0 | M13: <=500工日 | N13: 5 | O13: 武汉虹信技术服务有限责任公司 | P13: 1082 | Q13: 417
A14: 2 | B14: 材料费 | C14: 主要材料费+辅助材料费 | D14: =D15+D16 -> 3721.92 | F14: 15 | G14: 施工队伍调遗费 | H14: 2×[单程调遗费定额×调遗人数]按451定额计取 | I14: =P26*Q26*2 -> 14178 | K14: 35<L<=100 | L14: 141 | M14: <=1000工日 | N14: 10
A15: (1) | B15: 主要材料费 | C15: 表四材料表-总计 | D15: =表四乙供主材!CQ11 -> 3721.92 | F15: 16 | G15: 大型施工机械调遗费 | H15: 不计取 | K15: 100<L<=200 | L15: 174 | M15: <=2000工日 | N15: 17
A16: (2) | B16: 辅助材料费 | C16: 不计取 | F16: 二 | G16: 间接费 | H16: 规费+企业管理费 | I16: =I17+I22 -> 73222.09 | K16: 200<L<=400 | L16: 240
A17: 3 | B17: 机械使用费 | F17: （一） | G17: 规费 | H17: 1至4之和 | I17: =SUM(I18:I21) -> 40380.622 | K17: 400<L<=600 | L17: 295
A18: 4 | B18: 仪表使用费 | C18: 表三丙-总计 | D18: =表3丙!CR7 -> 9118.8 | F18: 1 | G18: 工程排污费 | H18: 按实际计列 | K18: 600<L<=800 | L18: 356
A19: (二） | B19: 措施费 | C19: 1至16之和 | D19: =SUM(D20:D26,I7:I15) -> 43423.687 | F19: 2 | G19: 社会保障费 | H19: 人工费×28.5% | I19: =D11*28.5% -> 34159.921 | K19: 800<L<=1000 | L19: 372
A20: 1 | B20: 环境保护费 | C20: 不计取 | F20: 3 | G20: 住房公积金 | H20: 人工费×4.19% | I20: =D11*4.19% -> 5022.1077 | K20: 1000<L<=1200 | L20: 417
A21: 2 | B21: 文明施工费 | C21: 人工费×1.1% | D21: =D11*1.1% -> 1318.4531 | F21: 4 | G21: 危险作业意外伤害保险费 | H21: 人工费×1% | I21: =D11*1% -> 1198.5937 | K21: 1200<L<=1400 | L21: 565
A22: 3 | B22: 工地器材搬运费 | C22: 人工费×1.1% | D22: =D11*1.1% -> 1318.4531 | F22: （二） | G22: 企业管理费 | H22: 人工费×27.4% | I22: =D11*27.4% -> 32841.468 | K22: 1400<L<=1600 | L22: 598
A23: 4 | B23: 工程干扰费 | C23: 人工费×4% | D23: =D11*4% -> 4794.3749 | F23: 三 | G23: 利润 | H23: 人工费×20.00% | I23: =D11*20% -> 23971.874 | K23: 1600<L<=1800 | L23: 634
A24: 5 | B24: 工程点交、场地清理费 | C24: 人工费×2.5% | D24: =D11*2.5% -> 2996.4843 | F24: 四 | G24: 税金 | H24: (直接费+间接费+利润-主材费)×10%＋主材费×16% | K24: 1800<L<=2000 | L24: 675
A25: 6 | B25: 临时设施费 | C25: 人工费×3.8%(按451定额计取) | D25: =表3!CQ65*114*3.8% -> 4554.6561 | K25: 2000<L<=2400 | L25: 746
A26: 7 | B26: 工程车辆使用费 | C26: 人工费×5.0% | D26: =D11*5% -> 5992.9686 | K26: 2400<L<=2800 | L26: 918 | O26: 施工队伍单程调遣费 | P26: =VLOOKUP(L10,O:Q,3,0) -> 417 | Q26: {=_xlfn.IFS(P10<=500,N13,P10<=1000,N14,P10<=2000,N15)} -> 17

Sheet 表3
B1: 序号 | C1: 定额编号 | D1: 项目名称 | E1: 单位 | F1: 单位定额值 （工日） | G1: 1 | H1: 2 | I1: 3 | J1: 4 | K1: 5 | L1: 6 | M1: 7 | N1: 8 | O1: 9 | P1: 10 | Q1: 11 | R1: 12 | S1: 13 | T1: 14 | U1: 15 | V1: 16 | W1: 17 | X1: 18 | Y1: 19 | Z1: 20 | AA1: 21 | AB1: 22 | AC1: 23 | AD1: 24 | AE1: 25 | AF1: 26 | AG1: 27 | AH1: 28 | AI1: 29 | AJ1: 30 | AK1: 31 | AL1: 32 | AM1: 33 | AN1: 34 | AO1: 35 | AP1: 36 | AQ1: 37 | AR1: 38 | AS1: 39 | AT1: 40 | AU1: 41 | AV1: 42 | AW1: 43 | AX1: 44 | AY1: 45 | AZ1: 46 | BA1: 47 | BB1: 48 | BC1: 49 | BD1: 50 | BE1: 51 | BF1: 52 | BG1: 53 | BH1: 54 | BI1: 55 | BJ1: 56 | BK1: 57 | BL1: 58 | BM1: 59 | BN1: 60 | BO1: 61 | BP1: 62 | BQ1: 63 | BR1: 64 | BS1: 65 | BT1: 66 | BU1: 67 | BV1: 68 | BW1: 69 | BX1: 70 | BY1: 71 | BZ1: 72 | CA1: 73 | CB1: 74 | CC1: 75 | CD1: 76 | CE1: 77 | CF1: 78 | CG1: 79 | CH1: 80 | CI1: 81 | CJ1: 82 | CK1: 83 | CL1: 84 | CM1: 85 | CN1: 86 | CO1: 87 | CP1: 88 | CQ1: 合计 | CS1: 江门鹤山浩龙（美化罩） | CT1: 江门鹤山大富（美化罩） | CU1: 江门益晖印刷（无平台） | CV1: 江门江海东海路（无平台） | CW1: 江门鹤山址山昆中石北（无平台）
G2: CBN-江门鹤山市连城C-RAN1（江门鹤山三连工业区二）U-Z5H | H2: CBN-江门鹤山路管所（江门鹤山裕兴雨具）U-Z5H | I2: CBN-江门鹤山市鹤城二（江门鹤山创美）U-Z5H | J2: CBN-江门鹤山福迳（江门鹤山甘牛集团）U-Z5H | K2: CBN-江门蓬江区滨江新区1二（江门新昌公园）U-Z5H | L2: CBN-江门鹤山浩龙（江门鹤山鹤城联东（设备替换））U-Z5H | M2: CBN-江门礼乐新丰（江门江海东海路（设备替换））U-Z5H | N2: CBN-江门轻轨礼乐站（江门捷宏一品）U-Z5H | O2: CBN-江门汇聪电子（江门白水带山脚）U-Z5H | P2: CBN-江门鹤山大朗（江门鹤山址山昆中石北）U-Z5H | Q2: CBN-江门荷塘（江门蓬江技师荷塘校区）U-Z5H | R2: CBN-江门益晖印刷（江门永达顺（新））U-Z5H | S2: CBN-江门三堡（江门蓬江元岭村西）U-Z5H | T2: CBN-江门鹤山大富（江门鹤山大墩村）U-Z5H | U2: CBN-江门鹤山平岭（江门鹤山共和平岭山顶村）U-Z5H | V2: CBN-江门柏年（江门江海连海二路）U-Z5H | W2: CBN-江门鹤山新民（江门鹤山共和新联油漆）U-Z5H | CS2: =_xlfn.DISPIMG("ID_89EEE287F0374E21B26E8089E30D0D2C",1) -> =DISPIMG("ID_89EEE287F0374E21B26E8089E30D0D2C",1) | CT2: =_xlfn.DISPIMG("ID_007C9AA90D9348AA8AFEBAAFEE0ED7AE",1) -> =DISPIMG("ID_007C9AA90D9348AA8AFEBAAFEE0ED7AE",1) | CU2: =_xlfn.DISPIMG("ID_859BD976886C4657B208C7B200C429F6",1) -> =DISPIMG("ID_859BD976886C4657B208C7B200C429F6",1) | CV2: =_xlfn.DISPIMG("ID_45C4567379384F7BB4FB15DF72D199A2",1) -> =DISPIMG("ID_45C4567379384F7BB4FB15DF72D199A2",1) | CW2: =_xlfn.DISPIMG("ID_DE64B22B83B54F1FBB0239388C1362A8",1) -> =DISPIMG("ID_DE64B22B83B54F1FBB0239388C1362A8",1)
K3: 美化玻璃内 | L3: 抱杆上，美化罩 | M3: 无平台作业 | P3: 挂墙新增BBU，无平台作业 | R3: 无平台 | T3: 机柜内新增BBU、美化罩 | U3: 挂墙新增BBU | V3: 挂墙新增BBU | CQ3: 技工
B4: Ⅰ | C4: Ⅱ | D4: Ⅲ | E4: Ⅳ | F4: Ⅴ | CQ4: Ⅸ
B5: 1 | C5: T5G2-046 | D5: 安装基带处理单元（机柜/箱嵌入式 BBU） | E5: 台 | F5: 1.08 | T5: 1 | CQ5: =SUM(G5:CP5) -> 1
B6: 2 | C6: T5G2-045 | D6: 安装基带处理单元（壁挂式 BBU） | E6: 台 | F6: 3.06 | P6: 1 | U6: 1 | V6: 1 | CQ6: =SUM(G6:CP6) -> 3
B7: 3 | C7: T5G2-116 | D7: 扩装设备板件 | E7: 块 | F7: 0.5 | G7: 1 | H7: 1 | I7: 1 | J7: 1 | K7: 1 | L7: 1 | M7: 1 | N7: 1 | O7: 1 | Q7: 1 | R7: 1 | S7: 1 | W7: 1 | CQ7: =SUM(G7:CP7) -> 13
B8: 4 | C8: T5G2-116*0.4 | D8: 拆除设备板件 | E8: 块 | F8: =0.5*0.4 -> 0.2 | L8: 1 | CQ8: =SUM(G8:CP8) -> 1
B9: 5 | C9: T5G1-054 | D9: 放绑软光纤（设备机架间）（15m以下） | E9: 条 | F9: 0.29 | G9: 2 | H9: 2 | I9: 2 | J9: 2 | K9: 2 | L9: 2 | M9: 2 | N9: 2 | O9: 2 | P9: 4 | Q9: 2 | R9: 2 | S9: 2 | T9: 6 | U9: 6 | V9: 6 | W9: 2 | CQ9: =SUM(G9:CP9) -> 48
B10: 6 | C10: T5G2-008 | D10: 安装定向天线（抱杆上） | E10: 副 | F10: 4.42 | Q10: 3 | CQ10: =SUM(G10:CP10) -> 3
B11: 7 | C11: T5G2-008*1.2 | D11: 安装定向天线（抱杆上宽体天线400mm 以上） | E11: 副 | F11: =4.42*1.2 -> 5.304 | I11: 3 | J11: 3 | O11: 3 | V11: 3 | CQ11: =SUM(G11:CP11) -> 12
B12: 8 | C12: T5G2-003*1.2 | D12: 安装定向天线（地面铁塔上、宽体天线400mm 以上）（安装高度40m以下） | E12: 副 | F12: =6.35*1.2 -> 7.62 | N12: 3 | U12: 3 | W12: 3 | CQ12: =SUM(G12:CP12) -> 9
B13: 9 | C13: T5G2-003*1.2 | D13: 拆除定向天线（地面铁塔上、宽体天线400mm 以上）（安装高度40m以下） | E13: 副 | F13: =6.35*1.2 -> 7.62 | N13: 2 | CQ13: =SUM(G13:CP13) -> 2
B14: 10 | C14: T5G2-008*1.3 | D14: 美化罩内安装定向天线-抱杆上 | E14: 副 | F14: =4.42*1.3 -> 5.746 | K14: 3 | L14: 3 | T14: 3 | CQ14: =SUM(G14:CP14) -> 9
B15: 11 | C15: T5G2-008*1.3 | D15: 美化罩内拆除定向天线-抱杆上 | E15: 副 | F15: =4.42*1.3 -> 5.746 | K15: 3 | L15: 3 | T15: 3 | CQ15: =SUM(G15:CP15) -> 9
B16: 12 | C16: T5G2-003*1.3 | D16: 无作业平台安装定向天线-地面铁塔上（安装高度40m以下） | E16: 副 | F16: =6.35*1.3 -> 8.255 | M16: 3 | R16: 3 | CQ16: =SUM(G16:CP16) -> 6
B17: 13 | C17: T5G2-003*1.3 | D17: 无作业平台拆除定向天线-地面铁塔上（拆除高度40m以下） | E17: 副 | F17: =6.35*1.3 -> 8.255 | R17: 3 | CQ17: =SUM(G17:CP17) -> 3
B18: 14 | C18: T5G2-008*1.2 | D18: 拆除定向天线（抱杆上、宽体天线400mm 以上） | E18: 副 | F18: =4.42*1.2 -> 5.304 | O18: 3 | CQ18: =SUM(G18:CP18) -> 3
B19: 15 | C19: T5G2-058 | D19: 安装射频拉远单元（抱杆上） | E19: 套 | F19: 2.13 | I19: 3 | J19: 3 | O19: 3 | Q19: 4 | S19: 3 | V19: 3 | CQ19: =SUM(G19:CP19) -> 19
B20: 16 | C20: T5G2-058*1 | D20: 拆除射频拉远单元（抱杆上） | E20: 套 | F20: 2.13 | Q20: 1 | CQ20: =SUM(G20:CP20) -> 1
B21: 17 | C21: T5G2-058*1.3 | D21: 美化罩内安装射频拉远单元-抱杆上 | E21: 套 | F21: =2.13*1.3 -> 2.769 | L21: 3 | T21: 3 | CQ21: =SUM(G21:CP21) -> 6
B22: 18 | C22: T5G2-058*1.3 | D22: 美化罩内拆除射频拉远单元-抱杆上 | E22: 套 | F22: 2.769 | K22: 3 | L22: 3 | CQ22: =SUM(G22:CP22) -> 6
B23: 19 | C23: T5G2-053 | D23: 安装射频拉远单元（地面铁塔上）（安装高度40m以下） | E23: 套 | F23: 2.88 | N23: 3 | U23: 3 | W23: 3 | CQ23: =SUM(G23:CP23) -> 9
B24: 20 | C24: T5G2-053*1.3 | D24: 无作业平台安装射频拉远单元-地面铁塔上（安装高度40m以下） | E24: 套 | F24: =2.88*1.3 -> 3.744 | M24: 3 | P24: 3 | R24: 3 | CQ24: =SUM(G24:CP24) -> 9
B25: 21 | C25: T5G2-053*1.3 | D25: 无作业平台拆除射频拉远单元（地面铁塔上）（安装高度40m以下） | E25: 套 | F25: =2.88*1.3 -> 3.744 | M25: 3 | CQ25: =SUM(G25:CP25) -> 3
B26: 22 | C26: T5G2-003*1 | D26: 拆除定向天线-地面铁塔上（拆除高度40m以下） | E26: 套 | F26: 6.35 | U26: 3 | CQ26: =SUM(G26:CP26) -> 3
B27: 23 | C27: T5G2-051 | D27: 安装射频拉远单元-楼顶铁塔上（安装高度20m以下） | E27: 套 | F27: 2.69 | G27: 3 | H27: 3 | CQ27: =SUM(G27:CP27) -> 6
B28: 24 | C28: T5G2-001*1.2 | D28: 安装安装定向天线-楼顶铁塔上（安装高度20m以下）宽体天线400mm 以上 | E28: 套 | F28: =5.7*1.2 -> 6.84 | G28: 3 | H28: 3 | CQ28: =SUM(G28:CP28) -> 6
B29: 25 | C29: T5G2-040 | D29: 调测室外基站天、馈线系统（1/2英寸射频同轴电缆） | E29: 条 | F29: 0.38 | G29: 12 | H29: 12 | I29: 12 | J29: 12 | L29: 12 | M29: 12 | N29: 20 | O29: 36 | P29: 13 | Q29: 12 | R29: 12 | S29: 12 | T29: 25 | U29: 25 | V29: 12 | W29: 12 | CQ29: =SUM(G29:CP29) -> 251
B30: 26 | C30: T5G2-044 | D30: 配合调测天、馈线系统 | E30: 扇区 | F30: 0.47 | G30: 3 | H30: 3 | I30: 3 | J30: 3 | K30: 3 | L30: 3 | M30: 3 | N30: 3 | O30: 3 | P30: 3 | Q30: 3 | R30: 3 | S30: 3 | T30: 3 | U30: 3 | V30: 3 | W30: 3 | CQ30: =SUM(G30:CP30) -> 51
A31: DCPD | B31: 27 | C31: T5G2-047 | D31: 安装电源转换器/配电单元（室内） | E31: 台 | F31: 0.8 | T31: 1 | U31: 1 | V31: 1 | CQ31: =SUM(G31:CP31) -> 3
B32: 28 | C32: T5G1-020 | D32: 安装室内墙挂综合箱（无源） | E32: 个 | F32: 0.96 | P32: 1 | U32: 1 | V32: 1 | CQ32: =SUM(G32:CP32) -> 3
B33: 29 | C33: T5G1-074 | D33: 室外布放电力电缆（单芯相线截面积16平方毫米以下） | E33: 十米条 | F33: 0.18 | G33: 0.9 | H33: 0.9 | I33: 0.9 | J33: 0.9 | K33: 0.9 | L33: 0.9 | M33: 0.9 | N33: 0.9 | P33: 0.9 | Q33: 0.9 | R33: 0.9 | S33: 0.9 | T33: 9 | U33: 0.9 | V33: 0.9 | W33: 0.9 | CQ33: =SUM(G33:CP33) -> 22.5
B34: 30 | C34: T5G1-074*1.1 | D34: 室外布放电力电缆（双芯相线截面积16平方毫米以下） | E34: 十米条 | F34: =0.18*1.1 -> 0.198 | G34: 7.5 | H34: 6 | I34: 6.5 | J34: 4.5 | K34: 7 | L34: 6.5 | M34: 18 | N34: 13.5 | O34: 20.5 | P34: 16.5 | Q34: 4.5 | R34: 10.5 | S34: 8 | T34: 4.5 | U34: 15 | V34: 6 | W34: 18 | CQ34: =SUM(G34:CP34) -> 173
B35: 31 | C35: T5G1-066 | D35: 室内布放电力电缆（单芯相线截面积16平方毫米以下） | E35: 十米条 | F35: 0.15 | P35: 1.6 | T35: 6 | U35: 4.8 | V35: 4.9 | CQ35: =SUM(G35:CP35) -> 17.3
B36: 32 | C36: T5G1-066*1.1 | D36: 室内布放电力电缆（双芯相线截面积16平方毫米以下） | E36: 十米条 | F36: =0.15*1.1 -> 0.165 | P36: 0.1 | T36: 0.1 | U36: 0.1 | V36: 0.1 | CQ36: =SUM(G36:CP36) -> 0.4
B37: 33 | C37: T5G1-074*0.4 | D37: 拆除室外电力电缆（单芯相线截面积16平方毫米以下） | E37: 十米条 | F37: =0.18*0.4 -> 0.072 | L37: 6.5 | M37: 18 | CQ37: =SUM(G37:CP37) -> 24.5
B38: 34 | C38: T5G2-024*0.4 | D38: 布放射频同轴电缆1/2英寸以下（4m以下）-带端头已连接好 | E38: 条 | F38: =0.2*0.4 -> 0.08 | G38: 12 | H38: 12 | I38: 12 | J38: 12 | K38: 12 | L38: 12 | M38: 12 | N38: 20 | O38: 36 | P38: 12 | Q38: 12 | R38: 24 | S38: 12 | T38: 24 | U38: 24 | V38: 12 | W38: 12 | CQ38: =SUM(G38:CP38) -> 272
B39: 35 | C39: T5G2-024 | D39: 布放射频同轴电缆1/2英寸以下（4m以下） | E39: 条 | F39: 0.2 | P39: 1 | T39: 1 | U39: 1 | V39: 1 | CQ39: =SUM(G39:CP39) -> 4
B40: 36 | C40: T5G2-025 | D40: 布放射频同轴电缆1/2英寸以下（4m以上每增加1m） | E40: 米条 | F40: 0.03 | P40: 21 | T40: 21 | U40: 21 | V40: 21 | CQ40: =SUM(G40:CP40) -> 84
...

Sheet 表3丙
A1: 序号 | B1: 定额编号 | C1: 项目名称 | D1: 单位 | E1: 仪表名称 | F1: 单位定额值 | H1: 1 | I1: 2 | J1: 3 | K1: 4 | L1: 5 | M1: 6 | N1: 7 | O1: 8 | P1: 9 | Q1: 10 | R1: 11 | S1: 12 | T1: 13 | U1: 14 | V1: 15 | W1: 16 | X1: 17 | Y1: 18 | Z1: 19 | AA1: 20 | AB1: 21 | AC1: 22 | AD1: 23 | AE1: 24 | AF1: 25 | AG1: 26 | AH1: 27 | AI1: 28 | AJ1: 29 | AK1: 30 | AL1: 31 | AM1: 32 | AN1: 33 | AO1: 34 | AP1: 35 | AQ1: 36 | AR1: 37 | AS1: 38 | AT1: 39 | AU1: 40 | AV1: 41 | AW1: 42 | AX1: 43 | AY1: 44 | AZ1: 45 | BA1: 46 | BB1: 47 | BC1: 48 | BD1: 49 | BE1: 50 | BF1: 51 | BG1: 52 | BH1: 53 | BI1: 54 | BJ1: 55 | BK1: 56 | BL1: 57 | BM1: 58 | BN1: 59 | BO1: 60 | BP1: 61 | BQ1: 62 | BR1: 63 | BS1: 64 | BT1: 65 | BU1: 66 | BV1: 67 | BW1: 68 | BX1: 69 | BY1: 70 | BZ1: 71 | CA1: 72 | CB1: 73 | CC1: 74 | CD1: 75 | CE1: 76 | CF1: 77 | CG1: 78 | CH1: 79 | CI1: 80 | CJ1: 81 | CK1: 82 | CL1: 83 | CM1: 84 | CN1: 85 | CO1: 86 | CP1: 87 | CQ1: 88
F2: 数量（台班） | G2: 单价（元） | H2: =表3!G2 -> CBN-江门鹤山市连城C-RAN1（江门鹤山三连工业区二）U-Z5H | I2: =表3!H2 -> CBN-江门鹤山路管所（江门鹤山裕兴雨具）U-Z5H | J2: =表3!I2 -> CBN-江门鹤山市鹤城二（江门鹤山创美）U-Z5H | K2: =表3!J2 -> CBN-江门鹤山福迳（江门鹤山甘牛集团）U-Z5H | L2: =表3!K2 -> CBN-江门蓬江区滨江新区1二（江门新昌公园）U-Z5H | M2: =表3!L2 -> CBN-江门鹤山浩龙（江门鹤山鹤城联东（设备替换））U-Z5H | N2: =表3!M2 -> CBN-江门礼乐新丰（江门江海东海路（设备替换））U-Z5H | O2: =表3!N2 -> CBN-江门轻轨礼乐站（江门捷宏一品）U-Z5H | ... CQ2: =表3!CP2 -> 0 | CR2: 合计值
H3: 数量 | CR3: 数量
A4: Ⅰ | B4: II | C4: III | D4: IV | E4: Ⅴ | F4: Ⅵ | G4: Ⅶ | H4: Ⅷ | CR4: Ⅸ
A5: 4 | B5: T5G2-111 | C5: 扩装、更换基带单元侧光电转换模块 | D5: 个 | E5: 误码测试仪(40G) | F5: 0.1 | G5: 894 | H5: =表3!G51 -> 6 | I5: =表3!H51 -> 6 | J5: =表3!I51 -> 6 | K5: =表3!J51 -> 6 | L5: =表3!K51 -> 6 | M5: =表3!L51 -> 6 | N5: =表3!M51 -> 6 | O5: =表3!N51 -> 6 | ... Z5: =表3!Y51 -> 0 | AA5: =表3!Z48 -> 0 | AB5: =表3!AA48 -> 0 | AC5: =表3!AB48 -> 0 | AD5: =表3!AC48 -> 0 | AE5: =表3!AD48 -> 0 | AF5: =表3!AE48 -> 0 | AG5: =表3!AF48 -> 0 | AH5: =表3!AG48 -> 0 | ... CQ5: =表3!CP48 -> 0 | CR5: =SUM(H5:CQ5) -> 102
A6: 5 | AA6: =AA5 -> 0 | AB6: =AB5 -> 0 | AC6: =AC5 -> 0 | AD6: =AD5 -> 0 | AE6: =AE5 -> 0 | AF6: =AF5 -> 0 | AG6: =AG5 -> 0 | AH6: =AH5 -> 0 | ... CQ6: =CQ5 -> 0 | CR6: =SUM(H6:CQ6) -> 0
B7: 合计 | H7: =ROUND(SUMPRODUCT($G$5:$G$6,$F$5:$F$6,H5:H6),4) -> 536.4 | I7: =ROUND(SUMPRODUCT($G$5:$G$6,$F$5:$F$6,I5:I6),4) -> 536.4 | J7: =ROUND(SUMPRODUCT($G$5:$G$6,$F$5:$F$6,J5:J6),4) -> 536.4 | K7: =ROUND(SUMPRODUCT($G$5:$G$6,$F$5:$F$6,K5:K6),4) -> 536.4 | L7: =ROUND(SUMPRODUCT($G$5:$G$6,$F$5:$F$6,L5:L6),4) -> 536.4 | M7: =ROUND(SUMPRODUCT($G$5:$G$6,$F$5:$F$6,M5:M6),4) -> 536.4 | N7: =ROUND(SUMPRODUCT($G$5:$G$6,$F$5:$F$6,N5:N6),4) -> 536.4 | O7: =ROUND(SUMPRODUCT($G$5:$G$6,$F$5:$F$6,O5:O6),4) -> 536.4 | ... CQ7: =ROUND(SUMPRODUCT($G$5:$G$6,$F$5:$F$6,CQ5:CQ6),4) -> 0 | CR7: =SUM(H7:CQ7) -> 9118.8

Sheet 表四设备
A1: 序号 | B1: 费用名称 | C1: 规格程式 | D1: 单位 | E1: 单价 （元） | F1: 合计 | H1: JMHSWX25052615025R | I1: JMHSWX25052615022R | J1: JMHSWX25052615021R | K1: JMHSWX25051308476R | L1: JMPJWX25051308301R | M1: JMHSWX25041800897R | N1: JMJHWX25041800899R | O1: JMJHWX24122521503R | P1: JMJHWX24122845347R | Q1: JMHSWX25071541474R | R1: JMPJWX25081257109R | S1: JMPJWX25090573549R | T1: JMPJWX25090573548R | U1: JMHSWX25090473480R | V1: JMHSWX25090473477R | W1: JMJHWX25092982719R | X1: JMHSWX25102086683R | Y1: 18 | Z1: 19 | AA1: 20 | AB1: 21 | AC1: 22 | AD1: 23 | AE1: 24 | AF1: 25 | AG1: 26 | AH1: 27 | AI1: 28 | AJ1: 29 | AK1: 30 | AL1: 31 | AM1: 32 | AN1: 33 | AO1: 34 | AP1: 35 | AQ1: 36 | AR1: 37 | AS1: 38 | AT1: 39 | AU1: 40 | AV1: 41 | AW1: 42 | AX1: 43 | AY1: 44 | AZ1: 45 | BA1: 46 | BB1: 47 | BC1: 48 | BD1: 49 | BE1: 50 | BF1: 51 | BG1: 52 | BH1: 53 | BI1: 54 | BJ1: 55 | BK1: 56 | BL1: 57 | BM1: 58 | BN1: 59 | BO1: 60 | BP1: 61 | BQ1: 62 | BR1: 63 | BS1: 64 | BT1: 65 | BU1: 66 | BV1: 67 | BW1: 68 | BX1: 69 | BY1: 70 | BZ1: 71 | CA1: 72 | CB1: 73 | CC1: 74 | CD1: 75 | CE1: 76 | CF1: 77 | CG1: 78 | CH1: 79 | CI1: 80 | CJ1: 81 | CK1: 82 | CL1: 83 | CM1: 84 | CN1: 85 | CO1: 86 | CP1: 87 | CQ1: 88 | CR1: 89 | CS1: 90 | CT1: 91 | CU1: 92 | CV1: 93 | CW1: 94 | CX1: 95 | CY1: 96 | CZ1: 97 | DA1: 98 | DB1: 99 | DC1: 100 | DD1: 101 | DE1: 102 | DF1: 103 | DG1: 104 | DH1: 105 | DI1: 106 | DJ1: 107 | DK1: 108 | DL1: 109 | DM1: 110 | DN1: 111 | DO1: 112 | DP1: 113 | DQ1: 114 | DR1: 115 | DS1: 116 | DT1: 117 | DU1: 118 | DV1: 119 | DW1: 120 | DX1: 121 | DY1: 122 | DZ1: 123 | EA1: 124 | EB1: 125 | EC1: 126 | ED1: 127 | EE1: 128 | EF1: 129 | EG1: 130 | EH1: 131 | EI1: 132 | EJ1: 133 | EK1: 134 | EL1: 135 | EM1: 136 | EN1: 137 | EO1: 138 | EP1: 139 | EQ1: 140 | ER1: 141 | ES1: 142 | ET1: 143 | EU1: 144 | EV1: 145 | EW1: 146 | EX1: 147 | EY1: 148 | EZ1: 149 | FA1: 150 | FB1: 151 | FC1: 152 | FD1: 153 | FE1: 154 | FF1: 155 | FG1: 156 | FH1: 157 | FI1: 158 | FJ1: 159 | FK1: 160 | FL1: 161 | FM1: 162 | FN1: 163 | FO1: 164 | FP1: 165 | FQ1: 166 | FR1: 167 | FS1: 168 | FT1: 169 | FU1: 170 | FV1: 171 | FW1: 172 | FX1: 173 | FY1: 174 | FZ1: 175 | GA1: 176 | GB1: 177 | GC1: 178 | GD1: 179
H2: 1 | I2: 2 | J2: 3 | K2: 4 | L2: 5 | M2: 6 | N2: 7 | O2: 8 | P2: 9 | Q2: 挂墙新增BBU | R2: 11 | S2: 12 | T2: 13 | U2: 机柜内新增BBU | V2: 挂墙新增BBU | W2: 挂墙新增BBU | X2: 17 | Y2: 18 | Z2: 19 | AA2: 20 | AB2: 21 | AC2: 22 | AD2: 23 | AE2: 24 | AF2: 25 | AG2: 26 | AH2: 27 | AI2: 28 | AJ2: 29 | AK2: 30 | AL2: 31 | AM2: 32 | AN2: 33 | AO2: 34 | AP2: 35 | AQ2: 36 | AR2: 37 | AS2: 38 | AT2: 39 | AU2: 40 | AV2: 41 | AW2: 42 | AX2: 43 | AY2: 44 | AZ2: 45 | BA2: 46 | BB2: 47 | BC2: 48 | BD2: 49 | BE2: 50 | BF2: 51 | BG2: 52 | BH2: 53 | BI2: 54 | BJ2: 55 | BK2: 56 | BL2: 57 | BM2: 58 | BN2: 59 | BO2: 60 | BP2: 61 | BQ2: 62 | BR2: 63 | BS2: 64 | BT2: 65 | BU2: 66 | BV2: 67 | BW2: 68 | BX2: 69 | BY2: 70 | BZ2: 71 | CA2: 72 | CB2: 73 | CC2: 74 | CD2: 75 | CE2: 76 | CF2: 77 | CG2: 78 | CH2: 79 | CI2: 80 | CJ2: 81 | CK2: 82 | CL2: 83 | CM2: 84 | CN2: 85 | CO2: 86 | CP2: 87 | CQ2: 88 | CR2: 89 | CS2: 90 | CT2: 91 | CU2: 92 | CV2: 93 | CW2: 94 | CX2: 95 | CY2: 96 | CZ2: 97 | DA2: 98 | DB2: 99 | DC2: 100 | DD2: 101 | DE2: 102 | DF2: 103 | DG2: 104 | DH2: 105 | DI2: 106 | DJ2: 107 | DK2: 108 | DL2: 109 | DM2: 110 | DN2: 111 | DO2: 112 | DP2: 113 | DQ2: 114 | DR2: 115 | DS2: 116 | DT2: 117 | DU2: 118 | DV2: 119 | DW2: 120 | DX2: 121 | DY2: 122 | DZ2: 123 | EA2: 124 | EB2: 125 | EC2: 126 | ED2: 127 | EE2: 128 | EF2: 129 | EG2: 130 | EH2: 131 | EI2: 132 | EJ2: 133 | EK2: 134 | EL2: 135 | EM2: 136 | EN2: 137 | EO2: 138 | EP2: 139 | EQ2: 140 | ER2: 141 | ES2: 142 | ET2: 143 | EU2: 144 | EV2: 145 | EW2: 146 | EX2: 147 | EY2: 148 | EZ2: 149 | FA2: 150 | FB2: 151 | FC2: 152 | FD2: 153 | FE2: 154 | FF2: 155 | FG2: 156 | FH2: 157 | FI2: 158 | FJ2: 159 | FK2: 160 | FL2: 161 | FM2: 162 | FN2: 163 | FO2: 164 | FP2: 165 | FQ2: 166 | FR2: 167 | FS2: 168 | FT2: 169 | FU2: 170 | FV2: 171 | FW2: 172 | FX2: 173 | FY2: 174 | FZ2: 175 | GA2: 176 | GB2: 177 | GC2: 178 | GD2: 179
H3: =[3]表3!G2 -> CBN-江门鹤山市连城C-RAN1（江门鹤山三连工业区二）U-Z5H | I3: =[3]表3!H2 -> CBN-江门鹤山路管所（江门鹤山裕兴雨具）U-Z5H | J3: =[3]表3!I2 -> CBN-江门鹤山市鹤城二（江门鹤山创美）U-Z5H | K3: =[3]表3!J2 -> CBN-江门鹤山福迳（江门鹤山甘牛集团）U-Z5H | L3: =[3]表3!K2 -> CBN-江门蓬江区滨江新区1二（江门新昌公园）U-Z5H | M3: =[3]表3!L2 -> CBN-江门鹤山浩龙（江门鹤山鹤城联东（设备替换））U-Z5H | N3: =[3]表3!M2 -> CBN-江门礼乐新丰（江门江海东海路（设备替换））U-Z5H | O3: =[3]表3!N2 -> CBN-江门轻轨礼乐站（江门捷宏一品）U-Z5H | ... X3: =[3]表3!W2 -> CBN-江门鹤山新民（江门鹤山共和新联油漆）U-Z5H | Y3: =INDEX([2]汇总!$C$6:$C$210,COLUMN()-7) -> 0 | Z3: =INDEX([2]汇总!$C$6:$C$210,COLUMN()-7) -> 0 | AA3: =INDEX([2]汇总!$C$6:$C$210,COLUMN()-7) -> 0 | AB3: =INDEX([2]汇总!$C$6:$C$210,COLUMN()-7) -> 0 | AC3: =INDEX([2]汇总!$C$6:$C$210,COLUMN()-7) -> 0 | AD3: =INDEX([2]汇总!$C$6:$C$210,COLUMN()-7) -> 0 | AE3: =INDEX([2]汇总!$C$6:$C$210,COLUMN()-7) -> 0 | AF3: =INDEX([2]汇总!$C$6:$C$210,COLUMN()-7) -> 0 | ... GD3: =INDEX([2]汇总!$C$6:$C$210,COLUMN()-7) -> 0
F4: 数量 | G4: 金额不含税（元) | H4: 数量 | I4: 数量 | J4: 数量 | K4: 数量 | L4: 数量 | M4: 数量 | N4: 数量 | O4: 数量 | P4: 数量 | Q4: 数量 | R4: 数量 | S4: 数量 | T4: 数量 | U4: 数量 | V4: 数量 | W4: 数量 | X4: 数量 | Y4: 数量 | Z4: 数量 | AA4: 数量 | AB4: 数量 | AC4: 数量 | AD4: 数量 | AE4: 数量 | AF4: 数量 | AG4: 数量 | AH4: 数量 | AI4: 数量 | AJ4: 数量 | AK4: 数量 | AL4: 数量 | AM4: 数量 | AN4: 数量 | AO4: 数量 | AP4: 数量 | AQ4: 数量 | AR4: 数量 | AS4: 数量 | AT4: 数量 | AU4: 数量 | AV4: 数量 | AW4: 数量 | AX4: 数量 | AY4: 数量 | AZ4: 数量 | BA4: 数量 | BB4: 数量 | BC4: 数量 | BD4: 数量 | BE4: 数量 | BF4: 数量 | BG4: 数量 | BH4: 数量 | BI4: 数量 | BJ4: 数量 | BK4: 数量 | BL4: 数量 | BM4: 数量 | BN4: 数量 | BO4: 数量 | BP4: 数量 | BQ4: 数量 | BR4: 数量 | BS4: 数量 | BT4: 数量 | BU4: 数量 | BV4: 数量 | BW4: 数量 | BX4: 数量 | BY4: 数量 | BZ4: 数量 | CA4: 数量 | CB4: 数量 | CC4: 数量 | CD4: 数量 | CE4: 数量 | CF4: 数量 | CG4: 数量 | CH4: 数量 | CI4: 数量 | CJ4: 数量 | CK4: 数量 | CL4: 数量 | CM4: 数量 | CN4: 数量 | CO4: 数量 | CP4: 数量 | CQ4: 数量 | CR4: 数量 | CS4: 数量 | CT4: 数量 | CU4: 数量 | CV4: 数量 | CW4: 数量 | CX4: 数量 | CY4: 数量 | CZ4: 数量 | DA4: 数量 | DB4: 数量 | DC4: 数量 | DD4: 数量 | DE4: 数量 | DF4: 数量 | DG4: 数量 | DH4: 数量 | DI4: 数量 | DJ4: 数量 | DK4: 数量 | DL4: 数量 | DM4: 数量 | DN4: 数量 | DO4: 数量 | DP4: 数量 | DQ4: 数量 | DR4: 数量 | DS4: 数量 | DT4: 数量 | DU4: 数量 | DV4: 数量 | DW4: 数量 | DX4: 数量 | DY4: 数量 | DZ4: 数量 | EA4: 数量 | EB4: 数量 | EC4: 数量 | ED4: 数量 | EE4: 数量 | EF4: 数量 | EG4: 数量 | EH4: 数量 | EI4: 数量 | EJ4: 数量 | EK4: 数量 | EL4: 数量 | EM4: 数量 | EN4: 数量 | EO4: 数量 | EP4: 数量 | EQ4: 数量 | ER4: 数量 | ES4: 数量 | ET4: 数量 | EU4: 数量 | EV4: 数量 | EW4: 数量 | EX4: 数量 | EY4: 数量 | EZ4: 数量 | FA4: 数量 | FB4: 数量 | FC4: 数量 | FD4: 数量 | FE4: 数量 | FF4: 数量 | FG4: 数量 | FH4: 数量 | FI4: 数量 | FJ4: 数量 | FK4: 数量 | FL4: 数量 | FM4: 数量 | FN4: 数量 | FO4: 数量 | FP4: 数量 | FQ4: 数量 | FR4: 数量 | FS4: 数量 | FT4: 数量 | FU4: 数量 | FV4: 数量 | FW4: 数量 | FX4: 数量 | FY4: 数量 | FZ4: 数量 | GA4: 数量 | GB4: 数量 | GC4: 数量 | GD4: 数量
A5: I | B5: II | C5: II | D5: III | E5: IV | F5: V | G5: VI | H5: V | I5: V | J5: V | K5: V | L5: V | M5: V | N5: V | O5: V | P5: V | Q5: V | R5: V | S5: V | T5: V | U5: V | V5: V | W5: V | X5: V | Y5: V | Z5: V | AA5: V | AB5: V | AC5: V | AD5: V | AE5: V | AF5: V | AG5: V | AH5: V | AI5: V | AJ5: V | AK5: V | AL5: V | AM5: V | AN5: V | AO5: V | AP5: V | AQ5: V | AR5: V | AS5: V | AT5: V | AU5: V | AV5: V | AW5: V | AX5: V | AY5: V | AZ5: V | BA5: V | BB5: V | BC5: V | BD5: V | BE5: V | BF5: V | BG5: V | BH5: V | BI5: V | BJ5: V | BK5: V | BL5: V | BM5: V | BN5: V | BO5: V | BP5: V | BQ5: V | BR5: V | BS5: V | BT5: V | BU5: V | BV5: V | BW5: V | BX5: V | BY5: V | BZ5: V | CA5: V | CB5: V | CC5: V | CD5: V | CE5: V | CF5: V | CG5: V | CH5: V | CI5: V | CJ5: V | CK5: V | CL5: V | CM5: V | CN5: V | CO5: V | CP5: V | CQ5: V | CR5: V | CS5: V | CT5: V | CU5: V | CV5: V | CW5: V | CX5: V | CY5: V | CZ5: V | DA5: V | DB5: V | DC5: V | DD5: V | DE5: V | DF5: V | DG5: V | DH5: V | DI5: V | DJ5: V | DK5: V | DL5: V | DM5: V | DN5: V | DO5: V | DP5: V | DQ5: V | DR5: V | DS5: V | DT5: V | DU5: V | DV5: V | DW5: V | DX5: V | DY5: V | DZ5: V | EA5: V | EB5: V | EC5: V | ED5: V | EE5: V | EF5: V | EG5: V | EH5: V | EI5: V | EJ5: V | EK5: V | EL5: V | EM5: V | EN5: V | EO5: V | EP5: V | EQ5: V | ER5: V | ES5: V | ET5: V | EU5: V | EV5: V | EW5: V | EX5: V | EY5: V | EZ5: V | FA5: V | FB5: V | FC5: V | FD5: V | FE5: V | FF5: V | FG5: V | FH5: V | FI5: V | FJ5: V | FK5: V | FL5: V | FM5: V | FN5: V | FO5: V | FP5: V | FQ5: V | FR5: V | FS5: V | FT5: V | FU5: V | FV5: V | FW5: V | FX5: V | FY5: V | FZ5: V | GA5: V | GB5: V | GC5: V | GD5: V
A6: 1 | B6: 10G-1.4KM单模光模块 | C6: 10G-1.4KM单模光模块 | D6: 个 | E6: 10.4 | F6: =SUM(H6:GD6) -> 16 | G6: =E6*F6 -> 166.4 | Q6: 5 | S6: 4 | T6: 4 | U6: 1 | V6: 1 | W6: 1
A7: 2 | B7: 25G-10KM单模光模块 | C7: 25G-10KM单模光模块 | D7: 个 | E7: 201.7 | F7: =SUM(H7:GD7) -> 34 | G7: =E7*F7 -> 6857.8 | H7: 2 | I7: 2 | J7: 2 | K7: 2 | L7: 2 | M7: 2 | N7: 2 | O7: 2 | P7: 2 | Q7: 2 | R7: 2 | S7: 2 | T7: 2 | U7: 2 | V7: 2 | W7: 2 | X7: 2
A8: 3 | B8: 25G-2KM单模光模块 | C8: 25G-2KM单模光模块 | D8: 个 | E8: 48.99 | F8: =SUM(H8:GD8) -> 56 | G8: =E8*F8 -> 2743.44 | H8: 4 | I8: 4 | J8: 4 | K8: 4 | L8: 4 | M8: 4 | N8: 4 | O8: 4 | P8: 4 | R8: 4 | U8: 4 | V8: 4 | W8: 4 | X8: 4
A9: 4 | B9: 700M 天线 | C9: 4448天线\700/900/1800/FA\4+4+4+8通道\电调（短款）dBi\四频13/14/16.5/15/14.5 | D9: 面 | E9: 3957.36 | F9: =SUM(H9:GD9) -> 18 | G9: =E9*F9 -> 71232.48 | L9: 3 | O9: 3 | P9: 3 | S9: 3 | U9: 3 | V9: 3
A10: 5 | B10: 700M 天线 | C10: 绿色700-900M宽频四通道电调天线 | D10: 面 | E10: 1558.96 | F10: =SUM(H10:GD10) -> 18 | G10: =E10*F10 -> 28061.28 | H10: 3 | I10: 3 | K10: 3 | N10: 3 | W10: 3 | X10: 3
A11: 6 | B11: BBU 直流电源线 | C11: BBU 直流电源线 | D11: 根 | E11: 0 | F11: =SUM(H11:GD11) -> 4 | G11: =E11*F11 -> 0 | Q11: 1 | U11: 1 | V11: 1 | W11: 1
A12: 7 | B12: LC-FC光纤（1芯） | C12: 单模1 LCUPC-FC/UPC G.652D 15M黄色|LC/PC-FC/PC-15M-φ2-SM/IOFC-FC/UPC-LC/PC G652D 1F φ2 PVC 15M//LC/F | D12: 根 | E12: 0 | F12: =SUM(H12:GD12) -> 34 | G12: =E12*F12 -> 0 | H12: 2 | I12: 2 | J12: 2 | K12: 2 | L12: 2 | M12: 2 | N12: 2 | O12: 2 | P12: 2 | Q12: 2 | R12: 2 | S12: 2 | T12: 2 | U12: 2 | V12: 2 | W12: 2 | X12: 2
A13: 8 | B13: 700M RRU接地线 | C13: H07V-K&RV黄绿色1×16mm2电线(VDE/CE/CCC)|绝缘层颜色:/黄/绿色;绝缘层材质:/聚氯乙烯;额定电压:Nom(V);导体材质:/铜;标称截面积:Nom(mm^2);屏蔽层:/否;CPR认证:/E等级;导体规格:/1*16mm2; | H07V-K 16mm2(R | D13: 米 | E13: 0 | F13: =SUM(H13:GD13) -> 177 | G13: =E13*F13 -> 0 | H13: 9 | I13: 9 | J13: 9 | K13: 9 | L13: 9 | M13: 9 | N13: 9 | O13: 9 | P13: 9 | Q13: 13 | R13: 9 | S13: 9 | T13: 9 | U13: 13 | V13: 13 | W13: 13 | X13: 17
A14: 9 | B14: 700M 室外RRU单元 | C14: R9214H S7200(W)整机(直流,不含光模块) | D14: 套 | E14: 0 | F14: =SUM(H14:GD14) -> 24 | G14: =E14*F14 -> 0 | L14: 3 | O14: 3 | P14: 3 | Q14: 3 | S14: 3 | T14: 3 | U14: 3 | V14: 3
A15: 10 | B15: 700M 室外RRU单元 | C15: R9264M M7290整机(直流,不含光模块) | D15: 套 | E15: 0 | F15: =SUM(H15:GD15) -> 27 | G15: =E15*F15 -> 0 | H15: 3 | I15: 3 | J15: 3 | K15: 3 | M15: 3 | N15: 3 | R15: 3 | W15: 3 | X15: 3
A16: 11 | B16: 700M RRU上跳线 | C16: RF-01024084-012|射频电缆组件|3米|长度:3m;线材:RF1/2S-;B端连接器:4.3-10M;A端连接器:DM;硫化风险等级不涉及 | 626979000517 V1.0 | D16: 根 | E16: 0 | F16: =SUM(H16:GD16) -> 132 | G16: =E16*F16 -> 0 | H16: 12 | I16: 12 | J16: 12 | L16: 12 | M16: 12 | N16: 12 | O16: 12 | P16: 12 | Q16: 12 | R16: 12 | T16: 12
A17: 12 | B17: 700M RRU上跳线 | C17: RF-01024084-205|射频电缆组件|5米|长度:5m;线材:RF1/2S-;B端连接器:4.3-10M;A端连接器:DM;硫化风险等级不涉及 | 626979000517 V1.0 | D17: 根 | E17: 0 | F17: =SUM(H17:GD17) -> 60 | G17: =E17*F17 -> 0 | K17: 12 | U17: 12 | V17: 12 | W17: 12 | X17: 12
A18: 13 | B18: 700M RRU上跳线 | C18: RF-01024084-012|射频电缆组件|10米|长度:10m;线材:RF1/2S-;B端连接器:4.3-10M;A端连接器:DM;硫化风险等级不涉及 | 626979000517 V1.0 | D18: 根 | E18: 0 | F18: =SUM(H18:GD18) -> 12 | G18: =E18*F18 -> 0 | S18: 12
A19: 14 | B19: RRU电源线 | C19: UL 2586黑色D型(芯线：蓝/红)2X10mm2(2x8AWG)编织屏蔽电缆(UL/CE) | UL2586 2X10mm2(2x8AWG) | D19: 米 | E19: 0 | F19: =SUM(H19:GD19) -> 415 | G19: =E19*F19 -> 0 | K19: 45 | P19: 190 | X19: 180
A20: 15 | B20: RRU电源线 | C20: UL 2586黑色D型(芯线：蓝/红)2X6mm2(2x10AWG)编织屏蔽电缆(UL/CE) | UL 2586 2×6mm2(2x10AWG) | D20: 米 | E20: 0 | F20: =SUM(H20:GD20) -> 1070 | G20: =E20*F20 -> 0 | H20: 75 | I20: 60 | J20: 65 | L20: 70 | O20: 135 | P20: 15 | Q20: 165 | R20: 45 | S20: 105 | T20: 80 | U20: 45 | V20: 150 | W20: 60
A21: 16 | B21: V9200安装件 | C21: V9200安装件 | D21: 套 | E21: 0 | F21: =SUM(H21:GD21) -> 4 | G21: =E21*F21 -> 0 | Q21: 1 | U21: 1 | V21: 1 | W21: 1
A22: 17 | B22: V9200风扇模块VFC | C22: V9200风扇模块VFC | D22: 块 | E22: 0 | F22: =SUM(H22:GD22) -> 4 | G22: =E22*F22 -> 0 | Q22: 1 | U22: 1 | V22: 1 | W22: 1
A23: 18 | B23: V9200工程安装辅料 | C23: V9200工程安装辅料 | D23: 套 | E23: 0 | F23: =SUM(H23:GD23) -> 4 | G23: =E23*F23 -> 0 | Q23: 1 | U23: 1 | V23: 1 | W23: 1
A24: 19 | B24: V9200机箱 | C24: V9200机箱 | D24: 套 | E24: 143.36 | F24: =SUM(H24:GD24) -> 4 | G24: =E24*F24 -> 573.44 | Q24: 1 | U24: 1 | V24: 1 | W24: 1
A25: 20 | B25: 基带处理板VBPe0d | C25: V9200基带处理模块VBPe0d | D25: 块 | E25: 0 | F25: =SUM(H25:GD25) -> 8 | G25: =E25*F25 -> 0 | L25: 1 | O25: 1 | P25: 1 | Q25: 1 | S25: 1 | T25: 1 | U25: 1 | V25: 1
A26: 21 | B26: 基带处理板VBPe0e | C26: V9200基带处理模块VBPe0e | D26: 块 | E26: 20135.98 | F26: =SUM(H26:GD26) -> 9 | G26: =E26*F26 -> 181223.82 | H26: 1 | I26: 1 | J26: 1 | K26: 1 | M26: 1 | N26: 1 | R26: 1 | W26: 1 | X26: 1
A27: 22 | B27: V9200交换管理模块VSWd0A | C27: V9200交换管理模块VSWd0A | D27: 块 | E27: 819.55 | F27: =SUM(H27:GD27) -> 4 | G27: =E27*F27 -> 3278.2 | Q27: 1 | U27: 1 | V27: 1 | W27: 1
A28: 23 | B28: GPS&BDS双模天线 | C28: GPS&BDS双模天线 | D28: 套 | E28: 0 | F28: =SUM(H28:GD28) -> 1 | G28: =E28*F28 -> 0 | W28: 1
A29: 24 | B29: GPS&BDS避雷器及辅料 | C29: GPS&BDS避雷器及辅料 | D29: 套 | E29: 0 | F29: =SUM(H29:GD29) -> 1 | G29: =E29*F29 -> 0 | W29: 1
A30: 25 | B30: 北斗三&GPS避雷器 | C30: 北斗三&GPS避雷器 | D30: 套 | E30: 0 | F30: =SUM(H30:GD30) -> 4 | G30: =E30*F30 -> 0 | Q30: 1 | U30: 1 | V30: 1 | W30: 1
A31: 26 | B31: 北斗三&GPS天线及辅料 | C31: 北斗三&GPS天线及辅料 | D31: 套 | E31: 14.83 | F31: =SUM(H31:GD31) -> 4 | G31: =E31*F31 -> 59.32 | Q31: 1 | U31: 1 | V31: 1 | W31: 1
A32: 27 | B32: 700M 天线 | C32: 多频段智能天线\700～900/1800/FAD\4+4+8通道\独立电调\四频14/16.5/13.5/15.5dBi | D32: 面 | E32: 3454.6 | F32: =SUM(H32:GD32) -> 3 | G32: =E32*F32 -> 10363.8 | M32: 3
